2020-03-18 09:50:41,551 [Thread-2: 12072]C:\Users\Administrator\AppData\Local\Programs\Python\Python36\lib\site-packages\django\core\servers\basehttp.py:log_message:136 INFO - "GET /api/v1.0/auth/logout HTTP/1.1" 200 48
2020-03-18 09:50:43,158 [Thread-2: 12072]C:\Users\Administrator\AppData\Local\Programs\Python\Python36\lib\site-packages\django\core\servers\basehttp.py:log_message:136 INFO - "POST /api/v1.0/auth/authorize HTTP/1.1" 200 73
2020-03-18 10:36:26,282 [Thread-2: 14536]C:\Users\Administrator\AppData\Local\Programs\Python\Python36\lib\site-packages\django\utils\log.py:log_response:228 WARNING - Not Found: /
2020-03-18 10:36:26,282 [Thread-2: 14536]C:\Users\Administrator\AppData\Local\Programs\Python\Python36\lib\site-packages\django\core\servers\basehttp.py:log_message:136 WARNING - "GET / HTTP/1.1" 404 2031
2020-03-18 10:36:26,485 [Thread-2: 14536]C:\Users\Administrator\AppData\Local\Programs\Python\Python36\lib\site-packages\django\utils\log.py:log_response:228 WARNING - Not Found: /favicon.ico
2020-03-18 10:36:26,486 [Thread-2: 14536]C:\Users\Administrator\AppData\Local\Programs\Python\Python36\lib\site-packages\django\core\servers\basehttp.py:log_message:136 WARNING - "GET /favicon.ico HTTP/1.1" 404 2082
2020-03-18 10:37:04,240 [Thread-4: 18228]C:\Users\Administrator\AppData\Local\Programs\Python\Python36\lib\site-packages\django\core\servers\basehttp.py:log_message:136 INFO - "POST /api/v1.0/auth/authorize HTTP/1.1" 200 73
2020-03-18 10:39:15,939 [Thread-4: 18228]C:\Users\Administrator\AppData\Local\Programs\Python\Python36\lib\site-packages\django\core\servers\basehttp.py:log_message:136 INFO - "GET /api/v1.0/auth/logout HTTP/1.1" 200 48
2020-03-18 10:39:16,967 [Thread-4: 18228]C:\Users\Administrator\AppData\Local\Programs\Python\Python36\lib\site-packages\django\core\servers\basehttp.py:log_message:136 INFO - "POST /api/v1.0/auth/authorize HTTP/1.1" 200 73
2020-03-19 14:45:50,003 [Thread-2: 14756]C:\Users\Administrator\AppData\Local\Programs\Python\Python36\lib\site-packages\django\utils\log.py:log_response:228 ERROR - Internal Server Error: /api/v1.0/service/menu
Traceback (most recent call last):
  File "C:\Users\Administrator\AppData\Local\Programs\Python\Python36\lib\site-packages\django\core\handlers\exception.py", line 34, in inner
    response = get_response(request)
  File "C:\Users\Administrator\AppData\Local\Programs\Python\Python36\lib\site-packages\django\core\handlers\base.py", line 126, in _get_response
    response = self.process_exception_by_middleware(e, request)
  File "C:\Users\Administrator\AppData\Local\Programs\Python\Python36\lib\site-packages\django\core\handlers\base.py", line 124, in _get_response
    response = wrapped_callback(request, *callback_args, **callback_kwargs)
  File "F:\微信小程序\Friday\school_engineer\backend\apis\views\menu.py", line 26, in get_menu
    global_app_data = init_app_data()
  File "F:\微信小程序\Friday\school_engineer\backend\apis\views\menu.py", line 21, in init_app_data
    with open(data_file, 'r', encoding='utf-8') as f:
FileNotFoundError: [Errno 2] No such file or directory: 'F:\\微信小程序\\Friday\\school_engineer\\backend\\app.yaml'
2020-03-19 14:45:50,005 [Thread-2: 14756]C:\Users\Administrator\AppData\Local\Programs\Python\Python36\lib\site-packages\django\core\servers\basehttp.py:log_message:136 ERROR - "GET /api/v1.0/service/menu HTTP/1.1" 500 71287
2020-03-19 14:46:44,498 [Thread-2: 19364]C:\Users\Administrator\AppData\Local\Programs\Python\Python36\lib\site-packages\django\core\servers\basehttp.py:log_message:136 INFO - "GET /api/v1.0/service/menu HTTP/1.1" 200 222
2020-03-19 14:48:38,152 [Thread-2: 5344]C:\Users\Administrator\AppData\Local\Programs\Python\Python36\lib\site-packages\django\core\servers\basehttp.py:log_message:136 INFO - "GET /api/v1.0/service/menu HTTP/1.1" 200 254
2020-03-19 14:53:49,847 [Thread-3: 11164]C:\Users\Administrator\AppData\Local\Programs\Python\Python36\lib\site-packages\django\core\servers\basehttp.py:log_message:136 INFO - "GET /api/v1.0/service/menu HTTP/1.1" 200 254
2020-03-19 14:55:29,996 [Thread-4: 2984]C:\Users\Administrator\AppData\Local\Programs\Python\Python36\lib\site-packages\django\core\servers\basehttp.py:log_message:136 INFO - "GET /api/v1.0/service/menu HTTP/1.1" 200 254
2020-03-19 14:57:15,980 [Thread-4: 2984]C:\Users\Administrator\AppData\Local\Programs\Python\Python36\lib\site-packages\django\core\servers\basehttp.py:log_message:136 INFO - "GET /api/v1.0/service/menu HTTP/1.1" 200 254
2020-03-19 14:57:29,380 [Thread-5: 14432]C:\Users\Administrator\AppData\Local\Programs\Python\Python36\lib\site-packages\django\core\servers\basehttp.py:log_message:136 INFO - "GET /api/v1.0/auth/status HTTP/1.1" 200 70
2020-03-19 14:57:29,381 [Thread-4: 2984]C:\Users\Administrator\AppData\Local\Programs\Python\Python36\lib\site-packages\django\core\servers\basehttp.py:log_message:136 INFO - "GET /api/v1.0/auth/status HTTP/1.1" 200 70
2020-03-19 14:57:30,295 [Thread-4: 2984]C:\Users\Administrator\AppData\Local\Programs\Python\Python36\lib\site-packages\django\core\servers\basehttp.py:log_message:136 INFO - "GET /api/v1.0/service/sch_engineer?type=backstage HTTP/1.1" 200 60
2020-03-19 14:57:30,313 [Thread-4: 2984]C:\Users\Administrator\AppData\Local\Programs\Python\Python36\lib\site-packages\django\core\servers\basehttp.py:log_message:136 INFO - "GET /api/v1.0/service/sch_engineer?type=backstage HTTP/1.1" 200 60
2020-03-19 14:57:39,685 [Thread-4: 2984]C:\Users\Administrator\AppData\Local\Programs\Python\Python36\lib\site-packages\django\core\servers\basehttp.py:log_message:136 INFO - "GET /api/v1.0/service/menu HTTP/1.1" 200 254
2020-03-19 14:58:11,009 [Thread-4: 2984]C:\Users\Administrator\AppData\Local\Programs\Python\Python36\lib\site-packages\django\core\servers\basehttp.py:log_message:136 INFO - "GET /api/v1.0/service/menu HTTP/1.1" 200 254
2020-03-19 14:58:34,205 [Thread-4: 2984]C:\Users\Administrator\AppData\Local\Programs\Python\Python36\lib\site-packages\django\core\servers\basehttp.py:log_message:136 INFO - "GET /api/v1.0/service/menu HTTP/1.1" 200 254
2020-03-19 15:03:31,096 [Thread-4: 2984]C:\Users\Administrator\AppData\Local\Programs\Python\Python36\lib\site-packages\django\core\servers\basehttp.py:log_message:136 INFO - "GET /api/v1.0/service/menu HTTP/1.1" 200 254
2020-03-19 15:03:39,618 [Thread-4: 2984]C:\Users\Administrator\AppData\Local\Programs\Python\Python36\lib\site-packages\django\core\servers\basehttp.py:log_message:136 INFO - "POST /api/v1.0/auth/authorize HTTP/1.1" 200 73
2020-03-19 15:07:26,468 [Thread-4: 2984]C:\Users\Administrator\AppData\Local\Programs\Python\Python36\lib\site-packages\django\core\servers\basehttp.py:log_message:136 INFO - "GET /api/v1.0/service/menu HTTP/1.1" 200 254
2020-03-19 15:09:07,170 [Thread-4: 2984]C:\Users\Administrator\AppData\Local\Programs\Python\Python36\lib\site-packages\django\core\servers\basehttp.py:log_message:136 INFO - "GET /api/v1.0/service/menu HTTP/1.1" 200 254
2020-03-19 15:10:19,927 [Thread-4: 2984]C:\Users\Administrator\AppData\Local\Programs\Python\Python36\lib\site-packages\django\core\servers\basehttp.py:log_message:136 INFO - "GET /api/v1.0/service/menu HTTP/1.1" 200 254
2020-03-19 15:11:42,857 [Thread-4: 2984]C:\Users\Administrator\AppData\Local\Programs\Python\Python36\lib\site-packages\django\core\servers\basehttp.py:log_message:136 INFO - "GET /api/v1.0/service/menu HTTP/1.1" 200 254
2020-03-19 15:13:04,707 [Thread-4: 2984]C:\Users\Administrator\AppData\Local\Programs\Python\Python36\lib\site-packages\django\core\servers\basehttp.py:log_message:136 INFO - "GET /api/v1.0/service/menu HTTP/1.1" 200 254
2020-03-19 15:13:49,577 [Thread-4: 2984]C:\Users\Administrator\AppData\Local\Programs\Python\Python36\lib\site-packages\django\core\servers\basehttp.py:log_message:136 INFO - "GET /api/v1.0/service/menu HTTP/1.1" 200 254
2020-03-19 15:15:24,301 [Thread-4: 2984]C:\Users\Administrator\AppData\Local\Programs\Python\Python36\lib\site-packages\django\core\servers\basehttp.py:log_message:136 INFO - "GET /api/v1.0/service/menu HTTP/1.1" 200 254
2020-03-19 15:16:12,575 [Thread-4: 2984]C:\Users\Administrator\AppData\Local\Programs\Python\Python36\lib\site-packages\django\core\servers\basehttp.py:log_message:136 INFO - "GET /api/v1.0/service/menu HTTP/1.1" 200 254
2020-03-19 15:16:46,255 [Thread-4: 2984]C:\Users\Administrator\AppData\Local\Programs\Python\Python36\lib\site-packages\django\core\servers\basehttp.py:log_message:136 INFO - "GET /api/v1.0/service/menu HTTP/1.1" 200 254
2020-03-19 15:17:07,081 [Thread-4: 2984]C:\Users\Administrator\AppData\Local\Programs\Python\Python36\lib\site-packages\django\core\servers\basehttp.py:log_message:136 INFO - "GET /api/v1.0/service/menu HTTP/1.1" 200 254
2020-03-19 15:17:10,115 [Thread-4: 2984]C:\Users\Administrator\AppData\Local\Programs\Python\Python36\lib\site-packages\django\core\servers\basehttp.py:log_message:136 INFO - "GET /api/v1.0/service/menu HTTP/1.1" 200 254
2020-03-19 15:23:17,880 [Thread-2: 5464]C:\Users\Administrator\AppData\Local\Programs\Python\Python36\lib\site-packages\django\core\servers\basehttp.py:log_message:136 INFO - "GET /api/v1.0/service/menu HTTP/1.1" 200 254
2020-03-19 15:23:31,447 [Thread-2: 5464]C:\Users\Administrator\AppData\Local\Programs\Python\Python36\lib\site-packages\django\core\servers\basehttp.py:log_message:136 INFO - "GET /api/v1.0/service/menu HTTP/1.1" 200 254
2020-03-19 15:24:07,043 [Thread-2: 5464]C:\Users\Administrator\AppData\Local\Programs\Python\Python36\lib\site-packages\django\core\servers\basehttp.py:log_message:136 INFO - "GET /api/v1.0/service/menu HTTP/1.1" 200 254
2020-03-19 15:24:21,308 [Thread-2: 5464]C:\Users\Administrator\AppData\Local\Programs\Python\Python36\lib\site-packages\django\core\servers\basehttp.py:log_message:136 INFO - "GET /api/v1.0/service/menu HTTP/1.1" 200 254
2020-03-19 15:24:36,313 [Thread-2: 5464]C:\Users\Administrator\AppData\Local\Programs\Python\Python36\lib\site-packages\django\core\servers\basehttp.py:log_message:136 INFO - "GET /api/v1.0/service/menu HTTP/1.1" 200 236
2020-03-19 15:24:53,087 [Thread-2: 5464]C:\Users\Administrator\AppData\Local\Programs\Python\Python36\lib\site-packages\django\core\servers\basehttp.py:log_message:136 INFO - "GET /api/v1.0/service/menu HTTP/1.1" 200 236
2020-03-19 15:25:00,349 [Thread-2: 5464]C:\Users\Administrator\AppData\Local\Programs\Python\Python36\lib\site-packages\django\core\servers\basehttp.py:log_message:136 INFO - "GET /api/v1.0/service/menu HTTP/1.1" 200 236
2020-03-19 15:25:12,801 [Thread-2: 5464]C:\Users\Administrator\AppData\Local\Programs\Python\Python36\lib\site-packages\django\core\servers\basehttp.py:log_message:136 INFO - "GET /api/v1.0/service/menu HTTP/1.1" 200 236
2020-03-19 15:25:20,603 [Thread-2: 5464]C:\Users\Administrator\AppData\Local\Programs\Python\Python36\lib\site-packages\django\core\servers\basehttp.py:log_message:136 INFO - "GET /api/v1.0/service/menu HTTP/1.1" 200 236
2020-03-19 15:29:33,907 [Thread-2: 1944]C:\Users\Administrator\AppData\Local\Programs\Python\Python36\lib\site-packages\django\core\servers\basehttp.py:log_message:136 INFO - "GET /api/v1.0/service/menu HTTP/1.1" 200 236
2020-03-19 15:30:06,859 [Thread-2: 1944]C:\Users\Administrator\AppData\Local\Programs\Python\Python36\lib\site-packages\django\core\servers\basehttp.py:log_message:136 INFO - "GET /api/v1.0/service/menu HTTP/1.1" 200 236
2020-03-19 15:30:12,596 [Thread-2: 1944]C:\Users\Administrator\AppData\Local\Programs\Python\Python36\lib\site-packages\django\core\servers\basehttp.py:log_message:136 INFO - "GET /api/v1.0/auth/status HTTP/1.1" 200 70
2020-03-19 15:30:12,615 [Thread-2: 1944]C:\Users\Administrator\AppData\Local\Programs\Python\Python36\lib\site-packages\django\core\servers\basehttp.py:log_message:136 INFO - "GET /api/v1.0/auth/status HTTP/1.1" 200 70
2020-03-19 15:30:19,701 [Thread-2: 1944]C:\Users\Administrator\AppData\Local\Programs\Python\Python36\lib\site-packages\django\core\servers\basehttp.py:log_message:136 INFO - "GET /api/v1.0/service/sch_engineer?type=backstage HTTP/1.1" 200 64
2020-03-19 15:30:19,729 [Thread-2: 1944]C:\Users\Administrator\AppData\Local\Programs\Python\Python36\lib\site-packages\django\core\servers\basehttp.py:log_message:136 INFO - "GET /api/v1.0/service/sch_engineer?type=backstage HTTP/1.1" 200 64
2020-03-19 15:30:33,236 [Thread-2: 1944]C:\Users\Administrator\AppData\Local\Programs\Python\Python36\lib\site-packages\django\core\servers\basehttp.py:log_message:136 INFO - "GET /api/v1.0/service/menu HTTP/1.1" 200 236
2020-03-19 15:30:45,966 [Thread-2: 1944]C:\Users\Administrator\AppData\Local\Programs\Python\Python36\lib\site-packages\django\core\servers\basehttp.py:log_message:136 INFO - "GET /api/v1.0/service/menu HTTP/1.1" 200 236
2020-03-19 15:30:52,202 [Thread-2: 1944]C:\Users\Administrator\AppData\Local\Programs\Python\Python36\lib\site-packages\django\core\servers\basehttp.py:log_message:136 INFO - "GET /api/v1.0/auth/status HTTP/1.1" 200 70
2020-03-19 15:30:52,218 [Thread-2: 1944]C:\Users\Administrator\AppData\Local\Programs\Python\Python36\lib\site-packages\django\core\servers\basehttp.py:log_message:136 INFO - "GET /api/v1.0/auth/status HTTP/1.1" 200 70
2020-03-19 15:30:53,219 [Thread-2: 1944]C:\Users\Administrator\AppData\Local\Programs\Python\Python36\lib\site-packages\django\core\servers\basehttp.py:log_message:136 INFO - "GET /api/v1.0/service/sch_engineer?type=backstage HTTP/1.1" 200 64
2020-03-19 15:30:53,273 [Thread-2: 1944]C:\Users\Administrator\AppData\Local\Programs\Python\Python36\lib\site-packages\django\core\servers\basehttp.py:log_message:136 INFO - "GET /api/v1.0/service/sch_engineer?type=backstage HTTP/1.1" 200 64
2020-03-19 15:32:35,506 [Thread-2: 7620]C:\Users\Administrator\AppData\Local\Programs\Python\Python36\lib\site-packages\django\core\servers\basehttp.py:log_message:136 INFO - "GET /api/v1.0/service/menu HTTP/1.1" 200 236
2020-03-19 15:35:01,133 [Thread-2: 7620]C:\Users\Administrator\AppData\Local\Programs\Python\Python36\lib\site-packages\django\core\servers\basehttp.py:log_message:136 INFO - "GET /api/v1.0/service/menu HTTP/1.1" 200 236
2020-03-19 15:35:50,127 [Thread-2: 7620]C:\Users\Administrator\AppData\Local\Programs\Python\Python36\lib\site-packages\django\core\servers\basehttp.py:log_message:136 INFO - "GET /api/v1.0/service/menu HTTP/1.1" 200 236
2020-03-19 15:36:05,363 [Thread-2: 7620]C:\Users\Administrator\AppData\Local\Programs\Python\Python36\lib\site-packages\django\core\servers\basehttp.py:log_message:136 INFO - "GET /api/v1.0/service/menu HTTP/1.1" 200 236
2020-03-19 15:40:33,061 [Thread-2: 7620]C:\Users\Administrator\AppData\Local\Programs\Python\Python36\lib\site-packages\django\core\servers\basehttp.py:log_message:136 INFO - "GET /api/v1.0/service/menu HTTP/1.1" 200 236
2020-03-19 15:42:05,505 [Thread-2: 7620]C:\Users\Administrator\AppData\Local\Programs\Python\Python36\lib\site-packages\django\core\servers\basehttp.py:log_message:136 INFO - "GET /api/v1.0/service/menu HTTP/1.1" 200 236
2020-03-19 15:42:22,859 [Thread-2: 7620]C:\Users\Administrator\AppData\Local\Programs\Python\Python36\lib\site-packages\django\core\servers\basehttp.py:log_message:136 INFO - "GET /api/v1.0/service/menu HTTP/1.1" 200 236
2020-03-19 15:43:13,319 [Thread-2: 7620]C:\Users\Administrator\AppData\Local\Programs\Python\Python36\lib\site-packages\django\core\servers\basehttp.py:log_message:136 INFO - "GET /api/v1.0/service/menu HTTP/1.1" 200 236
2020-03-19 15:47:36,040 [Thread-2: 7620]C:\Users\Administrator\AppData\Local\Programs\Python\Python36\lib\site-packages\django\core\servers\basehttp.py:log_message:136 INFO - "GET /api/v1.0/service/menu HTTP/1.1" 200 236
2020-03-19 15:47:45,466 [Thread-2: 7620]C:\Users\Administrator\AppData\Local\Programs\Python\Python36\lib\site-packages\django\core\servers\basehttp.py:log_message:136 INFO - "GET /api/v1.0/service/menu HTTP/1.1" 200 236
2020-03-19 15:48:26,022 [Thread-2: 7620]C:\Users\Administrator\AppData\Local\Programs\Python\Python36\lib\site-packages\django\core\servers\basehttp.py:log_message:136 INFO - "GET /api/v1.0/auth/status HTTP/1.1" 200 70
2020-03-19 15:48:26,094 [Thread-2: 7620]C:\Users\Administrator\AppData\Local\Programs\Python\Python36\lib\site-packages\django\core\servers\basehttp.py:log_message:136 INFO - "GET /api/v1.0/auth/status HTTP/1.1" 200 70
2020-03-19 15:48:27,168 [Thread-2: 7620]C:\Users\Administrator\AppData\Local\Programs\Python\Python36\lib\site-packages\django\core\servers\basehttp.py:log_message:136 INFO - "GET /api/v1.0/service/sch_engineer?type=backstage HTTP/1.1" 200 64
2020-03-19 15:48:27,234 [Thread-2: 7620]C:\Users\Administrator\AppData\Local\Programs\Python\Python36\lib\site-packages\django\core\servers\basehttp.py:log_message:136 INFO - "GET /api/v1.0/service/sch_engineer?type=backstage HTTP/1.1" 200 64
2020-03-19 15:48:36,063 [Thread-2: 7620]C:\Users\Administrator\AppData\Local\Programs\Python\Python36\lib\site-packages\django\core\servers\basehttp.py:log_message:136 INFO - "GET /api/v1.0/auth/status HTTP/1.1" 200 70
2020-03-19 15:48:47,136 [Thread-2: 7620]C:\Users\Administrator\AppData\Local\Programs\Python\Python36\lib\site-packages\django\core\servers\basehttp.py:log_message:136 INFO - "POST /api/v1.0/service/sch_engineer HTTP/1.1" 200 40
2020-03-19 15:48:48,168 [Thread-2: 7620]C:\Users\Administrator\AppData\Local\Programs\Python\Python36\lib\site-packages\django\core\servers\basehttp.py:log_message:136 INFO - "GET /api/v1.0/service/sch_engineer?type=backstage HTTP/1.1" 200 226
2020-03-19 15:48:55,695 [Thread-2: 7620]C:\Users\Administrator\AppData\Local\Programs\Python\Python36\lib\site-packages\django\core\servers\basehttp.py:log_message:136 INFO - "POST /api/v1.0/auth/authorize HTTP/1.1" 200 73
2020-03-19 15:48:56,733 [Thread-2: 7620]C:\Users\Administrator\AppData\Local\Programs\Python\Python36\lib\site-packages\django\core\servers\basehttp.py:log_message:136 INFO - "GET /api/v1.0/auth/status HTTP/1.1" 200 70
2020-03-19 15:48:57,585 [Thread-2: 7620]C:\Users\Administrator\AppData\Local\Programs\Python\Python36\lib\site-packages\django\core\servers\basehttp.py:log_message:136 INFO - "GET /api/v1.0/service/sch_engineer?type=backstage HTTP/1.1" 200 222
2020-03-19 08:17:26,106 [uWSGIWorker1Core0: 140563316180800]/home/ubuntu/.local/lib/python3.6/site-packages/django/core/handlers/exception.py:response_for_exception:74 ERROR - Invalid HTTP_HOST header: 'uwsgi'. You may need to add 'uwsgi' to ALLOWED_HOSTS.
2020-03-20 09:42:33,141 [Thread-2: 6276]C:\Users\xuekun\AppData\Roaming\Python\Python36\site-packages\django\core\servers\basehttp.py:log_message:124 INFO - "GET /api/v1.0/service/menu HTTP/1.1" 200 236
2020-03-20 09:44:43,651 [Thread-2: 9168]C:\Users\xuekun\AppData\Roaming\Python\Python36\site-packages\django\core\servers\basehttp.py:log_message:124 INFO - "POST /api/v1.0/auth/authorize HTTP/1.1" 200 73
2020-03-20 09:44:46,846 [Thread-3: 6716]C:\Users\xuekun\AppData\Roaming\Python\Python36\site-packages\django\core\servers\basehttp.py:log_message:124 INFO - "GET /api/v1.0/auth/status HTTP/1.1" 200 70
2020-03-20 09:44:46,900 [Thread-4: 13956]C:\Users\xuekun\AppData\Roaming\Python\Python36\site-packages\django\core\servers\basehttp.py:log_message:124 INFO - "GET /api/v1.0/auth/status HTTP/1.1" 200 70
2020-03-20 09:45:08,118 [Thread-5: 3400]C:\Users\xuekun\AppData\Roaming\Python\Python36\site-packages\django\core\servers\basehttp.py:log_message:124 INFO - "POST /api/v1.0/service/sch_engineer HTTP/1.1" 200 40
2020-03-20 09:49:22,948 [Thread-2: 5696]C:\Users\xuekun\AppData\Roaming\Python\Python36\site-packages\django\core\handlers\exception.py:handle_uncaught_exception:118 ERROR - Internal Server Error: /api/v1.0/service/sch_engineer
Traceback (most recent call last):
  File "C:\Users\xuekun\AppData\Roaming\Python\Python36\site-packages\django\core\handlers\exception.py", line 35, in inner
    response = get_response(request)
  File "C:\Users\xuekun\AppData\Roaming\Python\Python36\site-packages\django\core\handlers\base.py", line 128, in _get_response
    response = self.process_exception_by_middleware(e, request)
  File "C:\Users\xuekun\AppData\Roaming\Python\Python36\site-packages\django\core\handlers\base.py", line 126, in _get_response
    response = wrapped_callback(request, *callback_args, **callback_kwargs)
  File "C:\Users\xuekun\AppData\Roaming\Python\Python36\site-packages\django\views\decorators\csrf.py", line 54, in wrapped_view
    return view_func(*args, **kwargs)
  File "C:\Users\xuekun\AppData\Roaming\Python\Python36\site-packages\django\views\generic\base.py", line 69, in view
    return self.dispatch(request, *args, **kwargs)
  File "C:\python3.6\lib\site-packages\rest_framework\views.py", line 505, in dispatch
    response = self.handle_exception(exc)
  File "C:\python3.6\lib\site-packages\rest_framework\views.py", line 465, in handle_exception
    self.raise_uncaught_exception(exc)
  File "C:\python3.6\lib\site-packages\rest_framework\views.py", line 476, in raise_uncaught_exception
    raise exc
  File "C:\python3.6\lib\site-packages\rest_framework\views.py", line 502, in dispatch
    response = handler(request, *args, **kwargs)
  File "C:\Users\xuekun\Desktop\school_engineer-master\school_engineer-master\backend\apis\views\sch_engineer.py", line 54, in post
    one_day_count=device_question.objects.filter(openid=open_id,q_date=q_date).count()
  File "C:\Users\xuekun\AppData\Roaming\Python\Python36\site-packages\django\db\models\manager.py", line 82, in manager_method
    return getattr(self.get_queryset(), name)(*args, **kwargs)
  File "C:\Users\xuekun\AppData\Roaming\Python\Python36\site-packages\django\db\models\query.py", line 836, in filter
    return self._filter_or_exclude(False, *args, **kwargs)
  File "C:\Users\xuekun\AppData\Roaming\Python\Python36\site-packages\django\db\models\query.py", line 854, in _filter_or_exclude
    clone.query.add_q(Q(*args, **kwargs))
  File "C:\Users\xuekun\AppData\Roaming\Python\Python36\site-packages\django\db\models\sql\query.py", line 1253, in add_q
    clause, _ = self._add_q(q_object, self.used_aliases)
  File "C:\Users\xuekun\AppData\Roaming\Python\Python36\site-packages\django\db\models\sql\query.py", line 1277, in _add_q
    split_subq=split_subq,
  File "C:\Users\xuekun\AppData\Roaming\Python\Python36\site-packages\django\db\models\sql\query.py", line 1153, in build_filter
    lookups, parts, reffed_expression = self.solve_lookup_type(arg)
  File "C:\Users\xuekun\AppData\Roaming\Python\Python36\site-packages\django\db\models\sql\query.py", line 1015, in solve_lookup_type
    _, field, _, lookup_parts = self.names_to_path(lookup_splitted, self.get_meta())
  File "C:\Users\xuekun\AppData\Roaming\Python\Python36\site-packages\django\db\models\sql\query.py", line 1379, in names_to_path
    "Choices are: %s" % (name, ", ".join(available)))
django.core.exceptions.FieldError: Cannot resolve keyword 'openid' into field. Choices are: classes, grade, id, q_date, q_dealing, q_over, question, user_openid
2020-03-20 09:49:23,146 [Thread-2: 5696]C:\Users\xuekun\AppData\Roaming\Python\Python36\site-packages\django\core\servers\basehttp.py:log_message:124 ERROR - "POST /api/v1.0/service/sch_engineer HTTP/1.1" 500 18929
2020-03-20 09:50:00,684 [Thread-2: 7068]C:\Users\xuekun\AppData\Roaming\Python\Python36\site-packages\django\core\servers\basehttp.py:log_message:124 INFO - "POST /api/v1.0/service/sch_engineer HTTP/1.1" 200 40
2020-03-20 09:50:04,251 [Thread-3: 12664]C:\Users\xuekun\AppData\Roaming\Python\Python36\site-packages\django\core\servers\basehttp.py:log_message:124 INFO - "POST /api/v1.0/service/sch_engineer HTTP/1.1" 200 40
2020-03-20 09:50:09,060 [Thread-4: 13468]C:\Users\xuekun\AppData\Roaming\Python\Python36\site-packages\django\core\servers\basehttp.py:log_message:124 INFO - "POST /api/v1.0/service/sch_engineer HTTP/1.1" 200 40
2020-03-20 09:52:46,261 [Thread-2: 4596]C:\Users\xuekun\AppData\Roaming\Python\Python36\site-packages\django\core\servers\basehttp.py:log_message:124 INFO - "POST /api/v1.0/service/sch_engineer HTTP/1.1" 200 48
2020-03-20 09:52:53,303 [Thread-3: 13448]C:\Users\xuekun\AppData\Roaming\Python\Python36\site-packages\django\core\servers\basehttp.py:log_message:124 INFO - "POST /api/v1.0/service/sch_engineer HTTP/1.1" 200 48
2020-03-20 09:53:14,034 [Thread-4: 11828]C:\Users\xuekun\AppData\Roaming\Python\Python36\site-packages\django\core\servers\basehttp.py:log_message:124 INFO - "GET /api/v1.0/service/menu HTTP/1.1" 200 236
2020-03-20 09:53:27,271 [Thread-5: 3264]C:\Users\xuekun\AppData\Roaming\Python\Python36\site-packages\django\core\servers\basehttp.py:log_message:124 INFO - "GET /api/v1.0/auth/status HTTP/1.1" 200 70
2020-03-20 09:53:27,569 [Thread-6: 12396]C:\Users\xuekun\AppData\Roaming\Python\Python36\site-packages\django\core\servers\basehttp.py:log_message:124 INFO - "GET /api/v1.0/auth/status HTTP/1.1" 200 70
2020-03-20 09:53:29,873 [Thread-7: 13416]C:\Users\xuekun\AppData\Roaming\Python\Python36\site-packages\django\core\handlers\exception.py:handle_uncaught_exception:118 ERROR - Internal Server Error: /api/v1.0/service/sch_engineer
Traceback (most recent call last):
  File "C:\Users\xuekun\AppData\Roaming\Python\Python36\site-packages\django\core\handlers\exception.py", line 35, in inner
    response = get_response(request)
  File "C:\Users\xuekun\AppData\Roaming\Python\Python36\site-packages\django\core\handlers\base.py", line 128, in _get_response
    response = self.process_exception_by_middleware(e, request)
  File "C:\Users\xuekun\AppData\Roaming\Python\Python36\site-packages\django\core\handlers\base.py", line 126, in _get_response
    response = wrapped_callback(request, *callback_args, **callback_kwargs)
  File "C:\Users\xuekun\AppData\Roaming\Python\Python36\site-packages\django\views\decorators\csrf.py", line 54, in wrapped_view
    return view_func(*args, **kwargs)
  File "C:\Users\xuekun\AppData\Roaming\Python\Python36\site-packages\django\views\generic\base.py", line 69, in view
    return self.dispatch(request, *args, **kwargs)
  File "C:\python3.6\lib\site-packages\rest_framework\views.py", line 505, in dispatch
    response = self.handle_exception(exc)
  File "C:\python3.6\lib\site-packages\rest_framework\views.py", line 465, in handle_exception
    self.raise_uncaught_exception(exc)
  File "C:\python3.6\lib\site-packages\rest_framework\views.py", line 476, in raise_uncaught_exception
    raise exc
  File "C:\python3.6\lib\site-packages\rest_framework\views.py", line 502, in dispatch
    response = handler(request, *args, **kwargs)
  File "C:\Users\xuekun\Desktop\school_engineer-master\school_engineer-master\backend\apis\views\sch_engineer.py", line 54, in post
    one_day_count=device_question.objects.filter(user_openid=open_id,q_date=q_date).count()
  File "C:\Users\xuekun\AppData\Roaming\Python\Python36\site-packages\django\db\models\manager.py", line 82, in manager_method
    return getattr(self.get_queryset(), name)(*args, **kwargs)
  File "C:\Users\xuekun\AppData\Roaming\Python\Python36\site-packages\django\db\models\query.py", line 836, in filter
    return self._filter_or_exclude(False, *args, **kwargs)
  File "C:\Users\xuekun\AppData\Roaming\Python\Python36\site-packages\django\db\models\query.py", line 854, in _filter_or_exclude
    clone.query.add_q(Q(*args, **kwargs))
  File "C:\Users\xuekun\AppData\Roaming\Python\Python36\site-packages\django\db\models\sql\query.py", line 1253, in add_q
    clause, _ = self._add_q(q_object, self.used_aliases)
  File "C:\Users\xuekun\AppData\Roaming\Python\Python36\site-packages\django\db\models\sql\query.py", line 1277, in _add_q
    split_subq=split_subq,
  File "C:\Users\xuekun\AppData\Roaming\Python\Python36\site-packages\django\db\models\sql\query.py", line 1215, in build_filter
    condition = self.build_lookup(lookups, col, value)
  File "C:\Users\xuekun\AppData\Roaming\Python\Python36\site-packages\django\db\models\sql\query.py", line 1085, in build_lookup
    lookup = lookup_class(lhs, rhs)
  File "C:\Users\xuekun\AppData\Roaming\Python\Python36\site-packages\django\db\models\lookups.py", line 18, in __init__
    self.rhs = self.get_prep_lookup()
  File "C:\Users\xuekun\AppData\Roaming\Python\Python36\site-packages\django\db\models\lookups.py", line 68, in get_prep_lookup
    return self.lhs.output_field.get_prep_value(self.rhs)
  File "C:\Users\xuekun\AppData\Roaming\Python\Python36\site-packages\django\db\models\fields\__init__.py", line 1271, in get_prep_value
    return self.to_python(value)
  File "C:\Users\xuekun\AppData\Roaming\Python\Python36\site-packages\django\db\models\fields\__init__.py", line 1246, in to_python
    params={'value': value},
django.core.exceptions.ValidationError: ["'' value has an invalid date format. It must be in YYYY-MM-DD format."]
2020-03-20 09:53:29,946 [Thread-7: 13416]C:\Users\xuekun\AppData\Roaming\Python\Python36\site-packages\django\core\servers\basehttp.py:log_message:124 ERROR - "POST /api/v1.0/service/sch_engineer HTTP/1.1" 500 19242
2020-03-20 09:57:15,111 [Thread-8: 10860]C:\Users\xuekun\AppData\Roaming\Python\Python36\site-packages\django\core\servers\basehttp.py:log_message:124 INFO - "GET /api/v1.0/service/menu HTTP/1.1" 200 236
2020-03-20 09:57:19,253 [Thread-9: 4184]C:\Users\xuekun\AppData\Roaming\Python\Python36\site-packages\django\core\servers\basehttp.py:log_message:124 INFO - "GET /api/v1.0/auth/status HTTP/1.1" 200 70
2020-03-20 09:57:19,295 [Thread-10: 2248]C:\Users\xuekun\AppData\Roaming\Python\Python36\site-packages\django\core\servers\basehttp.py:log_message:124 INFO - "GET /api/v1.0/auth/status HTTP/1.1" 200 70
2020-03-20 09:57:29,107 [Thread-11: 4956]C:\Users\xuekun\AppData\Roaming\Python\Python36\site-packages\django\core\servers\basehttp.py:log_message:124 INFO - "POST /api/v1.0/service/sch_engineer HTTP/1.1" 200 48
2020-03-20 10:02:18,849 [Thread-2: 2712]C:\Users\xuekun\AppData\Roaming\Python\Python36\site-packages\django\core\servers\basehttp.py:log_message:124 INFO - "GET /api/v1.0/service/menu HTTP/1.1" 200 236
2020-03-20 10:02:25,686 [Thread-3: 4852]C:\Users\xuekun\AppData\Roaming\Python\Python36\site-packages\django\core\servers\basehttp.py:log_message:124 INFO - "GET /api/v1.0/auth/status HTTP/1.1" 200 70
2020-03-20 10:02:25,696 [Thread-4: 6208]C:\Users\xuekun\AppData\Roaming\Python\Python36\site-packages\django\core\servers\basehttp.py:log_message:124 INFO - "GET /api/v1.0/auth/status HTTP/1.1" 200 70
2020-03-20 10:02:36,392 [Thread-5: 8348]C:\Users\xuekun\AppData\Roaming\Python\Python36\site-packages\django\core\servers\basehttp.py:log_message:124 INFO - "POST /api/v1.0/service/sch_engineer HTTP/1.1" 200 48
2020-03-20 10:02:59,085 [Thread-6: 8772]C:\Users\xuekun\AppData\Roaming\Python\Python36\site-packages\django\core\servers\basehttp.py:log_message:124 INFO - "POST /api/v1.0/service/sch_engineer HTTP/1.1" 200 40
2020-03-20 10:15:44,391 [Thread-2: 3128]C:\Users\xuekun\AppData\Roaming\Python\Python36\site-packages\django\core\servers\basehttp.py:log_message:124 INFO - "GET /api/v1.0/auth/status HTTP/1.1" 200 70
2020-03-20 10:15:47,811 [Thread-3: 8856]C:\Users\xuekun\AppData\Roaming\Python\Python36\site-packages\django\core\servers\basehttp.py:log_message:124 INFO - "POST /api/v1.0/service/sch_engineer HTTP/1.1" 200 40
2020-03-20 10:15:56,526 [Thread-4: 4600]C:\Users\xuekun\AppData\Roaming\Python\Python36\site-packages\django\core\servers\basehttp.py:log_message:124 INFO - "POST /api/v1.0/service/sch_engineer HTTP/1.1" 200 48
2020-03-20 10:16:03,314 [Thread-5: 14324]C:\Users\xuekun\AppData\Roaming\Python\Python36\site-packages\django\core\servers\basehttp.py:log_message:124 INFO - "POST /api/v1.0/service/sch_engineer HTTP/1.1" 200 48
2020-03-20 10:19:30,989 [Thread-2: 4600]C:\Users\xuekun\AppData\Roaming\Python\Python36\site-packages\django\core\servers\basehttp.py:log_message:124 INFO - "GET /api/v1.0/service/menu HTTP/1.1" 200 236
2020-03-20 10:19:36,841 [Thread-4: 4980]C:\Users\xuekun\AppData\Roaming\Python\Python36\site-packages\django\core\servers\basehttp.py:log_message:124 INFO - "GET /api/v1.0/auth/status HTTP/1.1" 200 70
2020-03-20 10:19:36,853 [Thread-3: 9012]C:\Users\xuekun\AppData\Roaming\Python\Python36\site-packages\django\core\servers\basehttp.py:log_message:124 INFO - "GET /api/v1.0/auth/status HTTP/1.1" 200 70
2020-03-20 10:19:45,819 [Thread-5: 5412]C:\Users\xuekun\AppData\Roaming\Python\Python36\site-packages\django\core\servers\basehttp.py:log_message:124 INFO - "POST /api/v1.0/service/sch_engineer HTTP/1.1" 200 48
2020-03-20 10:19:52,896 [Thread-6: 6956]C:\Users\xuekun\AppData\Roaming\Python\Python36\site-packages\django\core\servers\basehttp.py:log_message:124 INFO - "POST /api/v1.0/service/sch_engineer HTTP/1.1" 200 40
2020-03-20 10:23:01,887 [Thread-7: 4132]C:\Users\xuekun\AppData\Roaming\Python\Python36\site-packages\django\core\servers\basehttp.py:log_message:124 INFO - "GET /api/v1.0/service/menu HTTP/1.1" 200 236
2020-03-20 10:23:07,249 [Thread-8: 3560]C:\Users\xuekun\AppData\Roaming\Python\Python36\site-packages\django\core\servers\basehttp.py:log_message:124 INFO - "GET /api/v1.0/auth/status HTTP/1.1" 200 70
2020-03-20 10:23:07,273 [Thread-9: 32]C:\Users\xuekun\AppData\Roaming\Python\Python36\site-packages\django\core\servers\basehttp.py:log_message:124 INFO - "GET /api/v1.0/auth/status HTTP/1.1" 200 70
2020-03-20 10:23:18,441 [Thread-10: 7516]C:\Users\xuekun\AppData\Roaming\Python\Python36\site-packages\django\core\servers\basehttp.py:log_message:124 INFO - "POST /api/v1.0/service/sch_engineer HTTP/1.1" 200 40
2020-03-20 10:23:22,728 [Thread-11: 5452]C:\Users\xuekun\AppData\Roaming\Python\Python36\site-packages\django\core\servers\basehttp.py:log_message:124 INFO - "POST /api/v1.0/service/sch_engineer HTTP/1.1" 200 40
2020-03-20 10:23:27,095 [Thread-12: 2240]C:\Users\xuekun\AppData\Roaming\Python\Python36\site-packages\django\core\servers\basehttp.py:log_message:124 INFO - "POST /api/v1.0/service/sch_engineer HTTP/1.1" 200 48
2020-03-20 10:27:47,271 [Thread-13: 13832]C:\Users\xuekun\AppData\Roaming\Python\Python36\site-packages\django\core\servers\basehttp.py:log_message:124 INFO - "GET /api/v1.0/service/menu HTTP/1.1" 200 236
2020-03-20 10:29:30,633 [Thread-14: 408]C:\Users\xuekun\AppData\Roaming\Python\Python36\site-packages\django\core\servers\basehttp.py:log_message:124 INFO - "GET /api/v1.0/service/menu HTTP/1.1" 200 236
2020-03-20 10:33:52,321 [Thread-2: 6068]C:\Users\xuekun\AppData\Roaming\Python\Python36\site-packages\django\core\servers\basehttp.py:log_message:124 INFO - "POST /api/v1.0/auth/authorize HTTP/1.1" 200 73
2020-03-20 10:42:13,197 [Thread-2: 10348]C:\Users\xuekun\AppData\Roaming\Python\Python36\site-packages\django\core\servers\basehttp.py:log_message:124 INFO - "GET /api/v1.0/service/menu HTTP/1.1" 200 236
2020-03-20 10:42:49,536 [Thread-3: 3292]C:\Users\xuekun\AppData\Roaming\Python\Python36\site-packages\django\core\servers\basehttp.py:log_message:124 INFO - "GET /api/v1.0/service/menu HTTP/1.1" 200 236
2020-03-20 10:44:10,193 [Thread-4: 5532]C:\Users\xuekun\AppData\Roaming\Python\Python36\site-packages\django\core\servers\basehttp.py:log_message:124 INFO - "GET /api/v1.0/service/menu HTTP/1.1" 200 236
2020-03-20 10:45:08,942 [Thread-5: 11596]C:\Users\xuekun\AppData\Roaming\Python\Python36\site-packages\django\core\servers\basehttp.py:log_message:124 INFO - "GET /api/v1.0/service/menu HTTP/1.1" 200 236
2020-03-20 10:46:15,966 [Thread-6: 7388]C:\Users\xuekun\AppData\Roaming\Python\Python36\site-packages\django\core\servers\basehttp.py:log_message:124 INFO - "GET /api/v1.0/service/menu HTTP/1.1" 200 236
2020-03-20 10:46:42,475 [Thread-7: 10476]C:\Users\xuekun\AppData\Roaming\Python\Python36\site-packages\django\core\servers\basehttp.py:log_message:124 INFO - "GET /api/v1.0/service/menu HTTP/1.1" 200 236
2020-03-20 10:47:08,813 [Thread-8: 1220]C:\Users\xuekun\AppData\Roaming\Python\Python36\site-packages\django\core\servers\basehttp.py:log_message:124 INFO - "GET /api/v1.0/service/menu HTTP/1.1" 200 236
2020-03-20 10:49:06,791 [Thread-9: 6596]C:\Users\xuekun\AppData\Roaming\Python\Python36\site-packages\django\core\servers\basehttp.py:log_message:124 INFO - "GET /api/v1.0/service/menu HTTP/1.1" 200 236
2020-03-20 10:51:42,012 [Thread-10: 13368]C:\Users\xuekun\AppData\Roaming\Python\Python36\site-packages\django\core\servers\basehttp.py:log_message:124 INFO - "GET /api/v1.0/service/menu HTTP/1.1" 200 236
2020-03-20 10:53:58,303 [Thread-11: 14404]C:\Users\xuekun\AppData\Roaming\Python\Python36\site-packages\django\core\servers\basehttp.py:log_message:124 INFO - "GET /api/v1.0/service/menu HTTP/1.1" 200 236
2020-03-20 10:54:11,695 [Thread-12: 14168]C:\Users\xuekun\AppData\Roaming\Python\Python36\site-packages\django\core\servers\basehttp.py:log_message:124 INFO - "POST /api/v1.0/auth/authorize HTTP/1.1" 200 61
2020-03-20 10:54:13,067 [Thread-13: 8916]C:\Users\xuekun\AppData\Roaming\Python\Python36\site-packages\django\core\servers\basehttp.py:log_message:124 INFO - "GET /api/v1.0/auth/status HTTP/1.1" 200 70
2020-03-20 10:54:13,122 [Thread-14: 2716]C:\Users\xuekun\AppData\Roaming\Python\Python36\site-packages\django\core\servers\basehttp.py:log_message:124 INFO - "GET /api/v1.0/auth/status HTTP/1.1" 200 70
2020-03-20 10:54:15,292 [Thread-15: 14456]C:\Users\xuekun\AppData\Roaming\Python\Python36\site-packages\django\core\servers\basehttp.py:log_message:124 INFO - "GET /api/v1.0/auth/status HTTP/1.1" 200 70
2020-03-20 10:54:31,410 [Thread-16: 8196]C:\Users\xuekun\AppData\Roaming\Python\Python36\site-packages\django\core\servers\basehttp.py:log_message:124 INFO - "GET /api/v1.0/auth/status HTTP/1.1" 200 70
2020-03-20 10:55:42,513 [Thread-17: 6360]C:\Users\xuekun\AppData\Roaming\Python\Python36\site-packages\django\core\servers\basehttp.py:log_message:124 INFO - "GET /api/v1.0/auth/logout HTTP/1.1" 200 48
2020-03-20 10:55:43,906 [Thread-18: 3440]C:\Users\xuekun\AppData\Roaming\Python\Python36\site-packages\django\core\servers\basehttp.py:log_message:124 INFO - "POST /api/v1.0/auth/authorize HTTP/1.1" 200 61
2020-03-20 10:57:16,053 [Thread-19: 480]C:\Users\xuekun\AppData\Roaming\Python\Python36\site-packages\django\core\servers\basehttp.py:log_message:124 INFO - "GET /api/v1.0/service/menu HTTP/1.1" 200 236
2020-03-20 10:57:26,192 [Thread-20: 11760]C:\Users\xuekun\AppData\Roaming\Python\Python36\site-packages\django\core\servers\basehttp.py:log_message:124 INFO - "POST /api/v1.0/auth/authorize HTTP/1.1" 200 73
2020-03-20 10:57:27,656 [Thread-21: 7636]C:\Users\xuekun\AppData\Roaming\Python\Python36\site-packages\django\core\servers\basehttp.py:log_message:124 INFO - "GET /api/v1.0/auth/status HTTP/1.1" 200 70
2020-03-20 10:57:27,812 [Thread-22: 3404]C:\Users\xuekun\AppData\Roaming\Python\Python36\site-packages\django\core\servers\basehttp.py:log_message:124 INFO - "GET /api/v1.0/auth/status HTTP/1.1" 200 70
2020-03-20 10:57:29,478 [Thread-23: 14468]C:\Users\xuekun\AppData\Roaming\Python\Python36\site-packages\django\core\servers\basehttp.py:log_message:124 INFO - "GET /api/v1.0/service/sch_engineer?type=backstage HTTP/1.1" 200 2260
2020-03-20 10:57:29,500 [Thread-24: 10996]C:\Users\xuekun\AppData\Roaming\Python\Python36\site-packages\django\core\servers\basehttp.py:log_message:124 INFO - "GET /api/v1.0/service/sch_engineer?type=backstage HTTP/1.1" 200 2260
2020-03-20 11:07:20,296 [Thread-2: 3988]C:\Users\xuekun\AppData\Roaming\Python\Python36\site-packages\django\core\servers\basehttp.py:log_message:124 INFO - "GET /api/v1.0/service/menu HTTP/1.1" 200 236
2020-03-20 11:08:54,017 [Thread-7: 3976]C:\Users\xuekun\AppData\Roaming\Python\Python36\site-packages\django\core\servers\basehttp.py:log_message:124 INFO - "POST /api/v1.0/auth/authorize HTTP/1.1" 200 73
2020-03-20 11:08:55,739 [Thread-8: 14360]C:\Users\xuekun\AppData\Roaming\Python\Python36\site-packages\django\core\servers\basehttp.py:log_message:124 INFO - "GET /api/v1.0/auth/status HTTP/1.1" 200 70
2020-03-20 11:08:58,539 [Thread-10: 488]C:\Users\xuekun\AppData\Roaming\Python\Python36\site-packages\django\core\servers\basehttp.py:log_message:124 INFO - "GET /api/v1.0/service/sch_engineer?type=backstage HTTP/1.1" 200 2264
2020-03-20 11:08:58,571 [Thread-9: 8212]C:\Users\xuekun\AppData\Roaming\Python\Python36\site-packages\django\core\servers\basehttp.py:log_message:124 INFO - "GET /api/v1.0/service/sch_engineer?type=backstage HTTP/1.1" 200 2264
2020-03-20 11:10:39,366 [Thread-2: 8864]C:\Users\xuekun\AppData\Roaming\Python\Python36\site-packages\django\core\servers\basehttp.py:log_message:124 INFO - "GET /api/v1.0/service/menu HTTP/1.1" 200 236
2020-03-20 11:11:02,153 [Thread-4: 2808]C:\Users\xuekun\AppData\Roaming\Python\Python36\site-packages\django\core\servers\basehttp.py:log_message:124 INFO - "POST /api/v1.0/auth/authorize HTTP/1.1" 200 61
2020-03-20 11:11:05,120 [Thread-5: 2796]C:\Users\xuekun\AppData\Roaming\Python\Python36\site-packages\django\core\servers\basehttp.py:log_message:124 INFO - "GET /api/v1.0/auth/status HTTP/1.1" 200 70
2020-03-20 11:11:05,324 [Thread-6: 11600]C:\Users\xuekun\AppData\Roaming\Python\Python36\site-packages\django\core\servers\basehttp.py:log_message:124 INFO - "GET /api/v1.0/auth/status HTTP/1.1" 200 70
2020-03-20 11:11:13,557 [Thread-7: 6460]C:\Users\xuekun\AppData\Roaming\Python\Python36\site-packages\django\core\servers\basehttp.py:log_message:124 INFO - "GET /api/v1.0/auth/logout HTTP/1.1" 200 48
2020-03-20 11:11:14,567 [Thread-8: 6284]C:\Users\xuekun\AppData\Roaming\Python\Python36\site-packages\django\core\servers\basehttp.py:log_message:124 INFO - "POST /api/v1.0/auth/authorize HTTP/1.1" 200 73
2020-03-20 11:11:21,666 [Thread-9: 8576]C:\Users\xuekun\AppData\Roaming\Python\Python36\site-packages\django\core\servers\basehttp.py:log_message:124 INFO - "GET /api/v1.0/service/sch_engineer?type=backstage HTTP/1.1" 200 2264
2020-03-20 11:11:21,889 [Thread-10: 6604]C:\Users\xuekun\AppData\Roaming\Python\Python36\site-packages\django\core\servers\basehttp.py:log_message:124 INFO - "GET /api/v1.0/service/sch_engineer?type=backstage HTTP/1.1" 200 2264
2020-03-20 11:11:32,642 [Thread-11: 9232]C:\Users\xuekun\AppData\Roaming\Python\Python36\site-packages\django\core\servers\basehttp.py:log_message:124 INFO - "GET /api/v1.0/auth/logout HTTP/1.1" 200 48
2020-03-20 11:11:33,738 [Thread-12: 14588]C:\Users\xuekun\AppData\Roaming\Python\Python36\site-packages\django\core\servers\basehttp.py:log_message:124 INFO - "POST /api/v1.0/auth/authorize HTTP/1.1" 200 73
2020-03-20 11:11:35,018 [Thread-13: 10960]C:\Users\xuekun\AppData\Roaming\Python\Python36\site-packages\django\core\servers\basehttp.py:log_message:124 INFO - "GET /api/v1.0/auth/status HTTP/1.1" 200 70
2020-03-20 11:11:37,430 [Thread-14: 13348]C:\Users\xuekun\AppData\Roaming\Python\Python36\site-packages\django\core\servers\basehttp.py:log_message:124 INFO - "GET /api/v1.0/service/sch_engineer?type=backstage HTTP/1.1" 200 2260
2020-03-20 11:11:40,248 [Thread-15: 10900]C:\Users\xuekun\AppData\Roaming\Python\Python36\site-packages\django\core\servers\basehttp.py:log_message:124 INFO - "GET /api/v1.0/service/sch_engineer?type=history HTTP/1.1" 200 2260
2020-03-20 11:11:40,341 [Thread-16: 4264]C:\Users\xuekun\AppData\Roaming\Python\Python36\site-packages\django\core\servers\basehttp.py:log_message:124 INFO - "GET /api/v1.0/service/sch_engineer?type=history HTTP/1.1" 200 2260
2020-03-20 11:11:44,893 [Thread-17: 4812]C:\Users\xuekun\AppData\Roaming\Python\Python36\site-packages\django\core\servers\basehttp.py:log_message:124 INFO - "GET /api/v1.0/service/sch_engineer?type=backstage HTTP/1.1" 200 2260
2020-03-20 12:10:52,798 [Thread-2: 5572]C:\Users\xuekun\AppData\Roaming\Python\Python36\site-packages\django\core\servers\basehttp.py:log_message:124 INFO - "GET /api/v1.0/auth/logout HTTP/1.1" 200 48
2020-03-20 12:10:54,875 [Thread-3: 16228]C:\Users\xuekun\AppData\Roaming\Python\Python36\site-packages\django\core\servers\basehttp.py:log_message:124 INFO - "POST /api/v1.0/auth/authorize HTTP/1.1" 200 73
2020-03-20 12:10:57,249 [Thread-4: 3288]C:\Users\xuekun\AppData\Roaming\Python\Python36\site-packages\django\core\servers\basehttp.py:log_message:124 INFO - "GET /api/v1.0/auth/status HTTP/1.1" 200 70
2020-03-20 12:10:59,447 [Thread-5: 6560]C:\Users\xuekun\AppData\Roaming\Python\Python36\site-packages\django\core\servers\basehttp.py:log_message:124 INFO - "GET /api/v1.0/service/sch_engineer?type=backstage HTTP/1.1" 200 2264
2020-03-20 12:11:13,113 [Thread-6: 14440]C:\Users\xuekun\AppData\Roaming\Python\Python36\site-packages\django\core\servers\basehttp.py:log_message:124 INFO - "GET /api/v1.0/auth/logout HTTP/1.1" 200 48
2020-03-20 12:11:14,117 [Thread-7: 11708]C:\Users\xuekun\AppData\Roaming\Python\Python36\site-packages\django\core\servers\basehttp.py:log_message:124 INFO - "POST /api/v1.0/auth/authorize HTTP/1.1" 200 73
2020-03-20 12:11:15,967 [Thread-8: 17032]C:\Users\xuekun\AppData\Roaming\Python\Python36\site-packages\django\core\servers\basehttp.py:log_message:124 INFO - "GET /api/v1.0/auth/status HTTP/1.1" 200 70
2020-03-20 12:11:18,061 [Thread-9: 16780]C:\Users\xuekun\AppData\Roaming\Python\Python36\site-packages\django\core\servers\basehttp.py:log_message:124 INFO - "GET /api/v1.0/service/sch_engineer?type=backstage HTTP/1.1" 200 2260
2020-03-20 12:11:19,959 [Thread-10: 420]C:\Users\xuekun\AppData\Roaming\Python\Python36\site-packages\django\core\servers\basehttp.py:log_message:124 INFO - "PUT /api/v1.0/service/sch_engineer HTTP/1.1" 200 2
2020-03-20 12:11:20,048 [Thread-11: 17404]C:\Users\xuekun\AppData\Roaming\Python\Python36\site-packages\django\core\servers\basehttp.py:log_message:124 INFO - "GET /api/v1.0/service/sch_engineer?type=backstage HTTP/1.1" 200 2259
2020-03-20 12:11:21,349 [Thread-12: 17372]C:\Users\xuekun\AppData\Roaming\Python\Python36\site-packages\django\core\servers\basehttp.py:log_message:124 INFO - "PUT /api/v1.0/service/sch_engineer HTTP/1.1" 200 2
2020-03-20 12:11:21,416 [Thread-13: 17368]C:\Users\xuekun\AppData\Roaming\Python\Python36\site-packages\django\core\servers\basehttp.py:log_message:124 INFO - "GET /api/v1.0/service/sch_engineer?type=backstage HTTP/1.1" 200 2258
2020-03-20 12:11:22,504 [Thread-14: 17308]C:\Users\xuekun\AppData\Roaming\Python\Python36\site-packages\django\core\servers\basehttp.py:log_message:124 INFO - "PUT /api/v1.0/service/sch_engineer HTTP/1.1" 200 2
2020-03-20 12:11:22,569 [Thread-15: 9200]C:\Users\xuekun\AppData\Roaming\Python\Python36\site-packages\django\core\servers\basehttp.py:log_message:124 INFO - "GET /api/v1.0/service/sch_engineer?type=backstage HTTP/1.1" 200 2257
2020-03-20 12:11:24,050 [Thread-16: 3376]C:\Users\xuekun\AppData\Roaming\Python\Python36\site-packages\django\core\servers\basehttp.py:log_message:124 INFO - "PUT /api/v1.0/service/sch_engineer HTTP/1.1" 200 2
2020-03-20 12:11:24,122 [Thread-17: 14456]C:\Users\xuekun\AppData\Roaming\Python\Python36\site-packages\django\core\servers\basehttp.py:log_message:124 INFO - "GET /api/v1.0/service/sch_engineer?type=backstage HTTP/1.1" 200 2256
2020-03-20 12:11:28,986 [Thread-18: 15400]C:\Users\xuekun\AppData\Roaming\Python\Python36\site-packages\django\core\servers\basehttp.py:log_message:124 INFO - "PUT /api/v1.0/service/sch_engineer HTTP/1.1" 200 2
2020-03-20 12:11:29,076 [Thread-19: 15156]C:\Users\xuekun\AppData\Roaming\Python\Python36\site-packages\django\core\servers\basehttp.py:log_message:124 INFO - "GET /api/v1.0/service/sch_engineer?type=backstage HTTP/1.1" 200 2092
2020-03-20 12:11:31,030 [Thread-20: 16724]C:\Users\xuekun\AppData\Roaming\Python\Python36\site-packages\django\core\servers\basehttp.py:log_message:124 INFO - "PUT /api/v1.0/service/sch_engineer HTTP/1.1" 200 2
2020-03-20 12:11:31,109 [Thread-21: 12192]C:\Users\xuekun\AppData\Roaming\Python\Python36\site-packages\django\core\servers\basehttp.py:log_message:124 INFO - "GET /api/v1.0/service/sch_engineer?type=backstage HTTP/1.1" 200 1883
2020-03-20 12:11:33,078 [Thread-22: 16708]C:\Users\xuekun\AppData\Roaming\Python\Python36\site-packages\django\core\servers\basehttp.py:log_message:124 INFO - "PUT /api/v1.0/service/sch_engineer HTTP/1.1" 200 2
2020-03-20 12:11:33,149 [Thread-23: 16728]C:\Users\xuekun\AppData\Roaming\Python\Python36\site-packages\django\core\servers\basehttp.py:log_message:124 INFO - "GET /api/v1.0/service/sch_engineer?type=backstage HTTP/1.1" 200 1719
2020-03-20 13:39:46,431 [Thread-2: 13372]C:\Users\xuekun\AppData\Roaming\Python\Python36\site-packages\django\core\servers\basehttp.py:log_message:124 INFO - "GET /api/v1.0/auth/logout HTTP/1.1" 200 48
2020-03-20 13:39:49,028 [Thread-3: 15768]C:\Users\xuekun\AppData\Roaming\Python\Python36\site-packages\django\core\servers\basehttp.py:log_message:124 INFO - "POST /api/v1.0/auth/authorize HTTP/1.1" 200 73
2020-03-20 13:39:51,145 [Thread-4: 12148]C:\Users\xuekun\AppData\Roaming\Python\Python36\site-packages\django\core\servers\basehttp.py:log_message:124 INFO - "GET /api/v1.0/auth/status HTTP/1.1" 200 70
2020-03-20 13:40:03,389 [Thread-5: 7588]C:\Users\xuekun\AppData\Roaming\Python\Python36\site-packages\django\core\handlers\exception.py:handle_uncaught_exception:118 ERROR - Internal Server Error: /api/v1.0/service/sch_engineer
Traceback (most recent call last):
  File "C:\Users\xuekun\AppData\Roaming\Python\Python36\site-packages\django\core\handlers\exception.py", line 35, in inner
    response = get_response(request)
  File "C:\Users\xuekun\AppData\Roaming\Python\Python36\site-packages\django\core\handlers\base.py", line 128, in _get_response
    response = self.process_exception_by_middleware(e, request)
  File "C:\Users\xuekun\AppData\Roaming\Python\Python36\site-packages\django\core\handlers\base.py", line 126, in _get_response
    response = wrapped_callback(request, *callback_args, **callback_kwargs)
  File "C:\Users\xuekun\AppData\Roaming\Python\Python36\site-packages\django\views\decorators\csrf.py", line 54, in wrapped_view
    return view_func(*args, **kwargs)
  File "C:\Users\xuekun\AppData\Roaming\Python\Python36\site-packages\django\views\generic\base.py", line 69, in view
    return self.dispatch(request, *args, **kwargs)
  File "C:\python3.6\lib\site-packages\rest_framework\views.py", line 505, in dispatch
    response = self.handle_exception(exc)
  File "C:\python3.6\lib\site-packages\rest_framework\views.py", line 465, in handle_exception
    self.raise_uncaught_exception(exc)
  File "C:\python3.6\lib\site-packages\rest_framework\views.py", line 476, in raise_uncaught_exception
    raise exc
  File "C:\python3.6\lib\site-packages\rest_framework\views.py", line 502, in dispatch
    response = handler(request, *args, **kwargs)
  File "C:\Users\xuekun\Desktop\school_engineer-master\school_engineer-master\backend\apis\views\sch_engineer.py", line 73, in post
    server = smtplib.SMTP_SSL(settings.EMAIL_HOST, settings.EMAIL_PORT)
AttributeError: module 'backend.settings' has no attribute 'EMAIL_HOST'
2020-03-20 13:40:03,505 [Thread-5: 7588]C:\Users\xuekun\AppData\Roaming\Python\Python36\site-packages\django\core\servers\basehttp.py:log_message:124 ERROR - "POST /api/v1.0/service/sch_engineer HTTP/1.1" 500 17270
2020-03-20 13:41:08,056 [Thread-2: 2184]C:\Users\xuekun\AppData\Roaming\Python\Python36\site-packages\django\core\servers\basehttp.py:log_message:124 INFO - "POST /api/v1.0/service/sch_engineer HTTP/1.1" 200 40
2020-03-20 13:48:19,461 [Thread-2: 14612]C:\Users\xuekun\AppData\Roaming\Python\Python36\site-packages\django\core\handlers\exception.py:handle_uncaught_exception:118 ERROR - Internal Server Error: /api/v1.0/service/sch_engineer
Traceback (most recent call last):
  File "C:\python3.6\lib\email\message.py", line 356, in set_charset
    cte(self)
TypeError: 'str' object is not callable

During handling of the above exception, another exception occurred:

Traceback (most recent call last):
  File "C:\Users\xuekun\AppData\Roaming\Python\Python36\site-packages\django\core\handlers\exception.py", line 35, in inner
    response = get_response(request)
  File "C:\Users\xuekun\AppData\Roaming\Python\Python36\site-packages\django\core\handlers\base.py", line 128, in _get_response
    response = self.process_exception_by_middleware(e, request)
  File "C:\Users\xuekun\AppData\Roaming\Python\Python36\site-packages\django\core\handlers\base.py", line 126, in _get_response
    response = wrapped_callback(request, *callback_args, **callback_kwargs)
  File "C:\Users\xuekun\AppData\Roaming\Python\Python36\site-packages\django\views\decorators\csrf.py", line 54, in wrapped_view
    return view_func(*args, **kwargs)
  File "C:\Users\xuekun\AppData\Roaming\Python\Python36\site-packages\django\views\generic\base.py", line 69, in view
    return self.dispatch(request, *args, **kwargs)
  File "C:\python3.6\lib\site-packages\rest_framework\views.py", line 505, in dispatch
    response = self.handle_exception(exc)
  File "C:\python3.6\lib\site-packages\rest_framework\views.py", line 465, in handle_exception
    self.raise_uncaught_exception(exc)
  File "C:\python3.6\lib\site-packages\rest_framework\views.py", line 476, in raise_uncaught_exception
    raise exc
  File "C:\python3.6\lib\site-packages\rest_framework\views.py", line 502, in dispatch
    response = handler(request, *args, **kwargs)
  File "C:\Users\xuekun\Desktop\school_engineer-master\school_engineer-master\backend\apis\views\sch_engineer.py", line 69, in post
    msg = MIMEText(new_question, "plain", "utf-8")
  File "C:\python3.6\lib\email\mime\text.py", line 42, in __init__
    self.set_payload(_text, _charset)
  File "C:\python3.6\lib\email\message.py", line 321, in set_payload
    self.set_charset(charset)
  File "C:\python3.6\lib\email\message.py", line 364, in set_charset
    payload = payload.encode('ascii', 'surrogateescape')
AttributeError: 'dict' object has no attribute 'encode'
2020-03-20 13:48:19,569 [Thread-2: 14612]C:\Users\xuekun\AppData\Roaming\Python\Python36\site-packages\django\core\servers\basehttp.py:log_message:124 ERROR - "POST /api/v1.0/service/sch_engineer HTTP/1.1" 500 17726
2020-03-20 13:49:23,958 [Thread-2: 5116]C:\Users\xuekun\AppData\Roaming\Python\Python36\site-packages\django\core\servers\basehttp.py:log_message:124 INFO - "POST /api/v1.0/service/sch_engineer HTTP/1.1" 200 40
2020-03-20 13:57:55,698 [Thread-2: 16960]C:\Users\xuekun\AppData\Roaming\Python\Python36\site-packages\django\core\servers\basehttp.py:log_message:124 INFO - "POST /api/v1.0/service/sch_engineer HTTP/1.1" 200 40
2020-03-20 14:00:44,647 [Thread-2: 16584]C:\Users\xuekun\AppData\Roaming\Python\Python36\site-packages\django\core\servers\basehttp.py:log_message:124 INFO - "POST /api/v1.0/service/sch_engineer HTTP/1.1" 200 40
2020-03-22 12:59:11,291 [Thread-2: 2988]C:\Users\Administrator\AppData\Local\Programs\Python\Python36\lib\site-packages\django\core\servers\basehttp.py:log_message:136 INFO - "GET /api/v1.0/service/menu HTTP/1.1" 200 236
2020-03-22 13:03:15,855 [Thread-2: 4248]C:\Users\Administrator\AppData\Local\Programs\Python\Python36\lib\site-packages\django\core\servers\basehttp.py:log_message:136 INFO - "GET /api/v1.0/service/sch_engineer?type=backstage HTTP/1.1" 200 60
2020-03-22 13:03:15,858 [Thread-3: 19964]C:\Users\Administrator\AppData\Local\Programs\Python\Python36\lib\site-packages\django\core\servers\basehttp.py:log_message:136 INFO - "GET /api/v1.0/service/sch_engineer?type=backstage HTTP/1.1" 200 60
2020-03-22 13:03:27,790 [Thread-3: 19964]C:\Users\Administrator\AppData\Local\Programs\Python\Python36\lib\site-packages\django\core\servers\basehttp.py:log_message:136 INFO - "POST /api/v1.0/auth/authorize HTTP/1.1" 200 73
2020-03-22 13:03:29,927 [Thread-3: 19964]C:\Users\Administrator\AppData\Local\Programs\Python\Python36\lib\site-packages\django\core\servers\basehttp.py:log_message:136 INFO - "GET /api/v1.0/service/sch_engineer?type=backstage HTTP/1.1" 200 222
2020-03-22 13:03:32,361 [Thread-3: 19964]C:\Users\Administrator\AppData\Local\Programs\Python\Python36\lib\site-packages\django\core\servers\basehttp.py:log_message:136 INFO - "GET /api/v1.0/service/sch_engineer?type=history HTTP/1.1" 200 222
2020-03-22 13:03:32,375 [Thread-3: 19964]C:\Users\Administrator\AppData\Local\Programs\Python\Python36\lib\site-packages\django\core\servers\basehttp.py:log_message:136 INFO - "GET /api/v1.0/service/sch_engineer?type=history HTTP/1.1" 200 222
2020-03-22 13:03:54,741 [Thread-2: 22060]C:\Users\Administrator\AppData\Local\Programs\Python\Python36\lib\site-packages\django\core\servers\basehttp.py:log_message:136 INFO - "GET /api/v1.0/service/sch_engineer?type=backstage HTTP/1.1" 200 222
2020-03-22 13:03:55,797 [Thread-2: 22060]C:\Users\Administrator\AppData\Local\Programs\Python\Python36\lib\site-packages\django\core\servers\basehttp.py:log_message:136 INFO - "GET /api/v1.0/service/sch_engineer?type=history HTTP/1.1" 200 222
2020-03-22 13:03:55,838 [Thread-2: 22060]C:\Users\Administrator\AppData\Local\Programs\Python\Python36\lib\site-packages\django\core\servers\basehttp.py:log_message:136 INFO - "GET /api/v1.0/service/sch_engineer?type=history HTTP/1.1" 200 222
2020-03-22 13:08:04,551 [Thread-2: 14740]C:\Users\Administrator\AppData\Local\Programs\Python\Python36\lib\site-packages\django\core\servers\basehttp.py:log_message:136 INFO - "GET /api/v1.0/service/menu HTTP/1.1" 200 236
2020-03-22 13:08:08,144 [Thread-2: 14740]C:\Users\Administrator\AppData\Local\Programs\Python\Python36\lib\site-packages\django\utils\log.py:log_response:228 ERROR - Internal Server Error: /api/v1.0/service/sch_engineer
Traceback (most recent call last):
  File "C:\Users\Administrator\AppData\Local\Programs\Python\Python36\lib\site-packages\django\core\handlers\exception.py", line 34, in inner
    response = get_response(request)
  File "C:\Users\Administrator\AppData\Local\Programs\Python\Python36\lib\site-packages\django\core\handlers\base.py", line 126, in _get_response
    response = self.process_exception_by_middleware(e, request)
  File "C:\Users\Administrator\AppData\Local\Programs\Python\Python36\lib\site-packages\django\core\handlers\base.py", line 124, in _get_response
    response = wrapped_callback(request, *callback_args, **callback_kwargs)
  File "C:\Users\Administrator\AppData\Local\Programs\Python\Python36\lib\site-packages\django\views\decorators\csrf.py", line 54, in wrapped_view
    return view_func(*args, **kwargs)
  File "C:\Users\Administrator\AppData\Local\Programs\Python\Python36\lib\site-packages\django\views\generic\base.py", line 68, in view
    return self.dispatch(request, *args, **kwargs)
  File "C:\Users\Administrator\AppData\Local\Programs\Python\Python36\lib\site-packages\rest_framework\views.py", line 505, in dispatch
    response = self.handle_exception(exc)
  File "C:\Users\Administrator\AppData\Local\Programs\Python\Python36\lib\site-packages\rest_framework\views.py", line 465, in handle_exception
    self.raise_uncaught_exception(exc)
  File "C:\Users\Administrator\AppData\Local\Programs\Python\Python36\lib\site-packages\rest_framework\views.py", line 476, in raise_uncaught_exception
    raise exc
  File "C:\Users\Administrator\AppData\Local\Programs\Python\Python36\lib\site-packages\rest_framework\views.py", line 502, in dispatch
    response = handler(request, *args, **kwargs)
  File "C:\Users\Administrator\Desktop\school_engineer\backend\apis\views\sch_engineer.py", line 49, in get
    question_dict=sch_engineerModelSerializers(question_set,many=True)
UnboundLocalError: local variable 'question_set' referenced before assignment
2020-03-22 13:08:08,157 [Thread-3: 10956]C:\Users\Administrator\AppData\Local\Programs\Python\Python36\lib\site-packages\django\utils\log.py:log_response:228 ERROR - Internal Server Error: /api/v1.0/service/sch_engineer
Traceback (most recent call last):
  File "C:\Users\Administrator\AppData\Local\Programs\Python\Python36\lib\site-packages\django\core\handlers\exception.py", line 34, in inner
    response = get_response(request)
  File "C:\Users\Administrator\AppData\Local\Programs\Python\Python36\lib\site-packages\django\core\handlers\base.py", line 126, in _get_response
    response = self.process_exception_by_middleware(e, request)
  File "C:\Users\Administrator\AppData\Local\Programs\Python\Python36\lib\site-packages\django\core\handlers\base.py", line 124, in _get_response
    response = wrapped_callback(request, *callback_args, **callback_kwargs)
  File "C:\Users\Administrator\AppData\Local\Programs\Python\Python36\lib\site-packages\django\views\decorators\csrf.py", line 54, in wrapped_view
    return view_func(*args, **kwargs)
  File "C:\Users\Administrator\AppData\Local\Programs\Python\Python36\lib\site-packages\django\views\generic\base.py", line 68, in view
    return self.dispatch(request, *args, **kwargs)
  File "C:\Users\Administrator\AppData\Local\Programs\Python\Python36\lib\site-packages\rest_framework\views.py", line 505, in dispatch
    response = self.handle_exception(exc)
  File "C:\Users\Administrator\AppData\Local\Programs\Python\Python36\lib\site-packages\rest_framework\views.py", line 465, in handle_exception
    self.raise_uncaught_exception(exc)
  File "C:\Users\Administrator\AppData\Local\Programs\Python\Python36\lib\site-packages\rest_framework\views.py", line 476, in raise_uncaught_exception
    raise exc
  File "C:\Users\Administrator\AppData\Local\Programs\Python\Python36\lib\site-packages\rest_framework\views.py", line 502, in dispatch
    response = handler(request, *args, **kwargs)
  File "C:\Users\Administrator\Desktop\school_engineer\backend\apis\views\sch_engineer.py", line 49, in get
    question_dict=sch_engineerModelSerializers(question_set,many=True)
UnboundLocalError: local variable 'question_set' referenced before assignment
2020-03-22 13:08:08,157 [Thread-2: 14740]C:\Users\Administrator\AppData\Local\Programs\Python\Python36\lib\site-packages\django\core\servers\basehttp.py:log_message:136 ERROR - "GET /api/v1.0/service/sch_engineer?type=backstage HTTP/1.1" 500 18213
2020-03-22 13:08:08,159 [Thread-3: 10956]C:\Users\Administrator\AppData\Local\Programs\Python\Python36\lib\site-packages\django\core\servers\basehttp.py:log_message:136 ERROR - "GET /api/v1.0/service/sch_engineer?type=backstage HTTP/1.1" 500 18213
2020-03-22 13:08:09,387 [Thread-3: 10956]C:\Users\Administrator\AppData\Local\Programs\Python\Python36\lib\site-packages\django\core\servers\basehttp.py:log_message:136 INFO - "GET /api/v1.0/service/sch_engineer?type=history HTTP/1.1" 200 222
2020-03-22 13:08:09,427 [Thread-3: 10956]C:\Users\Administrator\AppData\Local\Programs\Python\Python36\lib\site-packages\django\core\servers\basehttp.py:log_message:136 INFO - "GET /api/v1.0/service/sch_engineer?type=history HTTP/1.1" 200 222
2020-03-22 13:08:16,044 [Thread-3: 10956]C:\Users\Administrator\AppData\Local\Programs\Python\Python36\lib\site-packages\django\core\servers\basehttp.py:log_message:136 INFO - "GET /api/v1.0/service/sch_engineer?type=classess HTTP/1.1" 200 222
2020-03-22 13:08:18,456 [Thread-3: 10956]C:\Users\Administrator\AppData\Local\Programs\Python\Python36\lib\site-packages\django\utils\log.py:log_response:228 ERROR - Internal Server Error: /api/v1.0/service/sch_engineer
Traceback (most recent call last):
  File "C:\Users\Administrator\AppData\Local\Programs\Python\Python36\lib\site-packages\django\core\handlers\exception.py", line 34, in inner
    response = get_response(request)
  File "C:\Users\Administrator\AppData\Local\Programs\Python\Python36\lib\site-packages\django\core\handlers\base.py", line 126, in _get_response
    response = self.process_exception_by_middleware(e, request)
  File "C:\Users\Administrator\AppData\Local\Programs\Python\Python36\lib\site-packages\django\core\handlers\base.py", line 124, in _get_response
    response = wrapped_callback(request, *callback_args, **callback_kwargs)
  File "C:\Users\Administrator\AppData\Local\Programs\Python\Python36\lib\site-packages\django\views\decorators\csrf.py", line 54, in wrapped_view
    return view_func(*args, **kwargs)
  File "C:\Users\Administrator\AppData\Local\Programs\Python\Python36\lib\site-packages\django\views\generic\base.py", line 68, in view
    return self.dispatch(request, *args, **kwargs)
  File "C:\Users\Administrator\AppData\Local\Programs\Python\Python36\lib\site-packages\rest_framework\views.py", line 505, in dispatch
    response = self.handle_exception(exc)
  File "C:\Users\Administrator\AppData\Local\Programs\Python\Python36\lib\site-packages\rest_framework\views.py", line 465, in handle_exception
    self.raise_uncaught_exception(exc)
  File "C:\Users\Administrator\AppData\Local\Programs\Python\Python36\lib\site-packages\rest_framework\views.py", line 476, in raise_uncaught_exception
    raise exc
  File "C:\Users\Administrator\AppData\Local\Programs\Python\Python36\lib\site-packages\rest_framework\views.py", line 502, in dispatch
    response = handler(request, *args, **kwargs)
  File "C:\Users\Administrator\Desktop\school_engineer\backend\apis\views\sch_engineer.py", line 49, in get
    question_dict=sch_engineerModelSerializers(question_set,many=True)
UnboundLocalError: local variable 'question_set' referenced before assignment
2020-03-22 13:08:18,457 [Thread-3: 10956]C:\Users\Administrator\AppData\Local\Programs\Python\Python36\lib\site-packages\django\core\servers\basehttp.py:log_message:136 ERROR - "GET /api/v1.0/service/sch_engineer?type=backstage HTTP/1.1" 500 18213
2020-03-22 13:08:20,172 [Thread-3: 10956]C:\Users\Administrator\AppData\Local\Programs\Python\Python36\lib\site-packages\django\core\servers\basehttp.py:log_message:136 INFO - "GET /api/v1.0/auth/status HTTP/1.1" 200 70
2020-03-22 13:08:20,185 [Thread-3: 10956]C:\Users\Administrator\AppData\Local\Programs\Python\Python36\lib\site-packages\django\core\servers\basehttp.py:log_message:136 INFO - "GET /api/v1.0/auth/status HTTP/1.1" 200 70
2020-03-22 13:08:37,353 [Thread-3: 10956]C:\Users\Administrator\AppData\Local\Programs\Python\Python36\lib\site-packages\django\core\servers\basehttp.py:log_message:136 INFO - "POST /api/v1.0/service/sch_engineer HTTP/1.1" 200 40
2020-03-22 13:09:33,424 [Thread-2: 19484]C:\Users\Administrator\AppData\Local\Programs\Python\Python36\lib\site-packages\django\core\servers\basehttp.py:log_message:136 INFO - "GET /api/v1.0/service/sch_engineer?type=backstage HTTP/1.1" 200 386
2020-03-22 13:09:35,226 [Thread-2: 19484]C:\Users\Administrator\AppData\Local\Programs\Python\Python36\lib\site-packages\django\core\servers\basehttp.py:log_message:136 INFO - "GET /api/v1.0/service/sch_engineer?type=history HTTP/1.1" 200 386
2020-03-22 13:09:35,258 [Thread-2: 19484]C:\Users\Administrator\AppData\Local\Programs\Python\Python36\lib\site-packages\django\core\servers\basehttp.py:log_message:136 INFO - "GET /api/v1.0/service/sch_engineer?type=history HTTP/1.1" 200 386
2020-03-22 13:09:40,938 [Thread-2: 19484]C:\Users\Administrator\AppData\Local\Programs\Python\Python36\lib\site-packages\django\core\servers\basehttp.py:log_message:136 INFO - "GET /api/v1.0/service/sch_engineer?type=classess HTTP/1.1" 200 386
2020-03-22 13:10:58,995 [Thread-2: 19484]C:\Users\Administrator\AppData\Local\Programs\Python\Python36\lib\site-packages\django\core\servers\basehttp.py:log_message:136 INFO - "GET /api/v1.0/service/menu HTTP/1.1" 200 236
2020-03-22 13:11:03,334 [Thread-2: 19484]C:\Users\Administrator\AppData\Local\Programs\Python\Python36\lib\site-packages\django\core\servers\basehttp.py:log_message:136 INFO - "GET /api/v1.0/service/sch_engineer?type=backstage HTTP/1.1" 200 386
2020-03-22 13:11:03,416 [Thread-2: 19484]C:\Users\Administrator\AppData\Local\Programs\Python\Python36\lib\site-packages\django\core\servers\basehttp.py:log_message:136 INFO - "GET /api/v1.0/service/sch_engineer?type=backstage HTTP/1.1" 200 386
2020-03-22 13:11:04,675 [Thread-2: 19484]C:\Users\Administrator\AppData\Local\Programs\Python\Python36\lib\site-packages\django\core\servers\basehttp.py:log_message:136 INFO - "GET /api/v1.0/service/sch_engineer?type=history HTTP/1.1" 200 386
2020-03-22 13:11:04,705 [Thread-2: 19484]C:\Users\Administrator\AppData\Local\Programs\Python\Python36\lib\site-packages\django\core\servers\basehttp.py:log_message:136 INFO - "GET /api/v1.0/service/sch_engineer?type=history HTTP/1.1" 200 386
2020-03-22 13:11:06,128 [Thread-2: 19484]C:\Users\Administrator\AppData\Local\Programs\Python\Python36\lib\site-packages\django\core\servers\basehttp.py:log_message:136 INFO - "GET /api/v1.0/service/sch_engineer?type=history HTTP/1.1" 200 386
2020-03-22 13:11:08,996 [Thread-2: 19484]C:\Users\Administrator\AppData\Local\Programs\Python\Python36\lib\site-packages\django\core\servers\basehttp.py:log_message:136 INFO - "GET /api/v1.0/service/sch_engineer?type=classess HTTP/1.1" 200 386
2020-03-22 13:11:10,074 [Thread-2: 19484]C:\Users\Administrator\AppData\Local\Programs\Python\Python36\lib\site-packages\django\core\servers\basehttp.py:log_message:136 INFO - "GET /api/v1.0/service/sch_engineer?type=history HTTP/1.1" 200 386
2020-03-22 13:11:11,100 [Thread-2: 19484]C:\Users\Administrator\AppData\Local\Programs\Python\Python36\lib\site-packages\django\core\servers\basehttp.py:log_message:136 INFO - "GET /api/v1.0/service/sch_engineer?type=classess HTTP/1.1" 200 386
2020-03-22 13:11:11,786 [Thread-2: 19484]C:\Users\Administrator\AppData\Local\Programs\Python\Python36\lib\site-packages\django\core\servers\basehttp.py:log_message:136 INFO - "GET /api/v1.0/service/sch_engineer?type=history HTTP/1.1" 200 386
2020-03-22 13:11:17,537 [Thread-2: 19484]C:\Users\Administrator\AppData\Local\Programs\Python\Python36\lib\site-packages\django\core\servers\basehttp.py:log_message:136 INFO - "GET /api/v1.0/service/sch_engineer?type=history HTTP/1.1" 200 386
2020-03-22 13:11:19,146 [Thread-2: 19484]C:\Users\Administrator\AppData\Local\Programs\Python\Python36\lib\site-packages\django\core\servers\basehttp.py:log_message:136 INFO - "GET /api/v1.0/service/sch_engineer?type=classess HTTP/1.1" 200 386
2020-03-22 13:11:20,748 [Thread-2: 19484]C:\Users\Administrator\AppData\Local\Programs\Python\Python36\lib\site-packages\django\core\servers\basehttp.py:log_message:136 INFO - "GET /api/v1.0/service/sch_engineer?type=backstage HTTP/1.1" 200 386
2020-03-22 13:11:25,269 [Thread-2: 19484]C:\Users\Administrator\AppData\Local\Programs\Python\Python36\lib\site-packages\django\core\servers\basehttp.py:log_message:136 INFO - "PUT /api/v1.0/service/sch_engineer HTTP/1.1" 200 2
2020-03-22 13:11:25,301 [Thread-2: 19484]C:\Users\Administrator\AppData\Local\Programs\Python\Python36\lib\site-packages\django\core\servers\basehttp.py:log_message:136 INFO - "GET /api/v1.0/service/sch_engineer?type=backstage HTTP/1.1" 200 222
2020-03-22 13:11:27,344 [Thread-2: 19484]C:\Users\Administrator\AppData\Local\Programs\Python\Python36\lib\site-packages\django\core\servers\basehttp.py:log_message:136 INFO - "PUT /api/v1.0/service/sch_engineer HTTP/1.1" 200 2
2020-03-22 13:11:27,376 [Thread-2: 19484]C:\Users\Administrator\AppData\Local\Programs\Python\Python36\lib\site-packages\django\core\servers\basehttp.py:log_message:136 INFO - "GET /api/v1.0/service/sch_engineer?type=backstage HTTP/1.1" 200 60
2020-03-22 13:11:28,215 [Thread-2: 19484]C:\Users\Administrator\AppData\Local\Programs\Python\Python36\lib\site-packages\django\core\servers\basehttp.py:log_message:136 INFO - "GET /api/v1.0/service/sch_engineer?type=history HTTP/1.1" 200 60
2020-03-22 13:11:28,246 [Thread-2: 19484]C:\Users\Administrator\AppData\Local\Programs\Python\Python36\lib\site-packages\django\core\servers\basehttp.py:log_message:136 INFO - "GET /api/v1.0/service/sch_engineer?type=history HTTP/1.1" 200 60
2020-03-22 13:11:36,593 [Thread-2: 19484]C:\Users\Administrator\AppData\Local\Programs\Python\Python36\lib\site-packages\django\core\servers\basehttp.py:log_message:136 INFO - "GET /api/v1.0/service/sch_engineer?type=classess HTTP/1.1" 200 60
2020-03-22 13:11:37,412 [Thread-2: 19484]C:\Users\Administrator\AppData\Local\Programs\Python\Python36\lib\site-packages\django\core\servers\basehttp.py:log_message:136 INFO - "GET /api/v1.0/service/sch_engineer?type=history HTTP/1.1" 200 60
2020-03-22 13:11:38,947 [Thread-2: 19484]C:\Users\Administrator\AppData\Local\Programs\Python\Python36\lib\site-packages\django\core\servers\basehttp.py:log_message:136 INFO - "GET /api/v1.0/service/sch_engineer?type=backstage HTTP/1.1" 200 60
2020-03-22 13:11:41,233 [Thread-2: 19484]C:\Users\Administrator\AppData\Local\Programs\Python\Python36\lib\site-packages\django\core\servers\basehttp.py:log_message:136 INFO - "GET /api/v1.0/auth/status HTTP/1.1" 200 70
2020-03-22 13:11:41,251 [Thread-2: 19484]C:\Users\Administrator\AppData\Local\Programs\Python\Python36\lib\site-packages\django\core\servers\basehttp.py:log_message:136 INFO - "GET /api/v1.0/auth/status HTTP/1.1" 200 70
2020-03-22 13:11:42,051 [Thread-2: 19484]C:\Users\Administrator\AppData\Local\Programs\Python\Python36\lib\site-packages\django\core\servers\basehttp.py:log_message:136 INFO - "GET /api/v1.0/service/sch_engineer?type=backstage HTTP/1.1" 200 60
2020-03-22 13:11:43,454 [Thread-2: 19484]C:\Users\Administrator\AppData\Local\Programs\Python\Python36\lib\site-packages\django\core\servers\basehttp.py:log_message:136 INFO - "GET /api/v1.0/service/sch_engineer?type=history HTTP/1.1" 200 60
2020-03-22 13:11:43,457 [Thread-3: 22388]C:\Users\Administrator\AppData\Local\Programs\Python\Python36\lib\site-packages\django\core\servers\basehttp.py:log_message:136 INFO - "GET /api/v1.0/service/sch_engineer?type=history HTTP/1.1" 200 60
2020-03-22 13:21:42,305 [Thread-2: 21332]C:\Users\Administrator\AppData\Local\Programs\Python\Python36\lib\site-packages\django\core\servers\basehttp.py:log_message:136 INFO - "GET /api/v1.0/service/menu HTTP/1.1" 200 236
2020-03-22 13:21:45,189 [Thread-2: 21332]C:\Users\Administrator\AppData\Local\Programs\Python\Python36\lib\site-packages\django\utils\log.py:log_response:228 ERROR - Internal Server Error: /api/v1.0/service/sch_engineer
Traceback (most recent call last):
  File "C:\Users\Administrator\AppData\Local\Programs\Python\Python36\lib\site-packages\django\utils\datastructures.py", line 77, in __getitem__
    list_ = super().__getitem__(key)
KeyError: 'kind'

During handling of the above exception, another exception occurred:

Traceback (most recent call last):
  File "C:\Users\Administrator\AppData\Local\Programs\Python\Python36\lib\site-packages\django\core\handlers\exception.py", line 34, in inner
    response = get_response(request)
  File "C:\Users\Administrator\AppData\Local\Programs\Python\Python36\lib\site-packages\django\core\handlers\base.py", line 126, in _get_response
    response = self.process_exception_by_middleware(e, request)
  File "C:\Users\Administrator\AppData\Local\Programs\Python\Python36\lib\site-packages\django\core\handlers\base.py", line 124, in _get_response
    response = wrapped_callback(request, *callback_args, **callback_kwargs)
  File "C:\Users\Administrator\AppData\Local\Programs\Python\Python36\lib\site-packages\django\views\decorators\csrf.py", line 54, in wrapped_view
    return view_func(*args, **kwargs)
  File "C:\Users\Administrator\AppData\Local\Programs\Python\Python36\lib\site-packages\django\views\generic\base.py", line 68, in view
    return self.dispatch(request, *args, **kwargs)
  File "C:\Users\Administrator\AppData\Local\Programs\Python\Python36\lib\site-packages\rest_framework\views.py", line 505, in dispatch
    response = self.handle_exception(exc)
  File "C:\Users\Administrator\AppData\Local\Programs\Python\Python36\lib\site-packages\rest_framework\views.py", line 465, in handle_exception
    self.raise_uncaught_exception(exc)
  File "C:\Users\Administrator\AppData\Local\Programs\Python\Python36\lib\site-packages\rest_framework\views.py", line 476, in raise_uncaught_exception
    raise exc
  File "C:\Users\Administrator\AppData\Local\Programs\Python\Python36\lib\site-packages\rest_framework\views.py", line 502, in dispatch
    response = handler(request, *args, **kwargs)
  File "C:\Users\Administrator\Desktop\school_engineer\backend\apis\views\sch_engineer.py", line 40, in get
    kind=request.GET['kind']
  File "C:\Users\Administrator\AppData\Local\Programs\Python\Python36\lib\site-packages\django\utils\datastructures.py", line 79, in __getitem__
    raise MultiValueDictKeyError(key)
django.utils.datastructures.MultiValueDictKeyError: 'kind'
2020-03-22 13:21:45,192 [Thread-2: 21332]C:\Users\Administrator\AppData\Local\Programs\Python\Python36\lib\site-packages\django\core\servers\basehttp.py:log_message:136 ERROR - "GET /api/v1.0/service/sch_engineer?type=backstage HTTP/1.1" 500 18491
2020-03-22 13:21:45,253 [Thread-2: 21332]C:\Users\Administrator\AppData\Local\Programs\Python\Python36\lib\site-packages\django\utils\log.py:log_response:228 ERROR - Internal Server Error: /api/v1.0/service/sch_engineer
Traceback (most recent call last):
  File "C:\Users\Administrator\AppData\Local\Programs\Python\Python36\lib\site-packages\django\utils\datastructures.py", line 77, in __getitem__
    list_ = super().__getitem__(key)
KeyError: 'kind'

During handling of the above exception, another exception occurred:

Traceback (most recent call last):
  File "C:\Users\Administrator\AppData\Local\Programs\Python\Python36\lib\site-packages\django\core\handlers\exception.py", line 34, in inner
    response = get_response(request)
  File "C:\Users\Administrator\AppData\Local\Programs\Python\Python36\lib\site-packages\django\core\handlers\base.py", line 126, in _get_response
    response = self.process_exception_by_middleware(e, request)
  File "C:\Users\Administrator\AppData\Local\Programs\Python\Python36\lib\site-packages\django\core\handlers\base.py", line 124, in _get_response
    response = wrapped_callback(request, *callback_args, **callback_kwargs)
  File "C:\Users\Administrator\AppData\Local\Programs\Python\Python36\lib\site-packages\django\views\decorators\csrf.py", line 54, in wrapped_view
    return view_func(*args, **kwargs)
  File "C:\Users\Administrator\AppData\Local\Programs\Python\Python36\lib\site-packages\django\views\generic\base.py", line 68, in view
    return self.dispatch(request, *args, **kwargs)
  File "C:\Users\Administrator\AppData\Local\Programs\Python\Python36\lib\site-packages\rest_framework\views.py", line 505, in dispatch
    response = self.handle_exception(exc)
  File "C:\Users\Administrator\AppData\Local\Programs\Python\Python36\lib\site-packages\rest_framework\views.py", line 465, in handle_exception
    self.raise_uncaught_exception(exc)
  File "C:\Users\Administrator\AppData\Local\Programs\Python\Python36\lib\site-packages\rest_framework\views.py", line 476, in raise_uncaught_exception
    raise exc
  File "C:\Users\Administrator\AppData\Local\Programs\Python\Python36\lib\site-packages\rest_framework\views.py", line 502, in dispatch
    response = handler(request, *args, **kwargs)
  File "C:\Users\Administrator\Desktop\school_engineer\backend\apis\views\sch_engineer.py", line 40, in get
    kind=request.GET['kind']
  File "C:\Users\Administrator\AppData\Local\Programs\Python\Python36\lib\site-packages\django\utils\datastructures.py", line 79, in __getitem__
    raise MultiValueDictKeyError(key)
django.utils.datastructures.MultiValueDictKeyError: 'kind'
2020-03-22 13:21:45,255 [Thread-2: 21332]C:\Users\Administrator\AppData\Local\Programs\Python\Python36\lib\site-packages\django\core\servers\basehttp.py:log_message:136 ERROR - "GET /api/v1.0/service/sch_engineer?type=backstage HTTP/1.1" 500 18451
2020-03-22 13:22:21,857 [Thread-2: 1448]C:\Users\Administrator\AppData\Local\Programs\Python\Python36\lib\site-packages\django\core\servers\basehttp.py:log_message:136 INFO - "GET /api/v1.0/service/menu HTTP/1.1" 200 236
2020-03-22 13:22:24,472 [Thread-2: 1448]C:\Users\Administrator\AppData\Local\Programs\Python\Python36\lib\site-packages\django\utils\log.py:log_response:228 ERROR - Internal Server Error: /api/v1.0/service/sch_engineer
Traceback (most recent call last):
  File "C:\Users\Administrator\AppData\Local\Programs\Python\Python36\lib\site-packages\django\utils\datastructures.py", line 77, in __getitem__
    list_ = super().__getitem__(key)
KeyError: 'kind'

During handling of the above exception, another exception occurred:

Traceback (most recent call last):
  File "C:\Users\Administrator\AppData\Local\Programs\Python\Python36\lib\site-packages\django\core\handlers\exception.py", line 34, in inner
    response = get_response(request)
  File "C:\Users\Administrator\AppData\Local\Programs\Python\Python36\lib\site-packages\django\core\handlers\base.py", line 126, in _get_response
    response = self.process_exception_by_middleware(e, request)
  File "C:\Users\Administrator\AppData\Local\Programs\Python\Python36\lib\site-packages\django\core\handlers\base.py", line 124, in _get_response
    response = wrapped_callback(request, *callback_args, **callback_kwargs)
  File "C:\Users\Administrator\AppData\Local\Programs\Python\Python36\lib\site-packages\django\views\decorators\csrf.py", line 54, in wrapped_view
    return view_func(*args, **kwargs)
  File "C:\Users\Administrator\AppData\Local\Programs\Python\Python36\lib\site-packages\django\views\generic\base.py", line 68, in view
    return self.dispatch(request, *args, **kwargs)
  File "C:\Users\Administrator\AppData\Local\Programs\Python\Python36\lib\site-packages\rest_framework\views.py", line 505, in dispatch
    response = self.handle_exception(exc)
  File "C:\Users\Administrator\AppData\Local\Programs\Python\Python36\lib\site-packages\rest_framework\views.py", line 465, in handle_exception
    self.raise_uncaught_exception(exc)
  File "C:\Users\Administrator\AppData\Local\Programs\Python\Python36\lib\site-packages\rest_framework\views.py", line 476, in raise_uncaught_exception
    raise exc
  File "C:\Users\Administrator\AppData\Local\Programs\Python\Python36\lib\site-packages\rest_framework\views.py", line 502, in dispatch
    response = handler(request, *args, **kwargs)
  File "C:\Users\Administrator\Desktop\school_engineer\backend\apis\views\sch_engineer.py", line 40, in get
    kind=request.GET['kind']
  File "C:\Users\Administrator\AppData\Local\Programs\Python\Python36\lib\site-packages\django\utils\datastructures.py", line 79, in __getitem__
    raise MultiValueDictKeyError(key)
django.utils.datastructures.MultiValueDictKeyError: 'kind'
2020-03-22 13:22:24,477 [Thread-3: 2984]C:\Users\Administrator\AppData\Local\Programs\Python\Python36\lib\site-packages\django\utils\log.py:log_response:228 ERROR - Internal Server Error: /api/v1.0/service/sch_engineer
Traceback (most recent call last):
  File "C:\Users\Administrator\AppData\Local\Programs\Python\Python36\lib\site-packages\django\utils\datastructures.py", line 77, in __getitem__
    list_ = super().__getitem__(key)
KeyError: 'kind'

During handling of the above exception, another exception occurred:

Traceback (most recent call last):
  File "C:\Users\Administrator\AppData\Local\Programs\Python\Python36\lib\site-packages\django\core\handlers\exception.py", line 34, in inner
    response = get_response(request)
  File "C:\Users\Administrator\AppData\Local\Programs\Python\Python36\lib\site-packages\django\core\handlers\base.py", line 126, in _get_response
    response = self.process_exception_by_middleware(e, request)
  File "C:\Users\Administrator\AppData\Local\Programs\Python\Python36\lib\site-packages\django\core\handlers\base.py", line 124, in _get_response
    response = wrapped_callback(request, *callback_args, **callback_kwargs)
  File "C:\Users\Administrator\AppData\Local\Programs\Python\Python36\lib\site-packages\django\views\decorators\csrf.py", line 54, in wrapped_view
    return view_func(*args, **kwargs)
  File "C:\Users\Administrator\AppData\Local\Programs\Python\Python36\lib\site-packages\django\views\generic\base.py", line 68, in view
    return self.dispatch(request, *args, **kwargs)
  File "C:\Users\Administrator\AppData\Local\Programs\Python\Python36\lib\site-packages\rest_framework\views.py", line 505, in dispatch
    response = self.handle_exception(exc)
  File "C:\Users\Administrator\AppData\Local\Programs\Python\Python36\lib\site-packages\rest_framework\views.py", line 465, in handle_exception
    self.raise_uncaught_exception(exc)
  File "C:\Users\Administrator\AppData\Local\Programs\Python\Python36\lib\site-packages\rest_framework\views.py", line 476, in raise_uncaught_exception
    raise exc
  File "C:\Users\Administrator\AppData\Local\Programs\Python\Python36\lib\site-packages\rest_framework\views.py", line 502, in dispatch
    response = handler(request, *args, **kwargs)
  File "C:\Users\Administrator\Desktop\school_engineer\backend\apis\views\sch_engineer.py", line 40, in get
    kind=request.GET['kind']
  File "C:\Users\Administrator\AppData\Local\Programs\Python\Python36\lib\site-packages\django\utils\datastructures.py", line 79, in __getitem__
    raise MultiValueDictKeyError(key)
django.utils.datastructures.MultiValueDictKeyError: 'kind'
2020-03-22 13:22:24,480 [Thread-2: 1448]C:\Users\Administrator\AppData\Local\Programs\Python\Python36\lib\site-packages\django\core\servers\basehttp.py:log_message:136 ERROR - "GET /api/v1.0/service/sch_engineer?type=backstage HTTP/1.1" 500 18451
2020-03-22 13:22:24,483 [Thread-3: 2984]C:\Users\Administrator\AppData\Local\Programs\Python\Python36\lib\site-packages\django\core\servers\basehttp.py:log_message:136 ERROR - "GET /api/v1.0/service/sch_engineer?type=backstage HTTP/1.1" 500 18451
2020-03-22 13:22:47,484 [Thread-2: 18364]C:\Users\Administrator\AppData\Local\Programs\Python\Python36\lib\site-packages\django\utils\log.py:log_response:228 ERROR - Internal Server Error: /api/v1.0/service/sch_engineer
Traceback (most recent call last):
  File "C:\Users\Administrator\AppData\Local\Programs\Python\Python36\lib\site-packages\django\utils\datastructures.py", line 77, in __getitem__
    list_ = super().__getitem__(key)
KeyError: 'kind'

During handling of the above exception, another exception occurred:

Traceback (most recent call last):
  File "C:\Users\Administrator\AppData\Local\Programs\Python\Python36\lib\site-packages\django\core\handlers\exception.py", line 34, in inner
    response = get_response(request)
  File "C:\Users\Administrator\AppData\Local\Programs\Python\Python36\lib\site-packages\django\core\handlers\base.py", line 126, in _get_response
    response = self.process_exception_by_middleware(e, request)
  File "C:\Users\Administrator\AppData\Local\Programs\Python\Python36\lib\site-packages\django\core\handlers\base.py", line 124, in _get_response
    response = wrapped_callback(request, *callback_args, **callback_kwargs)
  File "C:\Users\Administrator\AppData\Local\Programs\Python\Python36\lib\site-packages\django\views\decorators\csrf.py", line 54, in wrapped_view
    return view_func(*args, **kwargs)
  File "C:\Users\Administrator\AppData\Local\Programs\Python\Python36\lib\site-packages\django\views\generic\base.py", line 68, in view
    return self.dispatch(request, *args, **kwargs)
  File "C:\Users\Administrator\AppData\Local\Programs\Python\Python36\lib\site-packages\rest_framework\views.py", line 505, in dispatch
    response = self.handle_exception(exc)
  File "C:\Users\Administrator\AppData\Local\Programs\Python\Python36\lib\site-packages\rest_framework\views.py", line 465, in handle_exception
    self.raise_uncaught_exception(exc)
  File "C:\Users\Administrator\AppData\Local\Programs\Python\Python36\lib\site-packages\rest_framework\views.py", line 476, in raise_uncaught_exception
    raise exc
  File "C:\Users\Administrator\AppData\Local\Programs\Python\Python36\lib\site-packages\rest_framework\views.py", line 502, in dispatch
    response = handler(request, *args, **kwargs)
  File "C:\Users\Administrator\Desktop\school_engineer\backend\apis\views\sch_engineer.py", line 40, in get
    kinds=request.GET['kind']
  File "C:\Users\Administrator\AppData\Local\Programs\Python\Python36\lib\site-packages\django\utils\datastructures.py", line 79, in __getitem__
    raise MultiValueDictKeyError(key)
django.utils.datastructures.MultiValueDictKeyError: 'kind'
2020-03-22 13:22:47,487 [Thread-2: 18364]C:\Users\Administrator\AppData\Local\Programs\Python\Python36\lib\site-packages\django\core\servers\basehttp.py:log_message:136 ERROR - "GET /api/v1.0/service/sch_engineer?type=backstage HTTP/1.1" 500 18452
2020-03-22 13:23:03,425 [Thread-2: 22420]C:\Users\Administrator\AppData\Local\Programs\Python\Python36\lib\site-packages\django\utils\log.py:log_response:228 ERROR - Internal Server Error: /api/v1.0/service/sch_engineer
Traceback (most recent call last):
  File "C:\Users\Administrator\AppData\Local\Programs\Python\Python36\lib\site-packages\django\utils\datastructures.py", line 77, in __getitem__
    list_ = super().__getitem__(key)
KeyError: 'kind'

During handling of the above exception, another exception occurred:

Traceback (most recent call last):
  File "C:\Users\Administrator\AppData\Local\Programs\Python\Python36\lib\site-packages\django\core\handlers\exception.py", line 34, in inner
    response = get_response(request)
  File "C:\Users\Administrator\AppData\Local\Programs\Python\Python36\lib\site-packages\django\core\handlers\base.py", line 126, in _get_response
    response = self.process_exception_by_middleware(e, request)
  File "C:\Users\Administrator\AppData\Local\Programs\Python\Python36\lib\site-packages\django\core\handlers\base.py", line 124, in _get_response
    response = wrapped_callback(request, *callback_args, **callback_kwargs)
  File "C:\Users\Administrator\AppData\Local\Programs\Python\Python36\lib\site-packages\django\views\decorators\csrf.py", line 54, in wrapped_view
    return view_func(*args, **kwargs)
  File "C:\Users\Administrator\AppData\Local\Programs\Python\Python36\lib\site-packages\django\views\generic\base.py", line 68, in view
    return self.dispatch(request, *args, **kwargs)
  File "C:\Users\Administrator\AppData\Local\Programs\Python\Python36\lib\site-packages\rest_framework\views.py", line 505, in dispatch
    response = self.handle_exception(exc)
  File "C:\Users\Administrator\AppData\Local\Programs\Python\Python36\lib\site-packages\rest_framework\views.py", line 465, in handle_exception
    self.raise_uncaught_exception(exc)
  File "C:\Users\Administrator\AppData\Local\Programs\Python\Python36\lib\site-packages\rest_framework\views.py", line 476, in raise_uncaught_exception
    raise exc
  File "C:\Users\Administrator\AppData\Local\Programs\Python\Python36\lib\site-packages\rest_framework\views.py", line 502, in dispatch
    response = handler(request, *args, **kwargs)
  File "C:\Users\Administrator\Desktop\school_engineer\backend\apis\views\sch_engineer.py", line 40, in get
    kinds=request.GET['kind']
  File "C:\Users\Administrator\AppData\Local\Programs\Python\Python36\lib\site-packages\django\utils\datastructures.py", line 79, in __getitem__
    raise MultiValueDictKeyError(key)
django.utils.datastructures.MultiValueDictKeyError: 'kind'
2020-03-22 13:23:03,428 [Thread-2: 22420]C:\Users\Administrator\AppData\Local\Programs\Python\Python36\lib\site-packages\django\core\servers\basehttp.py:log_message:136 ERROR - "GET /api/v1.0/service/sch_engineer?type=backstage HTTP/1.1" 500 18452
2020-03-22 13:23:45,918 [Thread-2: 6160]C:\Users\Administrator\AppData\Local\Programs\Python\Python36\lib\site-packages\django\utils\log.py:log_response:228 ERROR - Internal Server Error: /api/v1.0/service/sch_engineer
Traceback (most recent call last):
  File "C:\Users\Administrator\AppData\Local\Programs\Python\Python36\lib\site-packages\django\utils\datastructures.py", line 77, in __getitem__
    list_ = super().__getitem__(key)
KeyError: 'kinds'

During handling of the above exception, another exception occurred:

Traceback (most recent call last):
  File "C:\Users\Administrator\AppData\Local\Programs\Python\Python36\lib\site-packages\django\core\handlers\exception.py", line 34, in inner
    response = get_response(request)
  File "C:\Users\Administrator\AppData\Local\Programs\Python\Python36\lib\site-packages\django\core\handlers\base.py", line 126, in _get_response
    response = self.process_exception_by_middleware(e, request)
  File "C:\Users\Administrator\AppData\Local\Programs\Python\Python36\lib\site-packages\django\core\handlers\base.py", line 124, in _get_response
    response = wrapped_callback(request, *callback_args, **callback_kwargs)
  File "C:\Users\Administrator\AppData\Local\Programs\Python\Python36\lib\site-packages\django\views\decorators\csrf.py", line 54, in wrapped_view
    return view_func(*args, **kwargs)
  File "C:\Users\Administrator\AppData\Local\Programs\Python\Python36\lib\site-packages\django\views\generic\base.py", line 68, in view
    return self.dispatch(request, *args, **kwargs)
  File "C:\Users\Administrator\AppData\Local\Programs\Python\Python36\lib\site-packages\rest_framework\views.py", line 505, in dispatch
    response = self.handle_exception(exc)
  File "C:\Users\Administrator\AppData\Local\Programs\Python\Python36\lib\site-packages\rest_framework\views.py", line 465, in handle_exception
    self.raise_uncaught_exception(exc)
  File "C:\Users\Administrator\AppData\Local\Programs\Python\Python36\lib\site-packages\rest_framework\views.py", line 476, in raise_uncaught_exception
    raise exc
  File "C:\Users\Administrator\AppData\Local\Programs\Python\Python36\lib\site-packages\rest_framework\views.py", line 502, in dispatch
    response = handler(request, *args, **kwargs)
  File "C:\Users\Administrator\Desktop\school_engineer\backend\apis\views\sch_engineer.py", line 40, in get
    kinds=request.GET['kinds']
  File "C:\Users\Administrator\AppData\Local\Programs\Python\Python36\lib\site-packages\django\utils\datastructures.py", line 79, in __getitem__
    raise MultiValueDictKeyError(key)
django.utils.datastructures.MultiValueDictKeyError: 'kinds'
2020-03-22 13:23:45,921 [Thread-2: 6160]C:\Users\Administrator\AppData\Local\Programs\Python\Python36\lib\site-packages\django\core\servers\basehttp.py:log_message:136 ERROR - "GET /api/v1.0/service/sch_engineer?type=backstage HTTP/1.1" 500 18456
2020-03-22 13:24:58,075 [Thread-2: 11288]C:\Users\Administrator\AppData\Local\Programs\Python\Python36\lib\site-packages\django\core\servers\basehttp.py:log_message:136 INFO - "GET /api/v1.0/service/sch_engineer?kind=done&type=history HTTP/1.1" 200 60
2020-03-22 13:24:58,106 [Thread-2: 11288]C:\Users\Administrator\AppData\Local\Programs\Python\Python36\lib\site-packages\django\core\servers\basehttp.py:log_message:136 INFO - "GET /api/v1.0/service/sch_engineer?kind=done&type=history HTTP/1.1" 200 60
2020-03-22 13:25:00,497 [Thread-2: 11288]C:\Users\Administrator\AppData\Local\Programs\Python\Python36\lib\site-packages\django\utils\log.py:log_response:228 ERROR - Internal Server Error: /api/v1.0/service/sch_engineer
Traceback (most recent call last):
  File "C:\Users\Administrator\AppData\Local\Programs\Python\Python36\lib\site-packages\django\utils\datastructures.py", line 77, in __getitem__
    list_ = super().__getitem__(key)
KeyError: 'kind'

During handling of the above exception, another exception occurred:

Traceback (most recent call last):
  File "C:\Users\Administrator\AppData\Local\Programs\Python\Python36\lib\site-packages\django\core\handlers\exception.py", line 34, in inner
    response = get_response(request)
  File "C:\Users\Administrator\AppData\Local\Programs\Python\Python36\lib\site-packages\django\core\handlers\base.py", line 126, in _get_response
    response = self.process_exception_by_middleware(e, request)
  File "C:\Users\Administrator\AppData\Local\Programs\Python\Python36\lib\site-packages\django\core\handlers\base.py", line 124, in _get_response
    response = wrapped_callback(request, *callback_args, **callback_kwargs)
  File "C:\Users\Administrator\AppData\Local\Programs\Python\Python36\lib\site-packages\django\views\decorators\csrf.py", line 54, in wrapped_view
    return view_func(*args, **kwargs)
  File "C:\Users\Administrator\AppData\Local\Programs\Python\Python36\lib\site-packages\django\views\generic\base.py", line 68, in view
    return self.dispatch(request, *args, **kwargs)
  File "C:\Users\Administrator\AppData\Local\Programs\Python\Python36\lib\site-packages\rest_framework\views.py", line 505, in dispatch
    response = self.handle_exception(exc)
  File "C:\Users\Administrator\AppData\Local\Programs\Python\Python36\lib\site-packages\rest_framework\views.py", line 465, in handle_exception
    self.raise_uncaught_exception(exc)
  File "C:\Users\Administrator\AppData\Local\Programs\Python\Python36\lib\site-packages\rest_framework\views.py", line 476, in raise_uncaught_exception
    raise exc
  File "C:\Users\Administrator\AppData\Local\Programs\Python\Python36\lib\site-packages\rest_framework\views.py", line 502, in dispatch
    response = handler(request, *args, **kwargs)
  File "C:\Users\Administrator\Desktop\school_engineer\backend\apis\views\sch_engineer.py", line 40, in get
    kinds=request.GET['kind']
  File "C:\Users\Administrator\AppData\Local\Programs\Python\Python36\lib\site-packages\django\utils\datastructures.py", line 79, in __getitem__
    raise MultiValueDictKeyError(key)
django.utils.datastructures.MultiValueDictKeyError: 'kind'
2020-03-22 13:25:00,500 [Thread-2: 11288]C:\Users\Administrator\AppData\Local\Programs\Python\Python36\lib\site-packages\django\core\servers\basehttp.py:log_message:136 ERROR - "GET /api/v1.0/service/sch_engineer?type=backstage HTTP/1.1" 500 18452
2020-03-22 13:25:07,372 [Thread-2: 11288]C:\Users\Administrator\AppData\Local\Programs\Python\Python36\lib\site-packages\django\core\servers\basehttp.py:log_message:136 INFO - "POST /api/v1.0/auth/authorize HTTP/1.1" 200 73
2020-03-22 13:25:08,074 [Thread-2: 11288]C:\Users\Administrator\AppData\Local\Programs\Python\Python36\lib\site-packages\django\utils\log.py:log_response:228 ERROR - Internal Server Error: /api/v1.0/service/sch_engineer
Traceback (most recent call last):
  File "C:\Users\Administrator\AppData\Local\Programs\Python\Python36\lib\site-packages\django\utils\datastructures.py", line 77, in __getitem__
    list_ = super().__getitem__(key)
KeyError: 'kind'

During handling of the above exception, another exception occurred:

Traceback (most recent call last):
  File "C:\Users\Administrator\AppData\Local\Programs\Python\Python36\lib\site-packages\django\core\handlers\exception.py", line 34, in inner
    response = get_response(request)
  File "C:\Users\Administrator\AppData\Local\Programs\Python\Python36\lib\site-packages\django\core\handlers\base.py", line 126, in _get_response
    response = self.process_exception_by_middleware(e, request)
  File "C:\Users\Administrator\AppData\Local\Programs\Python\Python36\lib\site-packages\django\core\handlers\base.py", line 124, in _get_response
    response = wrapped_callback(request, *callback_args, **callback_kwargs)
  File "C:\Users\Administrator\AppData\Local\Programs\Python\Python36\lib\site-packages\django\views\decorators\csrf.py", line 54, in wrapped_view
    return view_func(*args, **kwargs)
  File "C:\Users\Administrator\AppData\Local\Programs\Python\Python36\lib\site-packages\django\views\generic\base.py", line 68, in view
    return self.dispatch(request, *args, **kwargs)
  File "C:\Users\Administrator\AppData\Local\Programs\Python\Python36\lib\site-packages\rest_framework\views.py", line 505, in dispatch
    response = self.handle_exception(exc)
  File "C:\Users\Administrator\AppData\Local\Programs\Python\Python36\lib\site-packages\rest_framework\views.py", line 465, in handle_exception
    self.raise_uncaught_exception(exc)
  File "C:\Users\Administrator\AppData\Local\Programs\Python\Python36\lib\site-packages\rest_framework\views.py", line 476, in raise_uncaught_exception
    raise exc
  File "C:\Users\Administrator\AppData\Local\Programs\Python\Python36\lib\site-packages\rest_framework\views.py", line 502, in dispatch
    response = handler(request, *args, **kwargs)
  File "C:\Users\Administrator\Desktop\school_engineer\backend\apis\views\sch_engineer.py", line 40, in get
    kinds=request.GET['kind']
  File "C:\Users\Administrator\AppData\Local\Programs\Python\Python36\lib\site-packages\django\utils\datastructures.py", line 79, in __getitem__
    raise MultiValueDictKeyError(key)
django.utils.datastructures.MultiValueDictKeyError: 'kind'
2020-03-22 13:25:08,075 [Thread-2: 11288]C:\Users\Administrator\AppData\Local\Programs\Python\Python36\lib\site-packages\django\core\servers\basehttp.py:log_message:136 ERROR - "GET /api/v1.0/service/sch_engineer?type=backstage HTTP/1.1" 500 18523
2020-03-22 13:25:09,439 [Thread-2: 11288]C:\Users\Administrator\AppData\Local\Programs\Python\Python36\lib\site-packages\django\core\servers\basehttp.py:log_message:136 INFO - "GET /api/v1.0/service/sch_engineer?kind=done&type=history HTTP/1.1" 200 884
2020-03-22 13:25:09,442 [Thread-3: 1480]C:\Users\Administrator\AppData\Local\Programs\Python\Python36\lib\site-packages\django\core\servers\basehttp.py:log_message:136 INFO - "GET /api/v1.0/service/sch_engineer?kind=done&type=history HTTP/1.1" 200 884
2020-03-22 13:25:11,403 [Thread-3: 1480]C:\Users\Administrator\AppData\Local\Programs\Python\Python36\lib\site-packages\django\core\servers\basehttp.py:log_message:136 INFO - "GET /api/v1.0/service/sch_engineer?kind=done&type=history HTTP/1.1" 200 884
2020-03-22 13:25:12,445 [Thread-3: 1480]C:\Users\Administrator\AppData\Local\Programs\Python\Python36\lib\site-packages\django\core\servers\basehttp.py:log_message:136 INFO - "GET /api/v1.0/service/sch_engineer?kind=done&type=history HTTP/1.1" 200 884
2020-03-22 13:25:13,158 [Thread-3: 1480]C:\Users\Administrator\AppData\Local\Programs\Python\Python36\lib\site-packages\django\core\servers\basehttp.py:log_message:136 INFO - "GET /api/v1.0/service/sch_engineer?kind=done&type=classess HTTP/1.1" 200 884
2020-03-22 13:25:13,955 [Thread-3: 1480]C:\Users\Administrator\AppData\Local\Programs\Python\Python36\lib\site-packages\django\core\servers\basehttp.py:log_message:136 INFO - "GET /api/v1.0/service/sch_engineer?kind=done&type=history HTTP/1.1" 200 884
2020-03-22 13:25:14,686 [Thread-3: 1480]C:\Users\Administrator\AppData\Local\Programs\Python\Python36\lib\site-packages\django\core\servers\basehttp.py:log_message:136 INFO - "GET /api/v1.0/service/sch_engineer?kind=done&type=classess HTTP/1.1" 200 884
2020-03-22 13:25:15,403 [Thread-3: 1480]C:\Users\Administrator\AppData\Local\Programs\Python\Python36\lib\site-packages\django\core\servers\basehttp.py:log_message:136 INFO - "GET /api/v1.0/service/sch_engineer?kind=done&type=history HTTP/1.1" 200 884
2020-03-22 13:25:22,045 [Thread-3: 1480]C:\Users\Administrator\AppData\Local\Programs\Python\Python36\lib\site-packages\django\core\servers\basehttp.py:log_message:136 INFO - "GET /api/v1.0/service/sch_engineer?kind=done&type=history HTTP/1.1" 200 884
2020-03-22 13:25:23,748 [Thread-3: 1480]C:\Users\Administrator\AppData\Local\Programs\Python\Python36\lib\site-packages\django\core\servers\basehttp.py:log_message:136 INFO - "GET /api/v1.0/service/sch_engineer?kind=done&type=classess HTTP/1.1" 200 884
2020-03-22 13:26:24,946 [Thread-2: 5320]C:\Users\Administrator\AppData\Local\Programs\Python\Python36\lib\site-packages\django\utils\log.py:log_response:228 ERROR - Internal Server Error: /api/v1.0/service/sch_engineer
Traceback (most recent call last):
  File "C:\Users\Administrator\AppData\Local\Programs\Python\Python36\lib\site-packages\django\utils\datastructures.py", line 77, in __getitem__
    list_ = super().__getitem__(key)
KeyError: 'kind'

During handling of the above exception, another exception occurred:

Traceback (most recent call last):
  File "C:\Users\Administrator\AppData\Local\Programs\Python\Python36\lib\site-packages\django\core\handlers\exception.py", line 34, in inner
    response = get_response(request)
  File "C:\Users\Administrator\AppData\Local\Programs\Python\Python36\lib\site-packages\django\core\handlers\base.py", line 126, in _get_response
    response = self.process_exception_by_middleware(e, request)
  File "C:\Users\Administrator\AppData\Local\Programs\Python\Python36\lib\site-packages\django\core\handlers\base.py", line 124, in _get_response
    response = wrapped_callback(request, *callback_args, **callback_kwargs)
  File "C:\Users\Administrator\AppData\Local\Programs\Python\Python36\lib\site-packages\django\views\decorators\csrf.py", line 54, in wrapped_view
    return view_func(*args, **kwargs)
  File "C:\Users\Administrator\AppData\Local\Programs\Python\Python36\lib\site-packages\django\views\generic\base.py", line 68, in view
    return self.dispatch(request, *args, **kwargs)
  File "C:\Users\Administrator\AppData\Local\Programs\Python\Python36\lib\site-packages\rest_framework\views.py", line 505, in dispatch
    response = self.handle_exception(exc)
  File "C:\Users\Administrator\AppData\Local\Programs\Python\Python36\lib\site-packages\rest_framework\views.py", line 465, in handle_exception
    self.raise_uncaught_exception(exc)
  File "C:\Users\Administrator\AppData\Local\Programs\Python\Python36\lib\site-packages\rest_framework\views.py", line 476, in raise_uncaught_exception
    raise exc
  File "C:\Users\Administrator\AppData\Local\Programs\Python\Python36\lib\site-packages\rest_framework\views.py", line 502, in dispatch
    response = handler(request, *args, **kwargs)
  File "C:\Users\Administrator\Desktop\school_engineer\backend\apis\views\sch_engineer.py", line 40, in get
    kinds=request.GET['kind']
  File "C:\Users\Administrator\AppData\Local\Programs\Python\Python36\lib\site-packages\django\utils\datastructures.py", line 79, in __getitem__
    raise MultiValueDictKeyError(key)
django.utils.datastructures.MultiValueDictKeyError: 'kind'
2020-03-22 13:26:24,949 [Thread-2: 5320]C:\Users\Administrator\AppData\Local\Programs\Python\Python36\lib\site-packages\django\core\servers\basehttp.py:log_message:136 ERROR - "GET /api/v1.0/service/sch_engineer?type=backstage HTTP/1.1" 500 18523
2020-03-22 13:26:31,634 [Thread-2: 5320]C:\Users\Administrator\AppData\Local\Programs\Python\Python36\lib\site-packages\django\core\servers\basehttp.py:log_message:136 INFO - "GET /api/v1.0/service/menu HTTP/1.1" 200 236
2020-03-22 13:26:37,643 [Thread-2: 18892]C:\Users\Administrator\AppData\Local\Programs\Python\Python36\lib\site-packages\django\core\servers\basehttp.py:log_message:136 INFO - "GET /api/v1.0/service/sch_engineer?kind=undone&type=backstage HTTP/1.1" 200 60
2020-03-22 13:26:37,706 [Thread-2: 18892]C:\Users\Administrator\AppData\Local\Programs\Python\Python36\lib\site-packages\django\core\servers\basehttp.py:log_message:136 INFO - "GET /api/v1.0/service/sch_engineer?kind=undone&type=backstage HTTP/1.1" 200 60
2020-03-22 13:26:40,820 [Thread-2: 18892]C:\Users\Administrator\AppData\Local\Programs\Python\Python36\lib\site-packages\django\core\servers\basehttp.py:log_message:136 INFO - "GET /api/v1.0/service/sch_engineer?kind=undone&type=backstage HTTP/1.1" 200 60
2020-03-22 13:26:43,086 [Thread-2: 18892]C:\Users\Administrator\AppData\Local\Programs\Python\Python36\lib\site-packages\django\core\servers\basehttp.py:log_message:136 INFO - "GET /api/v1.0/auth/status HTTP/1.1" 200 70
2020-03-22 13:26:43,131 [Thread-2: 18892]C:\Users\Administrator\AppData\Local\Programs\Python\Python36\lib\site-packages\django\core\servers\basehttp.py:log_message:136 INFO - "GET /api/v1.0/auth/status HTTP/1.1" 200 70
2020-03-22 13:26:54,505 [Thread-2: 18892]C:\Users\Administrator\AppData\Local\Programs\Python\Python36\lib\site-packages\django\core\servers\basehttp.py:log_message:136 INFO - "POST /api/v1.0/service/sch_engineer HTTP/1.1" 200 40
2020-03-22 13:26:56,233 [Thread-2: 18892]C:\Users\Administrator\AppData\Local\Programs\Python\Python36\lib\site-packages\django\core\servers\basehttp.py:log_message:136 INFO - "GET /api/v1.0/service/sch_engineer?kind=undone&type=backstage HTTP/1.1" 200 222
2020-03-22 13:27:15,937 [Thread-2: 18892]C:\Users\Administrator\AppData\Local\Programs\Python\Python36\lib\site-packages\django\core\servers\basehttp.py:log_message:136 INFO - "GET /api/v1.0/service/sch_engineer?kind=done&type=history HTTP/1.1" 200 884
2020-03-22 13:27:15,982 [Thread-2: 18892]C:\Users\Administrator\AppData\Local\Programs\Python\Python36\lib\site-packages\django\core\servers\basehttp.py:log_message:136 INFO - "GET /api/v1.0/service/sch_engineer?kind=done&type=history HTTP/1.1" 200 884
2020-03-22 13:27:17,068 [Thread-2: 18892]C:\Users\Administrator\AppData\Local\Programs\Python\Python36\lib\site-packages\django\core\servers\basehttp.py:log_message:136 INFO - "GET /api/v1.0/service/sch_engineer?kind=done&type=history HTTP/1.1" 200 884
2020-03-22 13:27:19,104 [Thread-2: 18892]C:\Users\Administrator\AppData\Local\Programs\Python\Python36\lib\site-packages\django\core\servers\basehttp.py:log_message:136 INFO - "GET /api/v1.0/service/sch_engineer?kind=done&type=classess HTTP/1.1" 200 884
2020-03-22 13:27:19,961 [Thread-2: 18892]C:\Users\Administrator\AppData\Local\Programs\Python\Python36\lib\site-packages\django\core\servers\basehttp.py:log_message:136 INFO - "GET /api/v1.0/service/sch_engineer?kind=done&type=history HTTP/1.1" 200 884
2020-03-22 13:27:20,704 [Thread-2: 18892]C:\Users\Administrator\AppData\Local\Programs\Python\Python36\lib\site-packages\django\core\servers\basehttp.py:log_message:136 INFO - "GET /api/v1.0/service/sch_engineer?kind=done&type=classess HTTP/1.1" 200 884
2020-03-22 13:27:21,363 [Thread-2: 18892]C:\Users\Administrator\AppData\Local\Programs\Python\Python36\lib\site-packages\django\core\servers\basehttp.py:log_message:136 INFO - "GET /api/v1.0/service/sch_engineer?kind=done&type=history HTTP/1.1" 200 884
2020-03-22 13:27:24,571 [Thread-2: 18892]C:\Users\Administrator\AppData\Local\Programs\Python\Python36\lib\site-packages\django\core\servers\basehttp.py:log_message:136 INFO - "GET /api/v1.0/service/sch_engineer?kind=undone&type=backstage HTTP/1.1" 200 222
2020-03-22 13:27:25,968 [Thread-2: 18892]C:\Users\Administrator\AppData\Local\Programs\Python\Python36\lib\site-packages\django\core\servers\basehttp.py:log_message:136 INFO - "PUT /api/v1.0/service/sch_engineer HTTP/1.1" 200 2
2020-03-22 13:27:26,011 [Thread-2: 18892]C:\Users\Administrator\AppData\Local\Programs\Python\Python36\lib\site-packages\django\core\servers\basehttp.py:log_message:136 INFO - "GET /api/v1.0/service/sch_engineer?kind=undone&type=backstage HTTP/1.1" 200 221
2020-03-22 13:27:28,200 [Thread-2: 18892]C:\Users\Administrator\AppData\Local\Programs\Python\Python36\lib\site-packages\django\core\servers\basehttp.py:log_message:136 INFO - "GET /api/v1.0/service/sch_engineer?kind=done&type=history HTTP/1.1" 200 884
2020-03-22 13:27:28,229 [Thread-2: 18892]C:\Users\Administrator\AppData\Local\Programs\Python\Python36\lib\site-packages\django\core\servers\basehttp.py:log_message:136 INFO - "GET /api/v1.0/service/sch_engineer?kind=done&type=history HTTP/1.1" 200 884
2020-03-22 13:27:29,278 [Thread-2: 18892]C:\Users\Administrator\AppData\Local\Programs\Python\Python36\lib\site-packages\django\core\servers\basehttp.py:log_message:136 INFO - "GET /api/v1.0/service/sch_engineer?kind=done&type=history HTTP/1.1" 200 884
2020-03-22 13:27:32,924 [Thread-2: 18892]C:\Users\Administrator\AppData\Local\Programs\Python\Python36\lib\site-packages\django\core\servers\basehttp.py:log_message:136 INFO - "GET /api/v1.0/service/sch_engineer?kind=undone&type=backstage HTTP/1.1" 200 221
2020-03-22 13:28:14,088 [Thread-2: 18892]C:\Users\Administrator\AppData\Local\Programs\Python\Python36\lib\site-packages\django\core\servers\basehttp.py:log_message:136 INFO - "GET /api/v1.0/service/menu HTTP/1.1" 200 236
2020-03-22 13:28:17,856 [Thread-2: 18892]C:\Users\Administrator\AppData\Local\Programs\Python\Python36\lib\site-packages\django\utils\log.py:log_response:228 ERROR - Internal Server Error: /api/v1.0/service/sch_engineer
Traceback (most recent call last):
  File "C:\Users\Administrator\AppData\Local\Programs\Python\Python36\lib\site-packages\django\utils\datastructures.py", line 77, in __getitem__
    list_ = super().__getitem__(key)
KeyError: 'type'

During handling of the above exception, another exception occurred:

Traceback (most recent call last):
  File "C:\Users\Administrator\AppData\Local\Programs\Python\Python36\lib\site-packages\django\core\handlers\exception.py", line 34, in inner
    response = get_response(request)
  File "C:\Users\Administrator\AppData\Local\Programs\Python\Python36\lib\site-packages\django\core\handlers\base.py", line 126, in _get_response
    response = self.process_exception_by_middleware(e, request)
  File "C:\Users\Administrator\AppData\Local\Programs\Python\Python36\lib\site-packages\django\core\handlers\base.py", line 124, in _get_response
    response = wrapped_callback(request, *callback_args, **callback_kwargs)
  File "C:\Users\Administrator\AppData\Local\Programs\Python\Python36\lib\site-packages\django\views\decorators\csrf.py", line 54, in wrapped_view
    return view_func(*args, **kwargs)
  File "C:\Users\Administrator\AppData\Local\Programs\Python\Python36\lib\site-packages\django\views\generic\base.py", line 68, in view
    return self.dispatch(request, *args, **kwargs)
  File "C:\Users\Administrator\AppData\Local\Programs\Python\Python36\lib\site-packages\rest_framework\views.py", line 505, in dispatch
    response = self.handle_exception(exc)
  File "C:\Users\Administrator\AppData\Local\Programs\Python\Python36\lib\site-packages\rest_framework\views.py", line 465, in handle_exception
    self.raise_uncaught_exception(exc)
  File "C:\Users\Administrator\AppData\Local\Programs\Python\Python36\lib\site-packages\rest_framework\views.py", line 476, in raise_uncaught_exception
    raise exc
  File "C:\Users\Administrator\AppData\Local\Programs\Python\Python36\lib\site-packages\rest_framework\views.py", line 502, in dispatch
    response = handler(request, *args, **kwargs)
  File "C:\Users\Administrator\Desktop\school_engineer\backend\apis\views\sch_engineer.py", line 42, in get
    typess=request.GET['type']
  File "C:\Users\Administrator\AppData\Local\Programs\Python\Python36\lib\site-packages\django\utils\datastructures.py", line 79, in __getitem__
    raise MultiValueDictKeyError(key)
django.utils.datastructures.MultiValueDictKeyError: 'type'
2020-03-22 13:28:17,859 [Thread-2: 18892]C:\Users\Administrator\AppData\Local\Programs\Python\Python36\lib\site-packages\django\core\servers\basehttp.py:log_message:136 ERROR - "GET /api/v1.0/service/sch_engineer?kind=undone HTTP/1.1" 500 18515
2020-03-22 13:28:17,918 [Thread-2: 18892]C:\Users\Administrator\AppData\Local\Programs\Python\Python36\lib\site-packages\django\utils\log.py:log_response:228 ERROR - Internal Server Error: /api/v1.0/service/sch_engineer
Traceback (most recent call last):
  File "C:\Users\Administrator\AppData\Local\Programs\Python\Python36\lib\site-packages\django\utils\datastructures.py", line 77, in __getitem__
    list_ = super().__getitem__(key)
KeyError: 'type'

During handling of the above exception, another exception occurred:

Traceback (most recent call last):
  File "C:\Users\Administrator\AppData\Local\Programs\Python\Python36\lib\site-packages\django\core\handlers\exception.py", line 34, in inner
    response = get_response(request)
  File "C:\Users\Administrator\AppData\Local\Programs\Python\Python36\lib\site-packages\django\core\handlers\base.py", line 126, in _get_response
    response = self.process_exception_by_middleware(e, request)
  File "C:\Users\Administrator\AppData\Local\Programs\Python\Python36\lib\site-packages\django\core\handlers\base.py", line 124, in _get_response
    response = wrapped_callback(request, *callback_args, **callback_kwargs)
  File "C:\Users\Administrator\AppData\Local\Programs\Python\Python36\lib\site-packages\django\views\decorators\csrf.py", line 54, in wrapped_view
    return view_func(*args, **kwargs)
  File "C:\Users\Administrator\AppData\Local\Programs\Python\Python36\lib\site-packages\django\views\generic\base.py", line 68, in view
    return self.dispatch(request, *args, **kwargs)
  File "C:\Users\Administrator\AppData\Local\Programs\Python\Python36\lib\site-packages\rest_framework\views.py", line 505, in dispatch
    response = self.handle_exception(exc)
  File "C:\Users\Administrator\AppData\Local\Programs\Python\Python36\lib\site-packages\rest_framework\views.py", line 465, in handle_exception
    self.raise_uncaught_exception(exc)
  File "C:\Users\Administrator\AppData\Local\Programs\Python\Python36\lib\site-packages\rest_framework\views.py", line 476, in raise_uncaught_exception
    raise exc
  File "C:\Users\Administrator\AppData\Local\Programs\Python\Python36\lib\site-packages\rest_framework\views.py", line 502, in dispatch
    response = handler(request, *args, **kwargs)
  File "C:\Users\Administrator\Desktop\school_engineer\backend\apis\views\sch_engineer.py", line 42, in get
    typess=request.GET['type']
  File "C:\Users\Administrator\AppData\Local\Programs\Python\Python36\lib\site-packages\django\utils\datastructures.py", line 79, in __getitem__
    raise MultiValueDictKeyError(key)
django.utils.datastructures.MultiValueDictKeyError: 'type'
2020-03-22 13:28:17,920 [Thread-2: 18892]C:\Users\Administrator\AppData\Local\Programs\Python\Python36\lib\site-packages\django\core\servers\basehttp.py:log_message:136 ERROR - "GET /api/v1.0/service/sch_engineer?kind=undone HTTP/1.1" 500 18515
2020-03-22 13:28:26,511 [Thread-2: 18892]C:\Users\Administrator\AppData\Local\Programs\Python\Python36\lib\site-packages\django\core\servers\basehttp.py:log_message:136 INFO - "GET /api/v1.0/service/menu HTTP/1.1" 200 236
2020-03-22 13:28:29,747 [Thread-2: 18892]C:\Users\Administrator\AppData\Local\Programs\Python\Python36\lib\site-packages\django\core\servers\basehttp.py:log_message:136 INFO - "GET /api/v1.0/service/sch_engineer?kind=undone&type=backstage HTTP/1.1" 200 221
2020-03-22 13:28:29,833 [Thread-2: 18892]C:\Users\Administrator\AppData\Local\Programs\Python\Python36\lib\site-packages\django\core\servers\basehttp.py:log_message:136 INFO - "GET /api/v1.0/service/sch_engineer?kind=undone&type=backstage HTTP/1.1" 200 221
2020-03-22 13:28:31,556 [Thread-2: 18892]C:\Users\Administrator\AppData\Local\Programs\Python\Python36\lib\site-packages\django\core\servers\basehttp.py:log_message:136 INFO - "GET /api/v1.0/service/sch_engineer?kind=done&type=history HTTP/1.1" 200 884
2020-03-22 13:28:31,587 [Thread-2: 18892]C:\Users\Administrator\AppData\Local\Programs\Python\Python36\lib\site-packages\django\core\servers\basehttp.py:log_message:136 INFO - "GET /api/v1.0/service/sch_engineer?kind=done&type=history HTTP/1.1" 200 884
2020-03-22 13:29:41,464 [Thread-2: 18892]C:\Users\Administrator\AppData\Local\Programs\Python\Python36\lib\site-packages\django\core\servers\basehttp.py:log_message:136 INFO - "GET /api/v1.0/service/menu HTTP/1.1" 200 236
2020-03-22 13:29:44,359 [Thread-2: 18892]C:\Users\Administrator\AppData\Local\Programs\Python\Python36\lib\site-packages\django\core\servers\basehttp.py:log_message:136 INFO - "GET /api/v1.0/service/sch_engineer?kind=undone&type=backstage HTTP/1.1" 200 221
2020-03-22 13:29:44,568 [Thread-2: 18892]C:\Users\Administrator\AppData\Local\Programs\Python\Python36\lib\site-packages\django\core\servers\basehttp.py:log_message:136 INFO - "GET /api/v1.0/service/sch_engineer?kind=undone&type=backstage HTTP/1.1" 200 221
2020-03-22 13:29:45,341 [Thread-2: 18892]C:\Users\Administrator\AppData\Local\Programs\Python\Python36\lib\site-packages\django\core\servers\basehttp.py:log_message:136 INFO - "GET /api/v1.0/service/sch_engineer?kind=done&type=history HTTP/1.1" 200 884
2020-03-22 13:29:45,382 [Thread-2: 18892]C:\Users\Administrator\AppData\Local\Programs\Python\Python36\lib\site-packages\django\core\servers\basehttp.py:log_message:136 INFO - "GET /api/v1.0/service/sch_engineer?kind=done&type=history HTTP/1.1" 200 884
2020-03-22 13:29:47,462 [Thread-2: 18892]C:\Users\Administrator\AppData\Local\Programs\Python\Python36\lib\site-packages\django\core\servers\basehttp.py:log_message:136 INFO - "GET /api/v1.0/service/sch_engineer?kind=done&type=history HTTP/1.1" 200 884
2020-03-22 13:29:48,752 [Thread-2: 18892]C:\Users\Administrator\AppData\Local\Programs\Python\Python36\lib\site-packages\django\core\servers\basehttp.py:log_message:136 INFO - "GET /api/v1.0/service/sch_engineer?kind=done&type=classess HTTP/1.1" 200 884
2020-03-22 13:29:49,868 [Thread-2: 18892]C:\Users\Administrator\AppData\Local\Programs\Python\Python36\lib\site-packages\django\core\servers\basehttp.py:log_message:136 INFO - "GET /api/v1.0/service/sch_engineer?kind=done&type=history HTTP/1.1" 200 884
2020-03-22 13:29:50,495 [Thread-2: 18892]C:\Users\Administrator\AppData\Local\Programs\Python\Python36\lib\site-packages\django\core\servers\basehttp.py:log_message:136 INFO - "GET /api/v1.0/service/sch_engineer?kind=done&type=classess HTTP/1.1" 200 884
2020-03-22 13:30:00,727 [Thread-2: 18892]C:\Users\Administrator\AppData\Local\Programs\Python\Python36\lib\site-packages\django\core\servers\basehttp.py:log_message:136 INFO - "GET /api/v1.0/service/sch_engineer?kind=done&type=history HTTP/1.1" 200 884
2020-03-22 13:30:08,484 [Thread-2: 18892]C:\Users\Administrator\AppData\Local\Programs\Python\Python36\lib\site-packages\django\core\servers\basehttp.py:log_message:136 INFO - "GET /api/v1.0/service/sch_engineer?kind=done&type=classess HTTP/1.1" 200 884
2020-03-22 13:30:27,357 [Thread-2: 18892]C:\Users\Administrator\AppData\Local\Programs\Python\Python36\lib\site-packages\django\core\servers\basehttp.py:log_message:136 INFO - "GET /api/v1.0/service/sch_engineer?kind=done&type=history HTTP/1.1" 200 884
2020-03-22 13:30:28,097 [Thread-2: 18892]C:\Users\Administrator\AppData\Local\Programs\Python\Python36\lib\site-packages\django\core\servers\basehttp.py:log_message:136 INFO - "GET /api/v1.0/service/sch_engineer?kind=done&type=classess HTTP/1.1" 200 884
2020-03-22 13:32:36,945 [Thread-2: 7356]C:\Users\Administrator\AppData\Local\Programs\Python\Python36\lib\site-packages\django\core\servers\basehttp.py:log_message:136 INFO - "GET /api/v1.0/service/menu HTTP/1.1" 200 236
2020-03-22 13:32:40,202 [Thread-2: 7356]C:\Users\Administrator\AppData\Local\Programs\Python\Python36\lib\site-packages\django\core\servers\basehttp.py:log_message:136 INFO - "GET /api/v1.0/service/sch_engineer?kind=undone&type=backstage HTTP/1.1" 200 221
2020-03-22 13:32:40,260 [Thread-2: 7356]C:\Users\Administrator\AppData\Local\Programs\Python\Python36\lib\site-packages\django\core\servers\basehttp.py:log_message:136 INFO - "GET /api/v1.0/service/sch_engineer?kind=undone&type=backstage HTTP/1.1" 200 221
2020-03-22 13:32:41,693 [Thread-2: 7356]C:\Users\Administrator\AppData\Local\Programs\Python\Python36\lib\site-packages\django\core\servers\basehttp.py:log_message:136 INFO - "GET /api/v1.0/service/sch_engineer?kind=done&type=history HTTP/1.1" 200 884
2020-03-22 13:32:41,725 [Thread-2: 7356]C:\Users\Administrator\AppData\Local\Programs\Python\Python36\lib\site-packages\django\core\servers\basehttp.py:log_message:136 INFO - "GET /api/v1.0/service/sch_engineer?kind=done&type=history HTTP/1.1" 200 884
2020-03-22 13:33:06,158 [Thread-2: 7356]C:\Users\Administrator\AppData\Local\Programs\Python\Python36\lib\site-packages\django\core\servers\basehttp.py:log_message:136 INFO - "GET /api/v1.0/service/menu HTTP/1.1" 200 236
2020-03-22 13:33:09,279 [Thread-2: 7356]C:\Users\Administrator\AppData\Local\Programs\Python\Python36\lib\site-packages\django\core\servers\basehttp.py:log_message:136 INFO - "GET /api/v1.0/service/sch_engineer?kind=undone&type=backstage HTTP/1.1" 200 221
2020-03-22 13:33:09,369 [Thread-2: 7356]C:\Users\Administrator\AppData\Local\Programs\Python\Python36\lib\site-packages\django\core\servers\basehttp.py:log_message:136 INFO - "GET /api/v1.0/service/sch_engineer?kind=undone&type=backstage HTTP/1.1" 200 221
2020-03-22 13:33:10,515 [Thread-2: 7356]C:\Users\Administrator\AppData\Local\Programs\Python\Python36\lib\site-packages\django\core\servers\basehttp.py:log_message:136 INFO - "GET /api/v1.0/service/sch_engineer?kind=done&type=history HTTP/1.1" 200 884
2020-03-22 13:33:10,550 [Thread-2: 7356]C:\Users\Administrator\AppData\Local\Programs\Python\Python36\lib\site-packages\django\core\servers\basehttp.py:log_message:136 INFO - "GET /api/v1.0/service/sch_engineer?kind=done&type=history HTTP/1.1" 200 884
2020-03-22 13:33:16,805 [Thread-2: 7356]C:\Users\Administrator\AppData\Local\Programs\Python\Python36\lib\site-packages\django\core\servers\basehttp.py:log_message:136 INFO - "GET /api/v1.0/service/sch_engineer?kind=done&type=classess HTTP/1.1" 200 884
2020-03-22 13:33:17,929 [Thread-2: 7356]C:\Users\Administrator\AppData\Local\Programs\Python\Python36\lib\site-packages\django\core\servers\basehttp.py:log_message:136 INFO - "GET /api/v1.0/service/sch_engineer?kind=done&type=history HTTP/1.1" 200 884
2020-03-22 13:36:24,351 [Thread-2: 21172]C:\Users\Administrator\AppData\Local\Programs\Python\Python36\lib\site-packages\django\core\servers\basehttp.py:log_message:136 INFO - "GET /api/v1.0/service/menu HTTP/1.1" 200 236
2020-03-22 13:36:28,064 [Thread-2: 21172]C:\Users\Administrator\AppData\Local\Programs\Python\Python36\lib\site-packages\django\core\servers\basehttp.py:log_message:136 INFO - "GET /api/v1.0/service/sch_engineer?kind=undone&type=backstage HTTP/1.1" 200 221
2020-03-22 13:36:28,128 [Thread-2: 21172]C:\Users\Administrator\AppData\Local\Programs\Python\Python36\lib\site-packages\django\core\servers\basehttp.py:log_message:136 INFO - "GET /api/v1.0/service/sch_engineer?kind=undone&type=backstage HTTP/1.1" 200 221
2020-03-22 13:36:29,074 [Thread-2: 21172]C:\Users\Administrator\AppData\Local\Programs\Python\Python36\lib\site-packages\django\core\servers\basehttp.py:log_message:136 INFO - "GET /api/v1.0/service/sch_engineer?kind=done&type=history HTTP/1.1" 200 884
2020-03-22 13:36:29,136 [Thread-2: 21172]C:\Users\Administrator\AppData\Local\Programs\Python\Python36\lib\site-packages\django\core\servers\basehttp.py:log_message:136 INFO - "GET /api/v1.0/service/sch_engineer?kind=done&type=history HTTP/1.1" 200 884
2020-03-22 13:36:30,723 [Thread-2: 21172]C:\Users\Administrator\AppData\Local\Programs\Python\Python36\lib\site-packages\django\core\servers\basehttp.py:log_message:136 INFO - "GET /api/v1.0/service/sch_engineer?kind=done&type=classess HTTP/1.1" 200 884
2020-03-22 13:36:31,921 [Thread-2: 21172]C:\Users\Administrator\AppData\Local\Programs\Python\Python36\lib\site-packages\django\core\servers\basehttp.py:log_message:136 INFO - "GET /api/v1.0/service/sch_engineer?kind=done&type=classess_over HTTP/1.1" 200 884
2020-03-22 13:36:35,371 [Thread-2: 21172]C:\Users\Administrator\AppData\Local\Programs\Python\Python36\lib\site-packages\django\core\servers\basehttp.py:log_message:136 INFO - "GET /api/v1.0/service/sch_engineer?kind=done&type=classess_over HTTP/1.1" 200 884
2020-03-22 13:36:40,486 [Thread-2: 21172]C:\Users\Administrator\AppData\Local\Programs\Python\Python36\lib\site-packages\django\core\servers\basehttp.py:log_message:136 INFO - "GET /api/v1.0/service/sch_engineer?kind=done&type=classess HTTP/1.1" 200 884
2020-03-22 13:36:44,761 [Thread-2: 21172]C:\Users\Administrator\AppData\Local\Programs\Python\Python36\lib\site-packages\django\core\servers\basehttp.py:log_message:136 INFO - "GET /api/v1.0/service/sch_engineer?kind=done&type=classess_over HTTP/1.1" 200 884
2020-03-22 13:37:30,195 [Thread-2: 1556]C:\Users\Administrator\AppData\Local\Programs\Python\Python36\lib\site-packages\django\core\servers\basehttp.py:log_message:136 INFO - "GET /api/v1.0/service/sch_engineer?kind=done&type=classess HTTP/1.1" 200 884
2020-03-22 13:37:32,021 [Thread-2: 1556]C:\Users\Administrator\AppData\Local\Programs\Python\Python36\lib\site-packages\django\core\servers\basehttp.py:log_message:136 INFO - "GET /api/v1.0/service/sch_engineer?kind=done&type=classess_over HTTP/1.1" 200 884
2020-03-22 13:37:33,416 [Thread-2: 1556]C:\Users\Administrator\AppData\Local\Programs\Python\Python36\lib\site-packages\django\core\servers\basehttp.py:log_message:136 INFO - "GET /api/v1.0/service/sch_engineer?kind=done&type=classess HTTP/1.1" 200 884
2020-03-22 13:37:35,989 [Thread-2: 1556]C:\Users\Administrator\AppData\Local\Programs\Python\Python36\lib\site-packages\django\core\servers\basehttp.py:log_message:136 INFO - "GET /api/v1.0/service/sch_engineer?kind=done&type=classess_over HTTP/1.1" 200 884
2020-03-22 13:37:40,816 [Thread-2: 1556]C:\Users\Administrator\AppData\Local\Programs\Python\Python36\lib\site-packages\django\core\servers\basehttp.py:log_message:136 INFO - "GET /api/v1.0/service/sch_engineer?kind=undone&type=backstage HTTP/1.1" 200 221
2020-03-22 13:37:43,280 [Thread-2: 1556]C:\Users\Administrator\AppData\Local\Programs\Python\Python36\lib\site-packages\django\core\servers\basehttp.py:log_message:136 INFO - "GET /api/v1.0/auth/status HTTP/1.1" 200 70
2020-03-22 13:37:43,327 [Thread-2: 1556]C:\Users\Administrator\AppData\Local\Programs\Python\Python36\lib\site-packages\django\core\servers\basehttp.py:log_message:136 INFO - "GET /api/v1.0/auth/status HTTP/1.1" 200 70
2020-03-22 13:37:53,538 [Thread-2: 1556]C:\Users\Administrator\AppData\Local\Programs\Python\Python36\lib\site-packages\django\core\servers\basehttp.py:log_message:136 INFO - "POST /api/v1.0/service/sch_engineer HTTP/1.1" 200 40
2020-03-22 13:37:54,753 [Thread-2: 1556]C:\Users\Administrator\AppData\Local\Programs\Python\Python36\lib\site-packages\django\core\servers\basehttp.py:log_message:136 INFO - "GET /api/v1.0/service/sch_engineer?kind=undone&type=backstage HTTP/1.1" 200 386
2020-03-22 13:37:56,607 [Thread-2: 1556]C:\Users\Administrator\AppData\Local\Programs\Python\Python36\lib\site-packages\django\core\servers\basehttp.py:log_message:136 INFO - "GET /api/v1.0/service/sch_engineer?kind=done&type=history HTTP/1.1" 200 884
2020-03-22 13:37:56,650 [Thread-2: 1556]C:\Users\Administrator\AppData\Local\Programs\Python\Python36\lib\site-packages\django\core\servers\basehttp.py:log_message:136 INFO - "GET /api/v1.0/service/sch_engineer?kind=done&type=history HTTP/1.1" 200 884
2020-03-22 13:37:58,031 [Thread-2: 1556]C:\Users\Administrator\AppData\Local\Programs\Python\Python36\lib\site-packages\django\core\servers\basehttp.py:log_message:136 INFO - "GET /api/v1.0/service/sch_engineer?kind=undone&type=backstage HTTP/1.1" 200 386
2020-03-22 13:38:01,377 [Thread-2: 1556]C:\Users\Administrator\AppData\Local\Programs\Python\Python36\lib\site-packages\django\core\servers\basehttp.py:log_message:136 INFO - "PUT /api/v1.0/service/sch_engineer HTTP/1.1" 200 2
2020-03-22 13:38:01,423 [Thread-2: 1556]C:\Users\Administrator\AppData\Local\Programs\Python\Python36\lib\site-packages\django\core\servers\basehttp.py:log_message:136 INFO - "GET /api/v1.0/service/sch_engineer?kind=undone&type=backstage HTTP/1.1" 200 221
2020-03-22 13:38:03,274 [Thread-2: 1556]C:\Users\Administrator\AppData\Local\Programs\Python\Python36\lib\site-packages\django\core\servers\basehttp.py:log_message:136 INFO - "GET /api/v1.0/service/sch_engineer?kind=done&type=history HTTP/1.1" 200 1048
2020-03-22 13:38:03,329 [Thread-2: 1556]C:\Users\Administrator\AppData\Local\Programs\Python\Python36\lib\site-packages\django\core\servers\basehttp.py:log_message:136 INFO - "GET /api/v1.0/service/sch_engineer?kind=done&type=history HTTP/1.1" 200 1048
2020-03-22 13:38:05,011 [Thread-2: 1556]C:\Users\Administrator\AppData\Local\Programs\Python\Python36\lib\site-packages\django\core\servers\basehttp.py:log_message:136 INFO - "GET /api/v1.0/service/sch_engineer?kind=done&type=classess_over HTTP/1.1" 200 1048
2020-03-22 13:38:08,381 [Thread-2: 1556]C:\Users\Administrator\AppData\Local\Programs\Python\Python36\lib\site-packages\django\core\servers\basehttp.py:log_message:136 INFO - "GET /api/v1.0/service/sch_engineer?kind=done&type=classess HTTP/1.1" 200 1048
2020-03-22 13:38:10,249 [Thread-2: 1556]C:\Users\Administrator\AppData\Local\Programs\Python\Python36\lib\site-packages\django\core\servers\basehttp.py:log_message:136 INFO - "GET /api/v1.0/service/sch_engineer?kind=done&type=history HTTP/1.1" 200 1048
2020-03-22 13:38:26,919 [Thread-2: 1556]C:\Users\Administrator\AppData\Local\Programs\Python\Python36\lib\site-packages\django\core\servers\basehttp.py:log_message:136 INFO - "GET /api/v1.0/service/sch_engineer?kind=done&type=classess_over HTTP/1.1" 200 1048
2020-03-22 13:38:30,788 [Thread-2: 1556]C:\Users\Administrator\AppData\Local\Programs\Python\Python36\lib\site-packages\django\core\servers\basehttp.py:log_message:136 INFO - "GET /api/v1.0/service/sch_engineer?kind=done&type=classess HTTP/1.1" 200 1048
2020-03-22 13:38:41,044 [Thread-2: 1556]C:\Users\Administrator\AppData\Local\Programs\Python\Python36\lib\site-packages\django\core\servers\basehttp.py:log_message:136 INFO - "GET /api/v1.0/service/sch_engineer?kind=undone&type=backstage HTTP/1.1" 200 221
2020-03-22 13:39:38,916 [Thread-2: 2764]C:\Users\Administrator\AppData\Local\Programs\Python\Python36\lib\site-packages\django\core\servers\basehttp.py:log_message:136 INFO - "GET /api/v1.0/service/sch_engineer?kind=undone&type=backstage HTTP/1.1" 200 221
2020-03-22 13:39:40,980 [Thread-2: 2764]C:\Users\Administrator\AppData\Local\Programs\Python\Python36\lib\site-packages\django\core\servers\basehttp.py:log_message:136 INFO - "GET /api/v1.0/auth/status HTTP/1.1" 200 70
2020-03-22 13:39:45,773 [Thread-2: 2764]C:\Users\Administrator\AppData\Local\Programs\Python\Python36\lib\site-packages\django\core\servers\basehttp.py:log_message:136 INFO - "POST /api/v1.0/service/sch_engineer HTTP/1.1" 200 48
2020-03-22 13:39:54,976 [Thread-2: 2764]C:\Users\Administrator\AppData\Local\Programs\Python\Python36\lib\site-packages\django\core\servers\basehttp.py:log_message:136 INFO - "POST /api/v1.0/service/sch_engineer HTTP/1.1" 200 40
2020-03-22 13:39:57,767 [Thread-2: 2764]C:\Users\Administrator\AppData\Local\Programs\Python\Python36\lib\site-packages\django\core\servers\basehttp.py:log_message:136 INFO - "GET /api/v1.0/service/sch_engineer?kind=undone&type=backstage HTTP/1.1" 200 383
2020-03-22 13:39:58,949 [Thread-2: 2764]C:\Users\Administrator\AppData\Local\Programs\Python\Python36\lib\site-packages\django\core\servers\basehttp.py:log_message:136 INFO - "GET /api/v1.0/service/sch_engineer?kind=done&type=history HTTP/1.1" 200 1048
2020-03-22 13:39:58,977 [Thread-2: 2764]C:\Users\Administrator\AppData\Local\Programs\Python\Python36\lib\site-packages\django\core\servers\basehttp.py:log_message:136 INFO - "GET /api/v1.0/service/sch_engineer?kind=done&type=history HTTP/1.1" 200 1048
2020-03-22 13:40:11,134 [Thread-2: 2764]C:\Users\Administrator\AppData\Local\Programs\Python\Python36\lib\site-packages\django\core\servers\basehttp.py:log_message:136 INFO - "GET /api/v1.0/service/sch_engineer?kind=done&type=classess_over HTTP/1.1" 200 1048
2020-03-22 13:40:14,331 [Thread-2: 2764]C:\Users\Administrator\AppData\Local\Programs\Python\Python36\lib\site-packages\django\core\servers\basehttp.py:log_message:136 INFO - "GET /api/v1.0/service/sch_engineer?kind=undone&type=backstage HTTP/1.1" 200 383
2020-03-22 13:40:17,491 [Thread-2: 2764]C:\Users\Administrator\AppData\Local\Programs\Python\Python36\lib\site-packages\django\core\servers\basehttp.py:log_message:136 INFO - "PUT /api/v1.0/service/sch_engineer HTTP/1.1" 200 2
2020-03-22 13:40:17,531 [Thread-2: 2764]C:\Users\Administrator\AppData\Local\Programs\Python\Python36\lib\site-packages\django\core\servers\basehttp.py:log_message:136 INFO - "GET /api/v1.0/service/sch_engineer?kind=undone&type=backstage HTTP/1.1" 200 221
2020-03-22 13:40:19,078 [Thread-2: 2764]C:\Users\Administrator\AppData\Local\Programs\Python\Python36\lib\site-packages\django\core\servers\basehttp.py:log_message:136 INFO - "GET /api/v1.0/service/sch_engineer?kind=done&type=history HTTP/1.1" 200 1209
2020-03-22 13:40:19,125 [Thread-2: 2764]C:\Users\Administrator\AppData\Local\Programs\Python\Python36\lib\site-packages\django\core\servers\basehttp.py:log_message:136 INFO - "GET /api/v1.0/service/sch_engineer?kind=done&type=history HTTP/1.1" 200 1209
2020-03-22 13:40:20,056 [Thread-2: 2764]C:\Users\Administrator\AppData\Local\Programs\Python\Python36\lib\site-packages\django\core\servers\basehttp.py:log_message:136 INFO - "GET /api/v1.0/service/sch_engineer?kind=done&type=classess_over HTTP/1.1" 200 1209
2020-03-22 13:40:22,487 [Thread-2: 2764]C:\Users\Administrator\AppData\Local\Programs\Python\Python36\lib\site-packages\django\core\servers\basehttp.py:log_message:136 INFO - "GET /api/v1.0/service/sch_engineer?kind=done&type=classess HTTP/1.1" 200 1209
2020-03-22 13:40:23,258 [Thread-2: 2764]C:\Users\Administrator\AppData\Local\Programs\Python\Python36\lib\site-packages\django\core\servers\basehttp.py:log_message:136 INFO - "GET /api/v1.0/service/sch_engineer?kind=done&type=history HTTP/1.1" 200 1209
2020-03-22 13:40:23,811 [Thread-2: 2764]C:\Users\Administrator\AppData\Local\Programs\Python\Python36\lib\site-packages\django\core\servers\basehttp.py:log_message:136 INFO - "GET /api/v1.0/service/sch_engineer?kind=done&type=classess_over HTTP/1.1" 200 1209
2020-03-22 13:40:28,566 [Thread-2: 2764]C:\Users\Administrator\AppData\Local\Programs\Python\Python36\lib\site-packages\django\core\servers\basehttp.py:log_message:136 INFO - "GET /api/v1.0/service/sch_engineer?kind=undone&type=backstage HTTP/1.1" 200 221
2020-03-22 13:54:34,371 [Thread-2: 22120]C:\Users\Administrator\AppData\Local\Programs\Python\Python36\lib\site-packages\django\core\servers\basehttp.py:log_message:136 INFO - "GET /api/v1.0/service/sch_engineer?kind=undone&type=backstage HTTP/1.1" 200 221
2020-03-22 13:54:36,009 [Thread-2: 22120]C:\Users\Administrator\AppData\Local\Programs\Python\Python36\lib\site-packages\django\core\servers\basehttp.py:log_message:136 INFO - "GET /api/v1.0/service/sch_engineer?kind=undone&type=backstage HTTP/1.1" 200 221
2020-03-22 13:54:40,097 [Thread-2: 22120]C:\Users\Administrator\AppData\Local\Programs\Python\Python36\lib\site-packages\django\core\servers\basehttp.py:log_message:136 INFO - "GET /api/v1.0/service/sch_engineer?kind=done&type=history HTTP/1.1" 200 1209
2020-03-22 13:54:40,157 [Thread-2: 22120]C:\Users\Administrator\AppData\Local\Programs\Python\Python36\lib\site-packages\django\core\servers\basehttp.py:log_message:136 INFO - "GET /api/v1.0/service/sch_engineer?kind=done&type=history HTTP/1.1" 200 1209
2020-03-22 14:02:46,260 [Thread-2: 5344]C:\Users\Administrator\AppData\Local\Programs\Python\Python36\lib\site-packages\django\utils\log.py:log_response:228 ERROR - Internal Server Error: /api/v1.0/service/sch_engineer
Traceback (most recent call last):
  File "C:\Users\Administrator\AppData\Local\Programs\Python\Python36\lib\site-packages\django\db\backends\utils.py", line 85, in _execute
    return self.cursor.execute(sql, params)
  File "C:\Users\Administrator\AppData\Local\Programs\Python\Python36\lib\site-packages\django\db\backends\mysql\base.py", line 71, in execute
    return self.cursor.execute(query, args)
  File "C:\Users\Administrator\AppData\Local\Programs\Python\Python36\lib\site-packages\pymysql\cursors.py", line 170, in execute
    result = self._query(query)
  File "C:\Users\Administrator\AppData\Local\Programs\Python\Python36\lib\site-packages\pymysql\cursors.py", line 328, in _query
    conn.query(q)
  File "C:\Users\Administrator\AppData\Local\Programs\Python\Python36\lib\site-packages\pymysql\connections.py", line 517, in query
    self._affected_rows = self._read_query_result(unbuffered=unbuffered)
  File "C:\Users\Administrator\AppData\Local\Programs\Python\Python36\lib\site-packages\pymysql\connections.py", line 732, in _read_query_result
    result.read()
  File "C:\Users\Administrator\AppData\Local\Programs\Python\Python36\lib\site-packages\pymysql\connections.py", line 1075, in read
    first_packet = self.connection._read_packet()
  File "C:\Users\Administrator\AppData\Local\Programs\Python\Python36\lib\site-packages\pymysql\connections.py", line 684, in _read_packet
    packet.check_error()
  File "C:\Users\Administrator\AppData\Local\Programs\Python\Python36\lib\site-packages\pymysql\protocol.py", line 220, in check_error
    err.raise_mysql_exception(self._data)
  File "C:\Users\Administrator\AppData\Local\Programs\Python\Python36\lib\site-packages\pymysql\err.py", line 109, in raise_mysql_exception
    raise errorclass(errno, errval)
pymysql.err.InternalError: (1054, "Unknown column 'apis_device_question.truly_date' in 'field list'")

The above exception was the direct cause of the following exception:

Traceback (most recent call last):
  File "C:\Users\Administrator\AppData\Local\Programs\Python\Python36\lib\site-packages\django\core\handlers\exception.py", line 34, in inner
    response = get_response(request)
  File "C:\Users\Administrator\AppData\Local\Programs\Python\Python36\lib\site-packages\django\core\handlers\base.py", line 126, in _get_response
    response = self.process_exception_by_middleware(e, request)
  File "C:\Users\Administrator\AppData\Local\Programs\Python\Python36\lib\site-packages\django\core\handlers\base.py", line 124, in _get_response
    response = wrapped_callback(request, *callback_args, **callback_kwargs)
  File "C:\Users\Administrator\AppData\Local\Programs\Python\Python36\lib\site-packages\django\views\decorators\csrf.py", line 54, in wrapped_view
    return view_func(*args, **kwargs)
  File "C:\Users\Administrator\AppData\Local\Programs\Python\Python36\lib\site-packages\django\views\generic\base.py", line 68, in view
    return self.dispatch(request, *args, **kwargs)
  File "C:\Users\Administrator\AppData\Local\Programs\Python\Python36\lib\site-packages\rest_framework\views.py", line 505, in dispatch
    response = self.handle_exception(exc)
  File "C:\Users\Administrator\AppData\Local\Programs\Python\Python36\lib\site-packages\rest_framework\views.py", line 465, in handle_exception
    self.raise_uncaught_exception(exc)
  File "C:\Users\Administrator\AppData\Local\Programs\Python\Python36\lib\site-packages\rest_framework\views.py", line 476, in raise_uncaught_exception
    raise exc
  File "C:\Users\Administrator\AppData\Local\Programs\Python\Python36\lib\site-packages\rest_framework\views.py", line 502, in dispatch
    response = handler(request, *args, **kwargs)
  File "C:\Users\Administrator\Desktop\school_engineer\backend\apis\views\sch_engineer.py", line 61, in get
    response = self.wrap_json_response(data=question_dict.data, code=ReturnCode.IS_ADMIN)
  File "C:\Users\Administrator\AppData\Local\Programs\Python\Python36\lib\site-packages\rest_framework\serializers.py", line 760, in data
    ret = super().data
  File "C:\Users\Administrator\AppData\Local\Programs\Python\Python36\lib\site-packages\rest_framework\serializers.py", line 260, in data
    self._data = self.to_representation(self.instance)
  File "C:\Users\Administrator\AppData\Local\Programs\Python\Python36\lib\site-packages\rest_framework\serializers.py", line 678, in to_representation
    self.child.to_representation(item) for item in iterable
  File "C:\Users\Administrator\AppData\Local\Programs\Python\Python36\lib\site-packages\django\db\models\query.py", line 268, in __iter__
    self._fetch_all()
  File "C:\Users\Administrator\AppData\Local\Programs\Python\Python36\lib\site-packages\django\db\models\query.py", line 1186, in _fetch_all
    self._result_cache = list(self._iterable_class(self))
  File "C:\Users\Administrator\AppData\Local\Programs\Python\Python36\lib\site-packages\django\db\models\query.py", line 54, in __iter__
    results = compiler.execute_sql(chunked_fetch=self.chunked_fetch, chunk_size=self.chunk_size)
  File "C:\Users\Administrator\AppData\Local\Programs\Python\Python36\lib\site-packages\django\db\models\sql\compiler.py", line 1065, in execute_sql
    cursor.execute(sql, params)
  File "C:\Users\Administrator\AppData\Local\Programs\Python\Python36\lib\site-packages\django\db\backends\utils.py", line 100, in execute
    return super().execute(sql, params)
  File "C:\Users\Administrator\AppData\Local\Programs\Python\Python36\lib\site-packages\django\db\backends\utils.py", line 68, in execute
    return self._execute_with_wrappers(sql, params, many=False, executor=self._execute)
  File "C:\Users\Administrator\AppData\Local\Programs\Python\Python36\lib\site-packages\django\db\backends\utils.py", line 77, in _execute_with_wrappers
    return executor(sql, params, many, context)
  File "C:\Users\Administrator\AppData\Local\Programs\Python\Python36\lib\site-packages\django\db\backends\utils.py", line 85, in _execute
    return self.cursor.execute(sql, params)
  File "C:\Users\Administrator\AppData\Local\Programs\Python\Python36\lib\site-packages\django\db\utils.py", line 89, in __exit__
    raise dj_exc_value.with_traceback(traceback) from exc_value
  File "C:\Users\Administrator\AppData\Local\Programs\Python\Python36\lib\site-packages\django\db\backends\utils.py", line 85, in _execute
    return self.cursor.execute(sql, params)
  File "C:\Users\Administrator\AppData\Local\Programs\Python\Python36\lib\site-packages\django\db\backends\mysql\base.py", line 71, in execute
    return self.cursor.execute(query, args)
  File "C:\Users\Administrator\AppData\Local\Programs\Python\Python36\lib\site-packages\pymysql\cursors.py", line 170, in execute
    result = self._query(query)
  File "C:\Users\Administrator\AppData\Local\Programs\Python\Python36\lib\site-packages\pymysql\cursors.py", line 328, in _query
    conn.query(q)
  File "C:\Users\Administrator\AppData\Local\Programs\Python\Python36\lib\site-packages\pymysql\connections.py", line 517, in query
    self._affected_rows = self._read_query_result(unbuffered=unbuffered)
  File "C:\Users\Administrator\AppData\Local\Programs\Python\Python36\lib\site-packages\pymysql\connections.py", line 732, in _read_query_result
    result.read()
  File "C:\Users\Administrator\AppData\Local\Programs\Python\Python36\lib\site-packages\pymysql\connections.py", line 1075, in read
    first_packet = self.connection._read_packet()
  File "C:\Users\Administrator\AppData\Local\Programs\Python\Python36\lib\site-packages\pymysql\connections.py", line 684, in _read_packet
    packet.check_error()
  File "C:\Users\Administrator\AppData\Local\Programs\Python\Python36\lib\site-packages\pymysql\protocol.py", line 220, in check_error
    err.raise_mysql_exception(self._data)
  File "C:\Users\Administrator\AppData\Local\Programs\Python\Python36\lib\site-packages\pymysql\err.py", line 109, in raise_mysql_exception
    raise errorclass(errno, errval)
django.db.utils.InternalError: (1054, "Unknown column 'apis_device_question.truly_date' in 'field list'")
2020-03-22 14:02:46,270 [Thread-2: 5344]C:\Users\Administrator\AppData\Local\Programs\Python\Python36\lib\site-packages\django\core\servers\basehttp.py:log_message:136 ERROR - "GET /api/v1.0/service/sch_engineer?kind=undone&type=backstage HTTP/1.1" 500 24305
2020-03-22 14:02:47,960 [Thread-2: 5344]C:\Users\Administrator\AppData\Local\Programs\Python\Python36\lib\site-packages\django\core\servers\basehttp.py:log_message:136 INFO - "GET /api/v1.0/auth/status HTTP/1.1" 200 70
2020-03-22 14:02:53,981 [Thread-2: 5344]C:\Users\Administrator\AppData\Local\Programs\Python\Python36\lib\site-packages\django\utils\log.py:log_response:228 ERROR - Internal Server Error: /api/v1.0/service/sch_engineer
Traceback (most recent call last):
  File "C:\Users\Administrator\AppData\Local\Programs\Python\Python36\lib\site-packages\django\db\backends\utils.py", line 85, in _execute
    return self.cursor.execute(sql, params)
  File "C:\Users\Administrator\AppData\Local\Programs\Python\Python36\lib\site-packages\django\db\backends\mysql\base.py", line 71, in execute
    return self.cursor.execute(query, args)
  File "C:\Users\Administrator\AppData\Local\Programs\Python\Python36\lib\site-packages\pymysql\cursors.py", line 170, in execute
    result = self._query(query)
  File "C:\Users\Administrator\AppData\Local\Programs\Python\Python36\lib\site-packages\pymysql\cursors.py", line 328, in _query
    conn.query(q)
  File "C:\Users\Administrator\AppData\Local\Programs\Python\Python36\lib\site-packages\pymysql\connections.py", line 517, in query
    self._affected_rows = self._read_query_result(unbuffered=unbuffered)
  File "C:\Users\Administrator\AppData\Local\Programs\Python\Python36\lib\site-packages\pymysql\connections.py", line 732, in _read_query_result
    result.read()
  File "C:\Users\Administrator\AppData\Local\Programs\Python\Python36\lib\site-packages\pymysql\connections.py", line 1075, in read
    first_packet = self.connection._read_packet()
  File "C:\Users\Administrator\AppData\Local\Programs\Python\Python36\lib\site-packages\pymysql\connections.py", line 684, in _read_packet
    packet.check_error()
  File "C:\Users\Administrator\AppData\Local\Programs\Python\Python36\lib\site-packages\pymysql\protocol.py", line 220, in check_error
    err.raise_mysql_exception(self._data)
  File "C:\Users\Administrator\AppData\Local\Programs\Python\Python36\lib\site-packages\pymysql\err.py", line 109, in raise_mysql_exception
    raise errorclass(errno, errval)
pymysql.err.InternalError: (1054, "Unknown column 'apis_device_question.truly_date' in 'where clause'")

The above exception was the direct cause of the following exception:

Traceback (most recent call last):
  File "C:\Users\Administrator\AppData\Local\Programs\Python\Python36\lib\site-packages\django\core\handlers\exception.py", line 34, in inner
    response = get_response(request)
  File "C:\Users\Administrator\AppData\Local\Programs\Python\Python36\lib\site-packages\django\core\handlers\base.py", line 126, in _get_response
    response = self.process_exception_by_middleware(e, request)
  File "C:\Users\Administrator\AppData\Local\Programs\Python\Python36\lib\site-packages\django\core\handlers\base.py", line 124, in _get_response
    response = wrapped_callback(request, *callback_args, **callback_kwargs)
  File "C:\Users\Administrator\AppData\Local\Programs\Python\Python36\lib\site-packages\django\views\decorators\csrf.py", line 54, in wrapped_view
    return view_func(*args, **kwargs)
  File "C:\Users\Administrator\AppData\Local\Programs\Python\Python36\lib\site-packages\django\views\generic\base.py", line 68, in view
    return self.dispatch(request, *args, **kwargs)
  File "C:\Users\Administrator\AppData\Local\Programs\Python\Python36\lib\site-packages\rest_framework\views.py", line 505, in dispatch
    response = self.handle_exception(exc)
  File "C:\Users\Administrator\AppData\Local\Programs\Python\Python36\lib\site-packages\rest_framework\views.py", line 465, in handle_exception
    self.raise_uncaught_exception(exc)
  File "C:\Users\Administrator\AppData\Local\Programs\Python\Python36\lib\site-packages\rest_framework\views.py", line 476, in raise_uncaught_exception
    raise exc
  File "C:\Users\Administrator\AppData\Local\Programs\Python\Python36\lib\site-packages\rest_framework\views.py", line 502, in dispatch
    response = handler(request, *args, **kwargs)
  File "C:\Users\Administrator\Desktop\school_engineer\backend\apis\views\sch_engineer.py", line 78, in post
    one_day_count=device_question.objects.filter(user_openid=open_id,truly_date=truly_date).count()
  File "C:\Users\Administrator\AppData\Local\Programs\Python\Python36\lib\site-packages\django\db\models\query.py", line 383, in count
    return self.query.get_count(using=self.db)
  File "C:\Users\Administrator\AppData\Local\Programs\Python\Python36\lib\site-packages\django\db\models\sql\query.py", line 498, in get_count
    number = obj.get_aggregation(using, ['__count'])['__count']
  File "C:\Users\Administrator\AppData\Local\Programs\Python\Python36\lib\site-packages\django\db\models\sql\query.py", line 483, in get_aggregation
    result = compiler.execute_sql(SINGLE)
  File "C:\Users\Administrator\AppData\Local\Programs\Python\Python36\lib\site-packages\django\db\models\sql\compiler.py", line 1065, in execute_sql
    cursor.execute(sql, params)
  File "C:\Users\Administrator\AppData\Local\Programs\Python\Python36\lib\site-packages\django\db\backends\utils.py", line 100, in execute
    return super().execute(sql, params)
  File "C:\Users\Administrator\AppData\Local\Programs\Python\Python36\lib\site-packages\django\db\backends\utils.py", line 68, in execute
    return self._execute_with_wrappers(sql, params, many=False, executor=self._execute)
  File "C:\Users\Administrator\AppData\Local\Programs\Python\Python36\lib\site-packages\django\db\backends\utils.py", line 77, in _execute_with_wrappers
    return executor(sql, params, many, context)
  File "C:\Users\Administrator\AppData\Local\Programs\Python\Python36\lib\site-packages\django\db\backends\utils.py", line 85, in _execute
    return self.cursor.execute(sql, params)
  File "C:\Users\Administrator\AppData\Local\Programs\Python\Python36\lib\site-packages\django\db\utils.py", line 89, in __exit__
    raise dj_exc_value.with_traceback(traceback) from exc_value
  File "C:\Users\Administrator\AppData\Local\Programs\Python\Python36\lib\site-packages\django\db\backends\utils.py", line 85, in _execute
    return self.cursor.execute(sql, params)
  File "C:\Users\Administrator\AppData\Local\Programs\Python\Python36\lib\site-packages\django\db\backends\mysql\base.py", line 71, in execute
    return self.cursor.execute(query, args)
  File "C:\Users\Administrator\AppData\Local\Programs\Python\Python36\lib\site-packages\pymysql\cursors.py", line 170, in execute
    result = self._query(query)
  File "C:\Users\Administrator\AppData\Local\Programs\Python\Python36\lib\site-packages\pymysql\cursors.py", line 328, in _query
    conn.query(q)
  File "C:\Users\Administrator\AppData\Local\Programs\Python\Python36\lib\site-packages\pymysql\connections.py", line 517, in query
    self._affected_rows = self._read_query_result(unbuffered=unbuffered)
  File "C:\Users\Administrator\AppData\Local\Programs\Python\Python36\lib\site-packages\pymysql\connections.py", line 732, in _read_query_result
    result.read()
  File "C:\Users\Administrator\AppData\Local\Programs\Python\Python36\lib\site-packages\pymysql\connections.py", line 1075, in read
    first_packet = self.connection._read_packet()
  File "C:\Users\Administrator\AppData\Local\Programs\Python\Python36\lib\site-packages\pymysql\connections.py", line 684, in _read_packet
    packet.check_error()
  File "C:\Users\Administrator\AppData\Local\Programs\Python\Python36\lib\site-packages\pymysql\protocol.py", line 220, in check_error
    err.raise_mysql_exception(self._data)
  File "C:\Users\Administrator\AppData\Local\Programs\Python\Python36\lib\site-packages\pymysql\err.py", line 109, in raise_mysql_exception
    raise errorclass(errno, errval)
django.db.utils.InternalError: (1054, "Unknown column 'apis_device_question.truly_date' in 'where clause'")
2020-03-22 14:02:53,991 [Thread-2: 5344]C:\Users\Administrator\AppData\Local\Programs\Python\Python36\lib\site-packages\django\core\servers\basehttp.py:log_message:136 ERROR - "POST /api/v1.0/service/sch_engineer HTTP/1.1" 500 23694
2020-03-22 14:03:36,814 [Thread-2: 5344]C:\Users\Administrator\AppData\Local\Programs\Python\Python36\lib\site-packages\django\utils\log.py:log_response:228 ERROR - Internal Server Error: /api/v1.0/service/sch_engineer
Traceback (most recent call last):
  File "C:\Users\Administrator\AppData\Local\Programs\Python\Python36\lib\site-packages\django\db\backends\utils.py", line 85, in _execute
    return self.cursor.execute(sql, params)
  File "C:\Users\Administrator\AppData\Local\Programs\Python\Python36\lib\site-packages\django\db\backends\mysql\base.py", line 71, in execute
    return self.cursor.execute(query, args)
  File "C:\Users\Administrator\AppData\Local\Programs\Python\Python36\lib\site-packages\pymysql\cursors.py", line 170, in execute
    result = self._query(query)
  File "C:\Users\Administrator\AppData\Local\Programs\Python\Python36\lib\site-packages\pymysql\cursors.py", line 328, in _query
    conn.query(q)
  File "C:\Users\Administrator\AppData\Local\Programs\Python\Python36\lib\site-packages\pymysql\connections.py", line 517, in query
    self._affected_rows = self._read_query_result(unbuffered=unbuffered)
  File "C:\Users\Administrator\AppData\Local\Programs\Python\Python36\lib\site-packages\pymysql\connections.py", line 732, in _read_query_result
    result.read()
  File "C:\Users\Administrator\AppData\Local\Programs\Python\Python36\lib\site-packages\pymysql\connections.py", line 1075, in read
    first_packet = self.connection._read_packet()
  File "C:\Users\Administrator\AppData\Local\Programs\Python\Python36\lib\site-packages\pymysql\connections.py", line 684, in _read_packet
    packet.check_error()
  File "C:\Users\Administrator\AppData\Local\Programs\Python\Python36\lib\site-packages\pymysql\protocol.py", line 220, in check_error
    err.raise_mysql_exception(self._data)
  File "C:\Users\Administrator\AppData\Local\Programs\Python\Python36\lib\site-packages\pymysql\err.py", line 109, in raise_mysql_exception
    raise errorclass(errno, errval)
pymysql.err.InternalError: (1054, "Unknown column 'apis_device_question.truly_date' in 'where clause'")

The above exception was the direct cause of the following exception:

Traceback (most recent call last):
  File "C:\Users\Administrator\AppData\Local\Programs\Python\Python36\lib\site-packages\django\core\handlers\exception.py", line 34, in inner
    response = get_response(request)
  File "C:\Users\Administrator\AppData\Local\Programs\Python\Python36\lib\site-packages\django\core\handlers\base.py", line 126, in _get_response
    response = self.process_exception_by_middleware(e, request)
  File "C:\Users\Administrator\AppData\Local\Programs\Python\Python36\lib\site-packages\django\core\handlers\base.py", line 124, in _get_response
    response = wrapped_callback(request, *callback_args, **callback_kwargs)
  File "C:\Users\Administrator\AppData\Local\Programs\Python\Python36\lib\site-packages\django\views\decorators\csrf.py", line 54, in wrapped_view
    return view_func(*args, **kwargs)
  File "C:\Users\Administrator\AppData\Local\Programs\Python\Python36\lib\site-packages\django\views\generic\base.py", line 68, in view
    return self.dispatch(request, *args, **kwargs)
  File "C:\Users\Administrator\AppData\Local\Programs\Python\Python36\lib\site-packages\rest_framework\views.py", line 505, in dispatch
    response = self.handle_exception(exc)
  File "C:\Users\Administrator\AppData\Local\Programs\Python\Python36\lib\site-packages\rest_framework\views.py", line 465, in handle_exception
    self.raise_uncaught_exception(exc)
  File "C:\Users\Administrator\AppData\Local\Programs\Python\Python36\lib\site-packages\rest_framework\views.py", line 476, in raise_uncaught_exception
    raise exc
  File "C:\Users\Administrator\AppData\Local\Programs\Python\Python36\lib\site-packages\rest_framework\views.py", line 502, in dispatch
    response = handler(request, *args, **kwargs)
  File "C:\Users\Administrator\Desktop\school_engineer\backend\apis\views\sch_engineer.py", line 78, in post
    one_day_count=device_question.objects.filter(user_openid=open_id,truly_date=truly_date).count()
  File "C:\Users\Administrator\AppData\Local\Programs\Python\Python36\lib\site-packages\django\db\models\query.py", line 383, in count
    return self.query.get_count(using=self.db)
  File "C:\Users\Administrator\AppData\Local\Programs\Python\Python36\lib\site-packages\django\db\models\sql\query.py", line 498, in get_count
    number = obj.get_aggregation(using, ['__count'])['__count']
  File "C:\Users\Administrator\AppData\Local\Programs\Python\Python36\lib\site-packages\django\db\models\sql\query.py", line 483, in get_aggregation
    result = compiler.execute_sql(SINGLE)
  File "C:\Users\Administrator\AppData\Local\Programs\Python\Python36\lib\site-packages\django\db\models\sql\compiler.py", line 1065, in execute_sql
    cursor.execute(sql, params)
  File "C:\Users\Administrator\AppData\Local\Programs\Python\Python36\lib\site-packages\django\db\backends\utils.py", line 100, in execute
    return super().execute(sql, params)
  File "C:\Users\Administrator\AppData\Local\Programs\Python\Python36\lib\site-packages\django\db\backends\utils.py", line 68, in execute
    return self._execute_with_wrappers(sql, params, many=False, executor=self._execute)
  File "C:\Users\Administrator\AppData\Local\Programs\Python\Python36\lib\site-packages\django\db\backends\utils.py", line 77, in _execute_with_wrappers
    return executor(sql, params, many, context)
  File "C:\Users\Administrator\AppData\Local\Programs\Python\Python36\lib\site-packages\django\db\backends\utils.py", line 85, in _execute
    return self.cursor.execute(sql, params)
  File "C:\Users\Administrator\AppData\Local\Programs\Python\Python36\lib\site-packages\django\db\utils.py", line 89, in __exit__
    raise dj_exc_value.with_traceback(traceback) from exc_value
  File "C:\Users\Administrator\AppData\Local\Programs\Python\Python36\lib\site-packages\django\db\backends\utils.py", line 85, in _execute
    return self.cursor.execute(sql, params)
  File "C:\Users\Administrator\AppData\Local\Programs\Python\Python36\lib\site-packages\django\db\backends\mysql\base.py", line 71, in execute
    return self.cursor.execute(query, args)
  File "C:\Users\Administrator\AppData\Local\Programs\Python\Python36\lib\site-packages\pymysql\cursors.py", line 170, in execute
    result = self._query(query)
  File "C:\Users\Administrator\AppData\Local\Programs\Python\Python36\lib\site-packages\pymysql\cursors.py", line 328, in _query
    conn.query(q)
  File "C:\Users\Administrator\AppData\Local\Programs\Python\Python36\lib\site-packages\pymysql\connections.py", line 517, in query
    self._affected_rows = self._read_query_result(unbuffered=unbuffered)
  File "C:\Users\Administrator\AppData\Local\Programs\Python\Python36\lib\site-packages\pymysql\connections.py", line 732, in _read_query_result
    result.read()
  File "C:\Users\Administrator\AppData\Local\Programs\Python\Python36\lib\site-packages\pymysql\connections.py", line 1075, in read
    first_packet = self.connection._read_packet()
  File "C:\Users\Administrator\AppData\Local\Programs\Python\Python36\lib\site-packages\pymysql\connections.py", line 684, in _read_packet
    packet.check_error()
  File "C:\Users\Administrator\AppData\Local\Programs\Python\Python36\lib\site-packages\pymysql\protocol.py", line 220, in check_error
    err.raise_mysql_exception(self._data)
  File "C:\Users\Administrator\AppData\Local\Programs\Python\Python36\lib\site-packages\pymysql\err.py", line 109, in raise_mysql_exception
    raise errorclass(errno, errval)
django.db.utils.InternalError: (1054, "Unknown column 'apis_device_question.truly_date' in 'where clause'")
2020-03-22 14:03:36,819 [Thread-2: 5344]C:\Users\Administrator\AppData\Local\Programs\Python\Python36\lib\site-packages\django\core\servers\basehttp.py:log_message:136 ERROR - "POST /api/v1.0/service/sch_engineer HTTP/1.1" 500 23694
2020-03-22 14:03:53,483 [Thread-2: 9052]C:\Users\Administrator\AppData\Local\Programs\Python\Python36\lib\site-packages\django\utils\log.py:log_response:228 ERROR - Internal Server Error: /api/v1.0/service/sch_engineer
Traceback (most recent call last):
  File "C:\Users\Administrator\AppData\Local\Programs\Python\Python36\lib\site-packages\django\db\backends\utils.py", line 85, in _execute
    return self.cursor.execute(sql, params)
  File "C:\Users\Administrator\AppData\Local\Programs\Python\Python36\lib\site-packages\django\db\backends\mysql\base.py", line 71, in execute
    return self.cursor.execute(query, args)
  File "C:\Users\Administrator\AppData\Local\Programs\Python\Python36\lib\site-packages\pymysql\cursors.py", line 170, in execute
    result = self._query(query)
  File "C:\Users\Administrator\AppData\Local\Programs\Python\Python36\lib\site-packages\pymysql\cursors.py", line 328, in _query
    conn.query(q)
  File "C:\Users\Administrator\AppData\Local\Programs\Python\Python36\lib\site-packages\pymysql\connections.py", line 517, in query
    self._affected_rows = self._read_query_result(unbuffered=unbuffered)
  File "C:\Users\Administrator\AppData\Local\Programs\Python\Python36\lib\site-packages\pymysql\connections.py", line 732, in _read_query_result
    result.read()
  File "C:\Users\Administrator\AppData\Local\Programs\Python\Python36\lib\site-packages\pymysql\connections.py", line 1075, in read
    first_packet = self.connection._read_packet()
  File "C:\Users\Administrator\AppData\Local\Programs\Python\Python36\lib\site-packages\pymysql\connections.py", line 684, in _read_packet
    packet.check_error()
  File "C:\Users\Administrator\AppData\Local\Programs\Python\Python36\lib\site-packages\pymysql\protocol.py", line 220, in check_error
    err.raise_mysql_exception(self._data)
  File "C:\Users\Administrator\AppData\Local\Programs\Python\Python36\lib\site-packages\pymysql\err.py", line 109, in raise_mysql_exception
    raise errorclass(errno, errval)
pymysql.err.InternalError: (1054, "Unknown column 'apis_device_question.truly_date' in 'where clause'")

The above exception was the direct cause of the following exception:

Traceback (most recent call last):
  File "C:\Users\Administrator\AppData\Local\Programs\Python\Python36\lib\site-packages\django\core\handlers\exception.py", line 34, in inner
    response = get_response(request)
  File "C:\Users\Administrator\AppData\Local\Programs\Python\Python36\lib\site-packages\django\core\handlers\base.py", line 126, in _get_response
    response = self.process_exception_by_middleware(e, request)
  File "C:\Users\Administrator\AppData\Local\Programs\Python\Python36\lib\site-packages\django\core\handlers\base.py", line 124, in _get_response
    response = wrapped_callback(request, *callback_args, **callback_kwargs)
  File "C:\Users\Administrator\AppData\Local\Programs\Python\Python36\lib\site-packages\django\views\decorators\csrf.py", line 54, in wrapped_view
    return view_func(*args, **kwargs)
  File "C:\Users\Administrator\AppData\Local\Programs\Python\Python36\lib\site-packages\django\views\generic\base.py", line 68, in view
    return self.dispatch(request, *args, **kwargs)
  File "C:\Users\Administrator\AppData\Local\Programs\Python\Python36\lib\site-packages\rest_framework\views.py", line 505, in dispatch
    response = self.handle_exception(exc)
  File "C:\Users\Administrator\AppData\Local\Programs\Python\Python36\lib\site-packages\rest_framework\views.py", line 465, in handle_exception
    self.raise_uncaught_exception(exc)
  File "C:\Users\Administrator\AppData\Local\Programs\Python\Python36\lib\site-packages\rest_framework\views.py", line 476, in raise_uncaught_exception
    raise exc
  File "C:\Users\Administrator\AppData\Local\Programs\Python\Python36\lib\site-packages\rest_framework\views.py", line 502, in dispatch
    response = handler(request, *args, **kwargs)
  File "C:\Users\Administrator\Desktop\school_engineer\backend\apis\views\sch_engineer.py", line 78, in post
    one_day_count=device_question.objects.filter(user_openid=open_id,truly_date=truly_date).count()
  File "C:\Users\Administrator\AppData\Local\Programs\Python\Python36\lib\site-packages\django\db\models\query.py", line 383, in count
    return self.query.get_count(using=self.db)
  File "C:\Users\Administrator\AppData\Local\Programs\Python\Python36\lib\site-packages\django\db\models\sql\query.py", line 498, in get_count
    number = obj.get_aggregation(using, ['__count'])['__count']
  File "C:\Users\Administrator\AppData\Local\Programs\Python\Python36\lib\site-packages\django\db\models\sql\query.py", line 483, in get_aggregation
    result = compiler.execute_sql(SINGLE)
  File "C:\Users\Administrator\AppData\Local\Programs\Python\Python36\lib\site-packages\django\db\models\sql\compiler.py", line 1065, in execute_sql
    cursor.execute(sql, params)
  File "C:\Users\Administrator\AppData\Local\Programs\Python\Python36\lib\site-packages\django\db\backends\utils.py", line 100, in execute
    return super().execute(sql, params)
  File "C:\Users\Administrator\AppData\Local\Programs\Python\Python36\lib\site-packages\django\db\backends\utils.py", line 68, in execute
    return self._execute_with_wrappers(sql, params, many=False, executor=self._execute)
  File "C:\Users\Administrator\AppData\Local\Programs\Python\Python36\lib\site-packages\django\db\backends\utils.py", line 77, in _execute_with_wrappers
    return executor(sql, params, many, context)
  File "C:\Users\Administrator\AppData\Local\Programs\Python\Python36\lib\site-packages\django\db\backends\utils.py", line 85, in _execute
    return self.cursor.execute(sql, params)
  File "C:\Users\Administrator\AppData\Local\Programs\Python\Python36\lib\site-packages\django\db\utils.py", line 89, in __exit__
    raise dj_exc_value.with_traceback(traceback) from exc_value
  File "C:\Users\Administrator\AppData\Local\Programs\Python\Python36\lib\site-packages\django\db\backends\utils.py", line 85, in _execute
    return self.cursor.execute(sql, params)
  File "C:\Users\Administrator\AppData\Local\Programs\Python\Python36\lib\site-packages\django\db\backends\mysql\base.py", line 71, in execute
    return self.cursor.execute(query, args)
  File "C:\Users\Administrator\AppData\Local\Programs\Python\Python36\lib\site-packages\pymysql\cursors.py", line 170, in execute
    result = self._query(query)
  File "C:\Users\Administrator\AppData\Local\Programs\Python\Python36\lib\site-packages\pymysql\cursors.py", line 328, in _query
    conn.query(q)
  File "C:\Users\Administrator\AppData\Local\Programs\Python\Python36\lib\site-packages\pymysql\connections.py", line 517, in query
    self._affected_rows = self._read_query_result(unbuffered=unbuffered)
  File "C:\Users\Administrator\AppData\Local\Programs\Python\Python36\lib\site-packages\pymysql\connections.py", line 732, in _read_query_result
    result.read()
  File "C:\Users\Administrator\AppData\Local\Programs\Python\Python36\lib\site-packages\pymysql\connections.py", line 1075, in read
    first_packet = self.connection._read_packet()
  File "C:\Users\Administrator\AppData\Local\Programs\Python\Python36\lib\site-packages\pymysql\connections.py", line 684, in _read_packet
    packet.check_error()
  File "C:\Users\Administrator\AppData\Local\Programs\Python\Python36\lib\site-packages\pymysql\protocol.py", line 220, in check_error
    err.raise_mysql_exception(self._data)
  File "C:\Users\Administrator\AppData\Local\Programs\Python\Python36\lib\site-packages\pymysql\err.py", line 109, in raise_mysql_exception
    raise errorclass(errno, errval)
django.db.utils.InternalError: (1054, "Unknown column 'apis_device_question.truly_date' in 'where clause'")
2020-03-22 14:03:53,495 [Thread-2: 9052]C:\Users\Administrator\AppData\Local\Programs\Python\Python36\lib\site-packages\django\core\servers\basehttp.py:log_message:136 ERROR - "POST /api/v1.0/service/sch_engineer HTTP/1.1" 500 23694
2020-03-22 14:06:27,624 [Thread-2: 5476]C:\Users\Administrator\AppData\Local\Programs\Python\Python36\lib\site-packages\django\core\servers\basehttp.py:log_message:136 INFO - "GET /api/v1.0/service/menu HTTP/1.1" 200 236
2020-03-22 14:06:36,220 [Thread-2: 5476]C:\Users\Administrator\AppData\Local\Programs\Python\Python36\lib\site-packages\django\core\servers\basehttp.py:log_message:136 INFO - "POST /api/v1.0/auth/authorize HTTP/1.1" 200 73
2020-03-22 14:06:39,475 [Thread-2: 5476]C:\Users\Administrator\AppData\Local\Programs\Python\Python36\lib\site-packages\django\core\servers\basehttp.py:log_message:136 INFO - "GET /api/v1.0/auth/status HTTP/1.1" 200 70
2020-03-22 14:06:39,495 [Thread-2: 5476]C:\Users\Administrator\AppData\Local\Programs\Python\Python36\lib\site-packages\django\core\servers\basehttp.py:log_message:136 INFO - "GET /api/v1.0/auth/status HTTP/1.1" 200 70
2020-03-22 14:06:53,308 [Thread-2: 5476]C:\Users\Administrator\AppData\Local\Programs\Python\Python36\lib\site-packages\django\core\servers\basehttp.py:log_message:136 INFO - "POST /api/v1.0/service/sch_engineer HTTP/1.1" 200 40
2020-03-22 14:07:07,115 [Thread-2: 5476]C:\Users\Administrator\AppData\Local\Programs\Python\Python36\lib\site-packages\django\core\servers\basehttp.py:log_message:136 INFO - "POST /api/v1.0/service/sch_engineer HTTP/1.1" 200 40
2020-03-22 14:07:15,459 [Thread-2: 5476]C:\Users\Administrator\AppData\Local\Programs\Python\Python36\lib\site-packages\django\core\servers\basehttp.py:log_message:136 INFO - "POST /api/v1.0/service/sch_engineer HTTP/1.1" 200 48
2020-03-22 14:07:23,420 [Thread-2: 5476]C:\Users\Administrator\AppData\Local\Programs\Python\Python36\lib\site-packages\django\core\servers\basehttp.py:log_message:136 INFO - "POST /api/v1.0/service/sch_engineer HTTP/1.1" 200 48
2020-03-22 14:07:34,448 [Thread-2: 5476]C:\Users\Administrator\AppData\Local\Programs\Python\Python36\lib\site-packages\django\core\servers\basehttp.py:log_message:136 INFO - "POST /api/v1.0/service/sch_engineer HTTP/1.1" 200 48
2020-03-22 14:07:36,857 [Thread-2: 5476]C:\Users\Administrator\AppData\Local\Programs\Python\Python36\lib\site-packages\django\core\servers\basehttp.py:log_message:136 INFO - "GET /api/v1.0/service/sch_engineer?kind=undone&type=backstage HTTP/1.1" 200 446
2020-03-22 14:07:36,922 [Thread-2: 5476]C:\Users\Administrator\AppData\Local\Programs\Python\Python36\lib\site-packages\django\core\servers\basehttp.py:log_message:136 INFO - "GET /api/v1.0/service/sch_engineer?kind=undone&type=backstage HTTP/1.1" 200 446
2020-03-22 14:07:44,507 [Thread-2: 5476]C:\Users\Administrator\AppData\Local\Programs\Python\Python36\lib\site-packages\django\core\servers\basehttp.py:log_message:136 INFO - "GET /api/v1.0/auth/logout HTTP/1.1" 200 48
2020-03-22 14:07:46,359 [Thread-2: 5476]C:\Users\Administrator\AppData\Local\Programs\Python\Python36\lib\site-packages\django\core\servers\basehttp.py:log_message:136 INFO - "POST /api/v1.0/auth/authorize HTTP/1.1" 200 73
2020-03-22 14:07:47,533 [Thread-2: 5476]C:\Users\Administrator\AppData\Local\Programs\Python\Python36\lib\site-packages\django\core\servers\basehttp.py:log_message:136 INFO - "GET /api/v1.0/service/sch_engineer?kind=undone&type=backstage HTTP/1.1" 200 442
2020-03-22 14:07:49,145 [Thread-2: 5476]C:\Users\Administrator\AppData\Local\Programs\Python\Python36\lib\site-packages\django\core\servers\basehttp.py:log_message:136 INFO - "GET /api/v1.0/service/sch_engineer?kind=done&type=history HTTP/1.1" 200 60
2020-03-22 14:07:49,193 [Thread-2: 5476]C:\Users\Administrator\AppData\Local\Programs\Python\Python36\lib\site-packages\django\core\servers\basehttp.py:log_message:136 INFO - "GET /api/v1.0/service/sch_engineer?kind=done&type=history HTTP/1.1" 200 60
2020-03-22 14:07:51,187 [Thread-2: 5476]C:\Users\Administrator\AppData\Local\Programs\Python\Python36\lib\site-packages\django\core\servers\basehttp.py:log_message:136 INFO - "GET /api/v1.0/service/sch_engineer?kind=undone&type=backstage HTTP/1.1" 200 442
2020-03-22 14:07:52,780 [Thread-2: 5476]C:\Users\Administrator\AppData\Local\Programs\Python\Python36\lib\site-packages\django\core\servers\basehttp.py:log_message:136 INFO - "PUT /api/v1.0/service/sch_engineer HTTP/1.1" 200 2
2020-03-22 14:07:52,822 [Thread-2: 5476]C:\Users\Administrator\AppData\Local\Programs\Python\Python36\lib\site-packages\django\core\servers\basehttp.py:log_message:136 INFO - "GET /api/v1.0/service/sch_engineer?kind=undone&type=backstage HTTP/1.1" 200 250
2020-03-22 14:07:54,459 [Thread-2: 5476]C:\Users\Administrator\AppData\Local\Programs\Python\Python36\lib\site-packages\django\core\servers\basehttp.py:log_message:136 INFO - "PUT /api/v1.0/service/sch_engineer HTTP/1.1" 200 2
2020-03-22 14:07:54,509 [Thread-2: 5476]C:\Users\Administrator\AppData\Local\Programs\Python\Python36\lib\site-packages\django\core\servers\basehttp.py:log_message:136 INFO - "GET /api/v1.0/service/sch_engineer?kind=undone&type=backstage HTTP/1.1" 200 60
2020-03-22 14:07:55,529 [Thread-2: 5476]C:\Users\Administrator\AppData\Local\Programs\Python\Python36\lib\site-packages\django\core\servers\basehttp.py:log_message:136 INFO - "GET /api/v1.0/service/sch_engineer?kind=done&type=history HTTP/1.1" 200 440
2020-03-22 14:07:55,583 [Thread-2: 5476]C:\Users\Administrator\AppData\Local\Programs\Python\Python36\lib\site-packages\django\core\servers\basehttp.py:log_message:136 INFO - "GET /api/v1.0/service/sch_engineer?kind=done&type=history HTTP/1.1" 200 440
2020-03-22 14:07:57,133 [Thread-2: 5476]C:\Users\Administrator\AppData\Local\Programs\Python\Python36\lib\site-packages\django\core\servers\basehttp.py:log_message:136 INFO - "GET /api/v1.0/service/sch_engineer?kind=done&type=classess_over HTTP/1.1" 200 440
2020-03-22 14:07:58,748 [Thread-2: 5476]C:\Users\Administrator\AppData\Local\Programs\Python\Python36\lib\site-packages\django\core\servers\basehttp.py:log_message:136 INFO - "GET /api/v1.0/service/sch_engineer?kind=done&type=classess HTTP/1.1" 200 440
2020-03-22 14:07:59,605 [Thread-2: 5476]C:\Users\Administrator\AppData\Local\Programs\Python\Python36\lib\site-packages\django\core\servers\basehttp.py:log_message:136 INFO - "GET /api/v1.0/service/sch_engineer?kind=done&type=history HTTP/1.1" 200 440
2020-03-22 14:08:03,627 [Thread-2: 5476]C:\Users\Administrator\AppData\Local\Programs\Python\Python36\lib\site-packages\django\core\servers\basehttp.py:log_message:136 INFO - "GET /api/v1.0/service/sch_engineer?kind=undone&type=backstage HTTP/1.1" 200 60
2020-03-22 14:08:33,404 [Thread-2: 5476]C:\Users\Administrator\AppData\Local\Programs\Python\Python36\lib\site-packages\django\core\servers\basehttp.py:log_message:136 INFO - "GET /api/v1.0/auth/status HTTP/1.1" 200 70
2020-03-22 14:08:38,394 [Thread-2: 5476]C:\Users\Administrator\AppData\Local\Programs\Python\Python36\lib\site-packages\django\core\servers\basehttp.py:log_message:136 INFO - "POST /api/v1.0/service/sch_engineer HTTP/1.1" 200 48
2020-03-22 14:08:46,130 [Thread-2: 5476]C:\Users\Administrator\AppData\Local\Programs\Python\Python36\lib\site-packages\django\core\servers\basehttp.py:log_message:136 INFO - "GET /api/v1.0/service/menu HTTP/1.1" 200 236
2020-03-22 14:08:48,271 [Thread-2: 5476]C:\Users\Administrator\AppData\Local\Programs\Python\Python36\lib\site-packages\django\core\servers\basehttp.py:log_message:136 INFO - "GET /api/v1.0/auth/status HTTP/1.1" 200 70
2020-03-22 14:08:49,232 [Thread-2: 5476]C:\Users\Administrator\AppData\Local\Programs\Python\Python36\lib\site-packages\django\core\servers\basehttp.py:log_message:136 INFO - "GET /api/v1.0/service/sch_engineer?kind=undone&type=backstage HTTP/1.1" 200 60
2020-03-22 14:08:50,799 [Thread-2: 5476]C:\Users\Administrator\AppData\Local\Programs\Python\Python36\lib\site-packages\django\core\servers\basehttp.py:log_message:136 INFO - "GET /api/v1.0/service/sch_engineer?kind=done&type=history HTTP/1.1" 200 440
2020-03-22 14:08:50,823 [Thread-2: 5476]C:\Users\Administrator\AppData\Local\Programs\Python\Python36\lib\site-packages\django\core\servers\basehttp.py:log_message:136 INFO - "GET /api/v1.0/service/sch_engineer?kind=done&type=history HTTP/1.1" 200 440
2020-03-22 14:08:51,929 [Thread-2: 5476]C:\Users\Administrator\AppData\Local\Programs\Python\Python36\lib\site-packages\django\core\servers\basehttp.py:log_message:136 INFO - "GET /api/v1.0/service/sch_engineer?kind=done&type=classess_over HTTP/1.1" 200 440
2020-03-22 14:08:52,677 [Thread-2: 5476]C:\Users\Administrator\AppData\Local\Programs\Python\Python36\lib\site-packages\django\core\servers\basehttp.py:log_message:136 INFO - "GET /api/v1.0/service/sch_engineer?kind=done&type=history HTTP/1.1" 200 440
2020-03-22 14:08:53,061 [Thread-2: 5476]C:\Users\Administrator\AppData\Local\Programs\Python\Python36\lib\site-packages\django\core\servers\basehttp.py:log_message:136 INFO - "GET /api/v1.0/service/sch_engineer?kind=done&type=classess HTTP/1.1" 200 440
2020-03-22 14:08:53,494 [Thread-2: 5476]C:\Users\Administrator\AppData\Local\Programs\Python\Python36\lib\site-packages\django\core\servers\basehttp.py:log_message:136 INFO - "GET /api/v1.0/service/sch_engineer?kind=done&type=history HTTP/1.1" 200 440
2020-03-22 14:08:53,816 [Thread-2: 5476]C:\Users\Administrator\AppData\Local\Programs\Python\Python36\lib\site-packages\django\core\servers\basehttp.py:log_message:136 INFO - "GET /api/v1.0/service/sch_engineer?kind=done&type=classess_over HTTP/1.1" 200 440
